Workbook

Sheet Declaration Summary
A1: NS IP DECLARATION
A3: DATE: | B3: =Inputs!C3 -> 46026.25
A5: TO: | B5: Egg Farmers of Nova Scotia | F5: PREPARED BY
B6: Email: Lorraine @nsegg.ca | F6: =Inputs!B5 -> Pamela Penney
A7: FROM: | B7: Hilly Acres Farm Ltd.
A9: RE: | B9: SURPLUS EGGS WEEK # | E9: =Inputs!C2 -> 53
B12: Boxes | C12: Dozens
A13: Nest Run | B13: =C13/15 -> 3720 | C13: ='Grade out Information'!Z26 -> 55800
A15: Graded X Large White | B15: =C15/15 -> 0 | C15: ='Grade out Information'!C11 -> 0
A16: Graded X Large Brown | B16: =C16/15 -> 0 | C16: ='Grade out Information'!C12 -> 0
A18: Graded Large White | B18: =C18/15 -> 0 | C18: ='Grade out Information'!D11 -> 0
A19: Graded Large Brown | B19: =C19/15 -> 0 | C19: ='Grade out Information'!D12 -> 0
A21: Graded Medium White | B21: =C21/15 -> 120 | C21: ='Grade out Information'!E11 -> 1800
A22: Graded Medium Brown | B22: =C22/15 -> 0 | C22: ='Grade out Information'!E12 -> 0
A24: Graded Small White | B24: =C24/15 -> 0 | C24: ='Grade out Information'!F11 -> 0
A25: Graded Small Brown | B25: =C25/15 -> 0 | C25: ='Grade out Information'!F12 -> 0
A27: TOTAL: | B27: =SUM(B13:B26) -> 3840 | C27: =SUM(C13:C26) -> 57600
B29: Left | C29: Left | D29: Left | E29: Declared | F29: Already | G29: Total
A30: BOXES | B30: From WK # | C30: From WK # | D30: From WK # | E30: WK # | F30: Shipped wk # | G30: on
G31: Hand
A32: Nest Run | E32: 0 | G32: =SUM(B32:E32)-F32 -> 0
A34: Graded X Large- White | E34: =('Grade out Information'!C11)/15 -> 0 | G34: =SUM(B34:E34)-F34 -> 0
A35: Graded X Large- Brown | E35: =('Grade out Information'!C12)/15 -> 0 | G35: =SUM(B35:E35)-F35 -> 0
A36: Graded Large- White | E36: =('Grade out Information'!D11)/15 -> 0 | G36: =SUM(B36:E36)-F36 -> 0
A37: Graded Large- Brown | E37: =('Grade out Information'!D12)/15 -> 0 | G37: =SUM(B37:E37)-F37 -> 0
A38: Graded Medium- White | E38: 0 | G38: =SUM(B38:E38)-F38 -> 0
A39: Graded Medium- Brown | E39: =('Grade out Information'!E12)/15 -> 0 | G39: =SUM(B39:E39)-F39 -> 0
A40: Graded Small- White | E40: =('Grade out Information'!F11)/15 -> 0 | G40: =SUM(B40:E40)-F40 -> 0
A41: Graded Small- Brown | E41: =('Grade out Information'!F12)/15 -> 0 | G41: =SUM(B41:E41)-F41 -> 0
A42: TOTAL: | B42: =SUM(B32:B41) -> 0 | C42: =SUM(C32:C41) -> 0 | D42: =SUM(D32:D41) -> 0 | E42: =SUM(E32:E41) -> 0 | F42: =SUM(F32:F41) -> 0 | G42: =SUM(G32:G41) -> 0

Sheet Grade out Information
A1: IP Breakdown to determine percentages and weights for the various IP Shippers
A3: Egg Farmers of Nova Scotia
A4: Hilly Acres Farm Ltd.
A7: Week | B7: Location | C7: Graded IP Dozens | G7: Graded Total | H7: Graded Total | I7: % of total | J7: Nest Run | K7: J/XL | M7: L | O7: M | Q7: S | S7: PW | U7: B | W7: C | X7: Reject/ | Z7: NR Total | AA7: Total | AB7: NR Total | AC7: % of total | AD7: Grand Total | AE7: Grand Total | AF7: % of total
A8: =Inputs!C2 -> 53 | C8: XL | D8: L | E8: M | F8: S | G8: Dozens | H8: Boxes | I8: Graded | J8: J/XL | K8: % | L8: L | M8: % | N8: M | O8: % | P8: S | Q8: % | R8: PW | S8: % | T8: B | U8: % | V8: C | W8: % | X8: loss | Y8: % | Z8: Dozens | AA8: % | AB8: Boxes | AC8: NR | AD8: Dozens | AE8: Boxes | AF8: IP
B9: GRADED IP INFORMATION
B11: Graded - White | C11: =Inputs!O73*15 -> 0 | D11: =Inputs!P73*15 -> 0 | E11: =Inputs!Q73*15 -> 1800 | F11: =Inputs!R73*15 -> 0 | G11: =SUM(C11:F11) -> 1800 | H11: =G11/15 -> 120
B12: Graded - Brown | C12: =Inputs!O74*15 -> 0 | D12: =Inputs!P74*15 -> 0 | E12: =Inputs!Q74*15 -> 0 | F12: =Inputs!R74*15 -> 0 | G12: =SUM(C12:F12) -> 0 | H12: =G12/15 -> 0
B14: NR GRADE OUT INFORMATION
B15: Theodore & Aaron Eyking Barn 6 - White | I15: =J15+L15+N15+P15+R15+T15+V15 -> 12396.441 | J15: =Inputs!P11 -> 4611.1882 | K15: =J15/Z15 -> 0.36596731 | L15: =Inputs!R11 -> 6266.8635 | M15: =L15/Z15 -> 0.49737012 | N15: =Inputs!T11 -> 1064.3316 | O15: =N15/Z15 -> 0.08447076 | P15: =Inputs!V11 -> 18.581094 | Q15: =P15/Z15 -> 0.00147469 | R15: =Inputs!X11 -> 2.4512127 | S15: =R15/Z15 -> 0.00019454069 | T15: =Inputs!Z11 -> 71.178403 | U15: =T15/Z15 -> 0.0056490796 | V15: =Inputs!AB11 -> 361.84711 | W15: =V15/Z15 -> 0.028718025 | X15: =Inputs!AD11 -> 203.55892 | Y15: =X15/Z15 -> 0.01615547 | Z15: =AB15*15 -> 12600 | AA15: =K15+M15+O15+Q15+S15+U15+W15+Y15 -> 1 | AB15: =Inputs!AH11 -> 840
B17: Chris & Nico Eyking Barn 7 - White | I17: =J17+L17+N17+P17+R17+T17+V17 -> 17714.462 | J17: =Inputs!P22 -> 6413.3608 | K17: =J17/Z17 -> 0.35629782 | L17: =Inputs!R22 -> 9053.4516 | M17: =L17/Z17 -> 0.50296953 | N17: =Inputs!T22 -> 1608.9473 | O17: =N17/Z17 -> 0.089385959 | P17: =Inputs!V22 -> 28.547305 | Q17: =P17/Z17 -> 0.0015859614 | R17: =Inputs!X22 -> 3.509117 | S17: =R17/Z17 -> 0.00019495095 | T17: =Inputs!Z22 -> 99.498089 | U17: =T17/Z17 -> 0.0055276716 | V17: =Inputs!AB22 -> 507.14832 | W17: =V17/Z17 -> 0.028174907 | X17: =Inputs!AD22 -> 285.53753 | Y17: =X17/Z17 -> 0.015863196 | Z17: =AB17*15 -> 18000 | AA17: =K17+M17+O17+Q17+S17+U17+W17+Y17 -> 1 | AB17: =Inputs!AH22 -> 1200
B18: Chris & Nico Eyking Barn 7 - Brown | I18: =J18+L18+N18+P18+R18+T18+V18 -> 0 | J18: =Inputs!P33 -> 0 | K18: =J18/Z18 -> #DIV/0! | L18: =Inputs!R33 -> 0 | M18: =L18/Z18 -> #DIV/0! | N18: =Inputs!T33 -> 0 | O18: =N18/Z18 -> #DIV/0! | P18: =Inputs!V33 -> 0 | Q18: =P18/Z18 -> #DIV/0! | R18: =Inputs!X33 -> 0 | S18: =R18/Z18 -> #DIV/0! | T18: =Inputs!Z33 -> 0 | U18: =T18/Z18 -> #DIV/0! | V18: =Inputs!AB33 -> 0 | W18: =V18/Z18 -> #DIV/0! | X18: =Inputs!AD33 -> 0 | Y18: =X18/Z18 -> #DIV/0! | Z18: =AB18*15 -> 0 | AA18: =K18+M18+O18+Q18+S18+U18+W18+Y18 -> #DIV/0! | AB18: =Inputs!AH33 -> 0
B20: Theodore & Aaron Eyking Barn 10 - White | I20: =J20+L20+N20+P20+R20+T20+V20 -> 9740.0608 | J20: =Inputs!P44 -> 3623.0764 | K20: =J20/Z20 -> 0.36596731 | L20: =Inputs!R44 -> 4923.9642 | M20: =L20/Z20 -> 0.49737012 | N20: =Inputs!T44 -> 836.26052 | O20: =N20/Z20 -> 0.08447076 | P20: =Inputs!V44 -> 14.599431 | Q20: =P20/Z20 -> 0.00147469 | R20: =Inputs!X44 -> 1.9259528 | S20: =R20/Z20 -> 0.00019454069 | T20: =Inputs!Z44 -> 55.925888 | U20: =T20/Z20 -> 0.0056490796 | V20: =Inputs!AB44 -> 284.30844 | W20: =V20/Z20 -> 0.028718025 | X20: =Inputs!AD44 -> 159.93916 | Y20: =X20/Z20 -> 0.01615547 | Z20: =AB20*15 -> 9900 | AA20: =K20+M20+O20+Q20+S20+U20+W20+Y20 -> 1 | AB20: =Inputs!AH44 -> 660
B21: Theodore & Aaron Eyking Barn 10 - Brown | I21: =J21+L21+N21+P21+R21+T21+V21 -> 1770.9202 | J21: =Inputs!P55 -> 658.74117 | K21: =J21/Z21 -> 0.36596731 | L21: =Inputs!R55 -> 895.26622 | M21: =L21/Z21 -> 0.49737012 | N21: =Inputs!T55 -> 152.04737 | O21: =N21/Z21 -> 0.08447076 | P21: =Inputs!V55 -> 2.654442 | Q21: =P21/Z21 -> 0.00147469 | R21: =Inputs!X55 -> 0.35017324 | S21: =R21/Z21 -> 0.00019454069 | T21: =Inputs!Z55 -> 10.168343 | U21: =T21/Z21 -> 0.0056490796 | V21: =Inputs!AB55 -> 51.692444 | W21: =V21/Z21 -> 0.028718025 | X21: =Inputs!AD55 -> 29.079846 | Y21: =X21/Z21 -> 0.01615547 | Z21: =AB21*15 -> 1800 | AA21: =K21+M21+O21+Q21+S21+U21+W21+Y21 -> 1 | AB21: =Inputs!AH55 -> 120
B23: Chris & Nico Eyking Barn 11 - White | I23: =J23+L23+N23+P23+R23+T23+V23 -> 13360.815 | J23: =Inputs!P67 -> 2329.7957 | K23: =J23/Z23 -> 0.17257746 | L23: =Inputs!R67 -> 8226.3379 | M23: =L23/Z23 -> 0.60935836 | N23: =Inputs!T67 -> 2467.4591 | O23: =N23/Z23 -> 0.18277475 | P23: =Inputs!V67 -> 49.95158 | Q23: =P23/Z23 -> 0.0037001171 | R23: =Inputs!X67 -> 2.737069 | S23: =R23/Z23 -> 0.00020274585 | T23: =Inputs!Z67 -> 43.482402 | U23: =T23/Z23 -> 0.0032209187 | V23: =Inputs!AB67 -> 241.05144 | W23: =V23/Z23 -> 0.017855662 | X23: =Inputs!AD67 -> 139.18485 | Y23: =X23/Z23 -> 0.010309989 | Z23: =AB23*15 -> 13500 | AA23: =K23+M23+O23+Q23+S23+U23+W23+Y23 -> 1 | AB23: =Inputs!AH67 -> 900
B26: Totals | C26: =SUM(C11:C25) -> 0 | D26: =SUM(D11:D25) -> 0 | E26: =SUM(E11:E25) -> 1800 | F26: =SUM(F11:F25) -> 0 | G26: =G11+G12 -> 1800 | H26: =SUM(H11+H12) -> 120 | J26: =SUM(J15:J25) -> 17636.162 | L26: =SUM(L15:L25) -> 29365.883 | N26: =SUM(N15:N25) -> 6129.0458 | P26: =SUM(P15:P25) -> 114.33385 | R26: =SUM(R15:R25) -> 10.973525 | T26: =SUM(T15:T25) -> 280.25313 | V26: =SUM(V15:V25) -> 1446.0478 | X26: =SUM(X15:X25) -> 817.30031 | Z26: =SUM(Z15:Z25) -> 55800 | AB26: =SUM(AB15:AB25) -> 3720 | AC26: =IF(AB33=0,0,AB33/(H33+AB33)) -> 0 | AD26: =G26+Z26 -> 57600 | AE26: =H26+AB26 -> 3840 | AF26: =I26+AC26 -> 0
A30: J/XL | B30: =J26 -> 17636.162
A31: L | B31: =L26 -> 29365.883
A32: M | B32: =N26 -> 6129.0458
A33: S | B33: =P26 -> 114.33385
A34: PW | B34: =R26 -> 10.973525
A35: B | B35: =T26 -> 280.25313
A36: C | B36: =V26 -> 1446.0478
A37: Rejects/loss | B37: =X26 -> 817.30031
A39: TOTAL | B39: =SUM(B30:B37) -> 55800

Sheet Hilly Acres Farm Ltd.
A1: Hilly Acres Farm Ltd. | F1: Week # | G1: =Inputs!C2 -> 53
A2: WEEKLY SUMMARY REPORT | F2: Week ending | G2: =Inputs!C3 -> 46026.25
N3: TOTAL
C4: Prod | D4: Marketing | E4: Housing | H4: TOTAL DZ | I4: NESTRUN | J4: TOTAL DZ | M4: TOTAL DZ | N4: MKTABLE
A5: BARN | C5: # | D5: Type | E5: Type | F5: Egg Type | G5: Colour | H5: RECEIVED | I5: DOZEN | J5: FOR GRADE | K5: REJECTS | L5: LOSS | M5: REJECTS/LOSS | N5: EGGS | O5: JUMBO | P5: EX LG | Q5: LARGE | R5: MEDIUM | S5: SMALL | T5: B GRADE | U5: CRACKS | V5: PEE WEE
A7: Theodore & Aaron Eyking Barn 6 | C7: 7169 | D7: RE | E7: Enriched | F7: Regular | G7: White | H7: =IFERROR(M7+N7,"") -> 28350 | I7: 0 | J7: =IFERROR(H7-I7,"") -> 28350 | K7: =IFERROR(($E$26/($H$27+$H$28)*$H$27)*R28,"") -> 458.00758 | L7: =IFERROR(($E$26/($H$27+$H$28)*$H$27)*S28,"") -> 0 | M7: =IFERROR(K7+L7,"") -> 458.00758 | N7: =IFERROR(O7+P7+Q7+R7+S7+T7+U7+V7,"") -> 27891.992 | O7: =IFERROR(($E$26/($H$27+$H$28)*$H$27)*J28,"") -> 0 | P7: =IFERROR(($E$26/($H$27+$H$28)*$H$27)*K28,"") -> 10375.173 | Q7: =IFERROR(($E$26/($H$27+$H$28)*$H$27)*L28,"") -> 14100.443 | R7: =IFERROR(($E$26/($H$27+$H$28)*$H$27)*M28,"") -> 2394.746 | S7: =IFERROR(($E$26/($H$27+$H$28)*$H$27)*N28,"") -> 41.807462 | T7: =IFERROR(($E$26/($H$27+$H$28)*$H$27)*O28,"") -> 160.15141 | U7: =IFERROR(($E$26/($H$27+$H$28)*$H$27)*P28,"") -> 814.156 | V7: =IFERROR(($E$26/($H$27+$H$28)*$H$27)*Q28,"") -> 5.5152285
A8: Theodore & Aaron Eyking Barn 6 | C8: 7169 | D8: RE | E8: Enriched | F8: Regular | G8: Brown | H8: =IFERROR(M8+N8,"") -> 0 | I8: 0 | J8: =IFERROR(H8-I8,"") -> 0 | K8: =IFERROR(($E$26/($H$27+$H$28)*$H$28)*R28,"") -> 0 | L8: =IFERROR(($E$26/($H$27+$H$28)*$H$28)*S28,"") -> 0 | M8: =IFERROR(K8+L8,"") -> 0 | N8: =IFERROR(O8+P8+Q8+R8+S8+T8+U8+V8,"") -> 0 | O8: =IFERROR(($E$26/($H$27+$H$28)*$H$28)*J28,"") -> 0 | P8: =IFERROR(($E$26/($H$27+$H$28)*$H$28)*K28,"") -> 0 | Q8: =IFERROR(($E$26/($H$27+$H$28)*$H$28)*L28,"") -> 0 | R8: =IFERROR(($E$26/($H$27+$H$28)*$H$28)*M28,"") -> 0 | S8: =IFERROR(($E$26/($H$27+$H$28)*$H$28)*N28,"") -> 0 | T8: =IFERROR(($E$26/($H$27+$H$28)*$H$28)*O28,"") -> 0 | U8: =IFERROR(($E$26/($H$27+$H$28)*$H$28)*P28,"") -> 0 | V8: =IFERROR(($E$26/($H$27+$H$28)*$H$28)*Q28,"") -> 0
A10: Chris & Nico Eyking Barn 7 | C10: 7168 | D10: RE | E10: Enriched | F10: Regular | G10: White | H10: =IFERROR(M10+N10,"") -> 20037.615 | I10: 0 | J10: =IFERROR(H10-I10,"") -> 20037.615 | K10: =IFERROR(($E$30/($H$31+$H$32)*$H$31)*R32,"") -> 317.86061 | L10: =IFERROR(($E$30/($H$31+$H$32)*$H$31)*S32,"") -> 0 | M10: =IFERROR(K10+L10,"") -> 317.86061 | N10: =IFERROR(O10+P10+Q10+R10+S10+T10+U10+V10,"") -> 19719.754 | O10: =IFERROR(($E$30/($H$31+$H$32)*$H$31)*J32,"") -> 0 | P10: =IFERROR(($E$30/($H$31+$H$32)*$H$31)*K32,"") -> 7139.3584 | Q10: =IFERROR(($E$30/($H$31+$H$32)*$H$31)*L32,"") -> 10078.31 | R10: =IFERROR(($E$30/($H$31+$H$32)*$H$31)*M32,"") -> 1791.0814 | S10: =IFERROR(($E$30/($H$31+$H$32)*$H$31)*N32,"") -> 31.778883 | T10: =IFERROR(($E$30/($H$31+$H$32)*$H$31)*O32,"") -> 110.76135 | U10: =IFERROR(($E$30/($H$31+$H$32)*$H$31)*P32,"") -> 564.55792 | V10: =IFERROR(($E$30/($H$31+$H$32)*$H$31)*Q32,"") -> 3.9063519
A11: Chris & Nico Eyking Barn 7 | C11: 7168 | D11: RE | E11: Enriched | F11: Regular | G11: Brown | H11: =IFERROR(M11+N11,"") -> 2222.3854 | I11: 0 | J11: =IFERROR(H11-I11,"") -> 2222.3854 | K11: =IFERROR(($E$30/($H$31+$H$32)*$H$32)*R32,"") -> 35.254136 | L11: =IFERROR(($E$30/($H$31+$H$32)*$H$32)*S32,"") -> 0 | M11: =IFERROR(K11+L11,"") -> 35.254136 | N11: =IFERROR(O11+P11+Q11+R11+S11+T11+U11+V11,"") -> 2187.1313 | O11: =IFERROR(($E$30/($H$31+$H$32)*$H$32)*J32,"") -> 0 | P11: =IFERROR(($E$30/($H$31+$H$32)*$H$32)*K32,"") -> 791.83108 | Q11: =IFERROR(($E$30/($H$31+$H$32)*$H$32)*L32,"") -> 1117.7922 | R11: =IFERROR(($E$30/($H$31+$H$32)*$H$32)*M32,"") -> 198.65005 | S11: =IFERROR(($E$30/($H$31+$H$32)*$H$32)*N32,"") -> 3.5246174 | T11: =IFERROR(($E$30/($H$31+$H$32)*$H$32)*O32,"") -> 12.284617 | U11: =IFERROR(($E$30/($H$31+$H$32)*$H$32)*P32,"") -> 62.615501 | V11: =IFERROR(($E$30/($H$31+$H$32)*$H$32)*Q32,"") -> 0.43325614
A13: Theodore & Aaron Eyking Barn 10 | C13: 7169 | D13: RE | E13: Enriched | F13: Regular | G13: White | H13: =IFERROR(M13+N13,"") -> 15902.206 | I13: 0 | J13: =IFERROR(H13-I13,"") -> 15902.206 | K13: =IFERROR(($E$34/($H$35+$H$36)*$H$35)*R36,"") -> 256.90762 | L13: =IFERROR(($E$34/($H$35+$H$36)*$H$35)*S36,"") -> 0 | M13: =IFERROR(K13+L13,"") -> 256.90762 | N13: =IFERROR(O13+P13+Q13+R13+S13+T13+U13+V13,"") -> 15645.299 | O13: =IFERROR(($E$34/($H$35+$H$36)*$H$35)*J36,"") -> 0 | P13: =IFERROR(($E$34/($H$35+$H$36)*$H$35)*K36,"") -> 5819.6877 | Q13: =IFERROR(($E$34/($H$35+$H$36)*$H$35)*L36,"") -> 7909.2822 | R13: =IFERROR(($E$34/($H$35+$H$36)*$H$35)*M36,"") -> 1343.2714 | S13: =IFERROR(($E$34/($H$35+$H$36)*$H$35)*N36,"") -> 23.450825 | T13: =IFERROR(($E$34/($H$35+$H$36)*$H$35)*O36,"") -> 89.832829 | U13: =IFERROR(($E$34/($H$35+$H$36)*$H$35)*P36,"") -> 456.67995 | V13: =IFERROR(($E$34/($H$35+$H$36)*$H$35)*Q36,"") -> 3.0936261
A14: Theodore & Aaron Eyking Barn 10 | C14: 7169 | D14: RE | E14: Enriched | F14: Regular | G14: Brown | H14: =IFERROR(M14+N14,"") -> 1062.7938 | I14: 0 | J14: =IFERROR(H14-I14,"") -> 1062.7938 | K14: =IFERROR(($E$34/($H$35+$H$36)*$H$36)*R36,"") -> 17.169933 | L14: =IFERROR(($E$34/($H$35+$H$36)*$H$36)*S36,"") -> 0 | M14: =IFERROR(K14+L14,"") -> 17.169933 | N14: =IFERROR(O14+P14+Q14+R14+S14+T14+U14+V14,"") -> 1045.6238 | O14: =IFERROR(($E$34/($H$35+$H$36)*$H$36)*J36,"") -> 0 | P14: =IFERROR(($E$34/($H$35+$H$36)*$H$36)*K36,"") -> 388.94779 | Q14: =IFERROR(($E$34/($H$35+$H$36)*$H$36)*L36,"") -> 528.60187 | R14: =IFERROR(($E$34/($H$35+$H$36)*$H$36)*M36,"") -> 89.774998 | S14: =IFERROR(($E$34/($H$35+$H$36)*$H$36)*N36,"") -> 1.5672914 | T14: =IFERROR(($E$34/($H$35+$H$36)*$H$36)*O36,"") -> 6.0038067 | U14: =IFERROR(($E$34/($H$35+$H$36)*$H$36)*P36,"") -> 30.521338 | V14: =IFERROR(($E$34/($H$35+$H$36)*$H$36)*Q36,"") -> 0.20675663
A16: Chris & Nico Eyking Barn 11 | C16: 7168 | D16: RE | E16: Enriched | F16: Regular | G16: White | H16: =IFERROR(M16+N16,"") -> 14805 | I16: 0 | J16: =IFERROR(H16-I16,"") -> 14805 | K16: =IFERROR(($E$38/($H$39)*$H$39)*R40,"") -> 152.63938 | L16: =IFERROR(($E$38/($H$39)*$H$39)*S40,"") -> 0 | M16: =IFERROR(K16+L16,"") -> 152.63938 | N16: =IFERROR(O16+P16+Q16+R16+S16+T16+U16+V16,"") -> 14652.361 | O16: =IFERROR(($E$38/($H$39)*$H$39)*J40,"") -> 0 | P16: =IFERROR(($E$38/($H$39)*$H$39)*K40,"") -> 2555.0093 | Q16: =IFERROR(($E$38/($H$39)*$H$39)*L40,"") -> 9021.5506 | R16: =IFERROR(($E$38/($H$39)*$H$39)*M40,"") -> 2705.9801 | S16: =IFERROR(($E$38/($H$39)*$H$39)*N40,"") -> 54.780233 | T16: =IFERROR(($E$38/($H$39)*$H$39)*O40,"") -> 47.685701 | U16: =IFERROR(($E$38/($H$39)*$H$39)*P40,"") -> 264.35308 | V16: =IFERROR(($E$38/($H$39)*$H$39)*Q40,"") -> 3.0016524
A19: Totals | H19: =SUM(H7:H18) -> 82380 | I19: =SUM(I7:I18) -> 0 | J19: =SUM(J7:J18) -> 82380 | K19: =SUM(K7:K18) -> 1237.8393 | L19: =SUM(L7:L18) -> 0 | M19: =SUM(M7:M18) -> 1237.8393 | N19: =SUM(N7:N18) -> 81142.161 | O19: =SUM(O7:O18) -> 0 | ... V19: =SUM(V7:V18) -> 16.156872
N21: =M19+N19 -> 82380
A22: **Email this to Lorraine Ryan, IP Office, email address: lorraine@nsegg.ca
H24: BIRD INVENTORY FOR WEEK | J24: JUMBO | K24: EX LG | L24: LARGE | M24: MEDIUM | N24: SMALL | O24: B | P24: C | Q24: PEE WEE | R24: REJECTS/ LOSS | T24: TOTAL DOZEN
A26: Barn 6 total dozen production for the week | E26: =Inputs!J29 -> 28350
A27: Theodore & Aaron Eyking Barn 6 | C27: 7169 | D27: RE | E27: Enriched | F27: Regular | G27: White | H27: ='Bird Inventory'!H3 -> 48997 | K27: =$E26*K28 -> 10375.173 | L27: =$E26*L28 -> 14100.443 | M27: =$E26*M28 -> 2394.746 | N27: =$E26*N28 -> 41.807462 | O27: =$E26*O28 -> 160.15141 | P27: =$E26*P28 -> 814.156 | Q27: =$E26*Q28 -> 5.5152285 | R27: =$E26*R28 -> 458.00758 | T27: =SUM(J27:S27) -> 28350
K28: =Inputs!Q11 -> 0.36596731 | L28: =Inputs!S11 -> 0.49737012 | M28: =Inputs!U11 -> 0.08447076 | N28: =Inputs!W11 -> 0.00147469 | O28: =Inputs!AA11 -> 0.0056490796 | P28: =Inputs!AC11 -> 0.028718025 | Q28: =Inputs!Y11 -> 0.00019454069 | R28: =Inputs!AE11 -> 0.01615547 | T28: =SUM(J28:S28) -> 1
A30: Barn 7 total dozen production for the week | E30: =Inputs!J30+Inputs!K30 -> 22260
A31: Chris & Nico Eyking Barn 7 | C31: 7168 | D31: RE | E31: Enriched | F31: Regular | G31: White | H31: ='Bird Inventory'!H5 -> 34370 | K31: =$E30*K32 -> 7931.1895 | L31: =$E30*L32 -> 11196.102 | M31: =$E30*M32 -> 1989.7315 | N31: =$E30*N32 -> 35.3035 | O31: =$E30*O32 -> 123.04597 | P31: =$E30*P32 -> 627.17342 | Q31: =$E30*Q32 -> 4.339608 | R31: =$E30*R32 -> 353.11475 | T31: =SUM(J31:S31) -> 22260
A32: Chris & Nico Eyking Barn 7 | C32: 7168 | D32: RE | E32: Enriched | F32: Regular | G32: Brown | H32: ='Bird Inventory'!H6 -> 3812 | K32: =Inputs!Q82 -> 0.35629782 | L32: =Inputs!S82 -> 0.50296953 | M32: =Inputs!U82 -> 0.089385959 | N32: =Inputs!W82 -> 0.0015859614 | O32: =Inputs!AA82 -> 0.0055276716 | P32: =Inputs!AC82 -> 0.028174907 | Q32: =Inputs!Y82 -> 0.00019495095 | R32: =Inputs!AE82 -> 0.015863196 | T32: =SUM(J32:S32) -> 1
A34: Barn 10 total dozen production for the week | E34: =Inputs!J31+Inputs!K31 -> 16965
A35: Theodore & Aaron Eyking Barn 10 | C35: 7169 | D35: RE | E35: Enriched | F35: Regular | G35: White | H35: ='Bird Inventory'!H8 -> 29641 | K35: =$E$34*K36 -> 6208.6355 | L35: =$E$34*L36 -> 8437.8841 | M35: =$E$34*M36 -> 1433.0464 | N35: =$E$34*N36 -> 25.018116 | O35: =$E$34*O36 -> 95.836636 | P35: =$E$34*P36 -> 487.20129 | Q35: =$E$34*Q36 -> 3.3003828 | R35: =$E$34*R36 -> 274.07755 | T35: =SUM(J35:S35) -> 16965
A36: Theodore & Aaron Eyking Barn 10 | C36: 7169 | D36: RE | E36: Enriched | F36: Regular | G36: Brown | H36: ='Bird Inventory'!H9 -> 1981 | K36: =Inputs!Q89 -> 0.36596731 | L36: =Inputs!S89 -> 0.49737012 | M36: =Inputs!U89 -> 0.08447076 | N36: =Inputs!W89 -> 0.00147469 | O36: =Inputs!AA89 -> 0.0056490796 | P36: =Inputs!AC89 -> 0.028718025 | Q36: =Inputs!Y89 -> 0.00019454069 | R36: =Inputs!AE89 -> 0.01615547 | T36: =SUM(J36:S36) -> 1
A38: Barn 11 total dozen production for the week | E38: =Inputs!J32 -> 14805
A39: Chris & Nico Eyking Barn 11 | C39: 7168 | D39: RE | E39: Enriched | F39: Regular | G39: White | H39: ='Bird Inventory'!H11 -> 24766 | K39: =$E38*K40 -> 2555.0093 | L39: =$E38*L40 -> 9021.5506 | M39: =$E38*M40 -> 2705.9801 | N39: =$E38*N40 -> 54.780233 | O39: =$E38*O40 -> 47.685701 | P39: =$E38*P40 -> 264.35308 | Q39: =$E38*Q40 -> 3.0016524 | R39: =$E38*R40 -> 152.63938 | T39: =SUM(J39:S39) -> 14805
K40: =Inputs!Q67 -> 0.17257746 | L40: =Inputs!S67 -> 0.60935836 | M40: =Inputs!U67 -> 0.18277475 | N40: =Inputs!W67 -> 0.0037001171 | O40: =Inputs!AA67 -> 0.0032209187 | P40: =Inputs!AC67 -> 0.017855662 | Q40: =Inputs!Y67 -> 0.00020274585 | R40: =Inputs!AE67 -> 0.010309989 | T40: =SUM(J40:S40) -> 1

Sheet Bird Inventory
A1: Bird Inventory
A3: Theodore & Aaron Eyking Barn 6 | C3: 7169 | D3: RE | E3: Enriched | F3: Regular | G3: White | H3: 48997
A5: Chris & Nico Eyking Barn 7 | C5: 7168 | D5: RE | E5: Enriched | F5: Regular | G5: White | H5: 34370
A6: Chris & Nico Eyking Barn 7 | C6: 7168 | D6: RE | E6: Enriched | F6: Regular | G6: Brown | H6: 3812
A8: Theodore & Aaron Eyking Barn 10 | C8: 7168 | D8: RE | E8: Enriched | F8: Regular | G8: White | H8: 29641
A9: Theodore & Aaron Eyking Barn 10 | C9: 7168 | D9: RE | E9: Enriched | F9: Regular | G9: Brown | H9: 1981
A11: Chris & Nico Eyking Barn 11 | C11: 7168 | D11: RE | E11: Enriched | F11: Regular | G11: White | H11: 24766

Sheet Pallet Information
A1: NO# | B1: WK | C1: TAG# | D1: BARN | E1: QUAN | F1: NR | G1: GRADED IP | H1: PACK | I1: NET | J1: Packaging | K1: GROSS | L1: WT | M1: IP# | N1: SHIP DATE | O1: CLR | P1: AGE | Q1: Class | R1: Cell ID | T1: Barn 6 White | U1: NR Grid Size | V1: NR Total
A2: Sample for Grading Station | V2: boxes
B3: 5 | C3: 123456 | D3: 7168-C3 | E3: 60 | F3: NR | H3: OLD | I3: =K3-192 -> 1408 | J3: =IF(H3="NEW",203, IF(H3="OLD",192,0)) -> 192 | K3: 1600 | L3: =I3/E3 -> 23.466667 | M3: 789456 | N3: 43663 | O3: White | P3: 50 | U3: NR 18 | V3: =COUNTIF(R$7:R$82,3)*60 -> 0
B4: 5 | C4: 123457 | D4: 7169-E6 | E4: 60 | G4: X L | H4: OLD | I4: =K4-J4 -> 1458 | J4: =IF(H4="NEW",203, IF(H4="OLD",192,0)) -> 192 | K4: 1650 | M4: 789456 | N4: 43663 | O4: White | P4: 30 | U4: NR 19 | V4: =COUNTIF(R$7:R$82,4)*60 -> 0
B5: 5 | C5: 123458 | D5: 7168-C10 | E5: 60 | G5: LARGE | H5: NEW | I5: =K5-J5 -> 1497 | J5: =IF(H5="NEW",203, IF(H5="OLD",192,0)) -> 203 | K5: 1700 | M5: 789456 | N5: 43663 | O5: Brown | U5: NR 20 | V5: =COUNTIF(R$7:R$82,5)*60 -> 0
U6: NR 21 | V6: =COUNTIF(R$7:R$82,6)*60 -> 0
A7: 4 | B7: =Inputs!C$2 -> 53 | C7: 1262964 | D7: Graded IP | E7: 60 | G7: MED | H7: NEW | I7: =IF(K7>0,K7-J7,"NA") -> NA | J7: =IF(H7="NEW",203, IF(H7="OLD",192,0)) -> 203 | L7: =IF(K7>0,I7/E7,"NA") -> NA | M7: 954147 | N7: Dec 29/25 | O7: MED | P7: =IF(D7=Inputs!F$4,Inputs!I$4,IF(D7=Inputs!F$2,Inputs!I$2,IF(D7=Inputs!F$3,Inputs!I$3,IF(D7=Inputs!F$5,Inputs!I$5,"NA")))) -> NA | Q7: =IF(ROUNDDOWN(I7/60,0)>24, 24, ROUNDDOWN(I7/60,0)) -> #VALUE! | R7: =IF(O7="MED",72,(IF(D7="7169-E6",3,0)+IF(D7="7168-E7",14,0)+IF(D7="7169-E10",36,0)+IF(D7="7168-E11",59,0))+IF(O7="Brown",11,0)+(Q7-18)) -> 72 | U7: NR 22 | V7: =COUNTIF(R$7:R$82,7)*60 -> 0
A8: 6 | B8: =Inputs!C$2 -> 53 | C8: 1262965 | D8: 7168-E7 | E8: 60 | F8: NR | H8: NEW | I8: =IF(K8>0,K8-J8,"NA") -> 1465 | J8: =IF(H8="NEW",203, IF(H8="OLD",192,0)) -> 203 | K8: 1668 | L8: =IF(K8>0,I8/E8,"NA") -> 24.416667 | M8: 954147 | N8: Dec 29/25 | O8: White | P8: =IF(D8=Inputs!F$4,Inputs!I$4,IF(D8=Inputs!F$2,Inputs!I$2,IF(D8=Inputs!F$3,Inputs!I$3,IF(D8=Inputs!F$5,Inputs!I$5,"NA")))) -> 64.892857 | Q8: =IF(ROUNDDOWN(I8/60,0)>24, 24, ROUNDDOWN(I8/60,0)) -> 24 | R8: =IF(O8="MED",72,(IF(D8="7169-E6",3,0)+IF(D8="7168-E7",14,0)+IF(D8="7169-E10",36,0)+IF(D8="7168-E11",59,0))+IF(O8="Brown",11,0)+(Q8-18)) -> 20 | U8: NR 23 | V8: =COUNTIF(R$7:R$82,8)*60 -> 0
A9: 10 | B9: =Inputs!C$2 -> 53 | C9: 1262966 | D9: 7168-E7 | E9: 60 | F9: NR | H9: NEW | I9: =IF(K9>0,K9-J9,"NA") -> 1467 | J9: =IF(H9="NEW",203, IF(H9="OLD",192,0)) -> 203 | K9: 1670 | L9: =IF(K9>0,I9/E9,"NA") -> 24.45 | M9: 954147 | N9: Dec 29/25 | O9: White | P9: =IF(D9=Inputs!F$4,Inputs!I$4,IF(D9=Inputs!F$2,Inputs!I$2,IF(D9=Inputs!F$3,Inputs!I$3,IF(D9=Inputs!F$5,Inputs!I$5,"NA")))) -> 64.892857 | Q9: =IF(ROUNDDOWN(I9/60,0)>24, 24, ROUNDDOWN(I9/60,0)) -> 24 | R9: =IF(O9="MED",72,(IF(D9="7169-E6",3,0)+IF(D9="7168-E7",14,0)+IF(D9="7169-E10",36,0)+IF(D9="7168-E11",59,0))+IF(O9="Brown",11,0)+(Q9-18)) -> 20 | U9: NR 24 | V9: =COUNTIF(R$7:R$82,9)*60 -> 840
A10: 11 | B10: =Inputs!C$2 -> 53 | C10: 1262967 | D10: 7169-E10 | E10: 60 | F10: NR | H10: NEW | I10: =IF(K10>0,K10-J10,"NA") -> 1507 | J10: =IF(H10="NEW",203, IF(H10="OLD",192,0)) -> 203 | K10: 1710 | L10: =IF(K10>0,I10/E10,"NA") -> 25.116667 | M10: 954147 | N10: Dec 29/25 | O10: White | P10: =IF(D10=Inputs!F$4,Inputs!I$4,IF(D10=Inputs!F$2,Inputs!I$2,IF(D10=Inputs!F$3,Inputs!I$3,IF(D10=Inputs!F$5,Inputs!I$5,"NA")))) -> 51.892857 | Q10: =IF(ROUNDDOWN(I10/60,0)>24, 24, ROUNDDOWN(I10/60,0)) -> 24 | R10: =IF(O10="MED",72,(IF(D10="7169-E6",3,0)+IF(D10="7168-E7",14,0)+IF(D10="7169-E10",36,0)+IF(D10="7168-E11",59,0))+IF(O10="Brown",11,0)+(Q10-18)) -> 42 | U10: Totals | V10: =SUM(V3:V9) -> 840
A11: 13 | B11: =Inputs!C$2 -> 53 | C11: 1262968 | D11: 7168-E7 | E11: 60 | F11: NR | H11: NEW | I11: =IF(K11>0,K11-J11,"NA") -> 1479 | J11: =IF(H11="NEW",203, IF(H11="OLD",192,0)) -> 203 | K11: 1682 | L11: =IF(K11>0,I11/E11,"NA") -> 24.65 | M11: 954147 | N11: Dec 29/25 | O11: White | P11: =IF(D11=Inputs!F$4,Inputs!I$4,IF(D11=Inputs!F$2,Inputs!I$2,IF(D11=Inputs!F$3,Inputs!I$3,IF(D11=Inputs!F$5,Inputs!I$5,"NA")))) -> 64.892857 | Q11: =IF(ROUNDDOWN(I11/60,0)>24, 24, ROUNDDOWN(I11/60,0)) -> 24 | R11: =IF(O11="MED",72,(IF(D11="7169-E6",3,0)+IF(D11="7168-E7",14,0)+IF(D11="7169-E10",36,0)+IF(D11="7168-E11",59,0))+IF(O11="Brown",11,0)+(Q11-18)) -> 20
A12: 29 | B12: =Inputs!C$2 -> 53 | C12: 1262969 | D12: 7168-E7 | E12: 60 | F12: NR | H12: NEW | I12: =IF(K12>0,K12-J12,"NA") -> 1469 | J12: =IF(H12="NEW",203, IF(H12="OLD",192,0)) -> 203 | K12: 1672 | L12: =IF(K12>0,I12/E12,"NA") -> 24.483333 | M12: 954147 | N12: Dec 29/25 | O12: White | P12: =IF(D12=Inputs!F$4,Inputs!I$4,IF(D12=Inputs!F$2,Inputs!I$2,IF(D12=Inputs!F$3,Inputs!I$3,IF(D12=Inputs!F$5,Inputs!I$5,"NA")))) -> 64.892857 | Q12: =IF(ROUNDDOWN(I12/60,0)>24, 24, ROUNDDOWN(I12/60,0)) -> 24 | R12: =IF(O12="MED",72,(IF(D12="7169-E6",3,0)+IF(D12="7168-E7",14,0)+IF(D12="7169-E10",36,0)+IF(D12="7168-E11",59,0))+IF(O12="Brown",11,0)+(Q12-18)) -> 20 | T12: Barn 7 White | U12: NR Grid Size | V12: NR Total
A13: 32 | B13: =Inputs!C$2 -> 53 | C13: 1262970 | D13: 7168-E7 | E13: 60 | F13: NR | H13: NEW | I13: =IF(K13>0,K13-J13,"NA") -> 1473 | J13: =IF(H13="NEW",203, IF(H13="OLD",192,0)) -> 203 | K13: 1676 | L13: =IF(K13>0,I13/E13,"NA") -> 24.55 | M13: 954147 | N13: Dec 29/25 | O13: White | P13: =IF(D13=Inputs!F$4,Inputs!I$4,IF(D13=Inputs!F$2,Inputs!I$2,IF(D13=Inputs!F$3,Inputs!I$3,IF(D13=Inputs!F$5,Inputs!I$5,"NA")))) -> 64.892857 | Q13: =IF(ROUNDDOWN(I13/60,0)>24, 24, ROUNDDOWN(I13/60,0)) -> 24 | R13: =IF(O13="MED",72,(IF(D13="7169-E6",3,0)+IF(D13="7168-E7",14,0)+IF(D13="7169-E10",36,0)+IF(D13="7168-E11",59,0))+IF(O13="Brown",11,0)+(Q13-18)) -> 20 | V13: Boxes
A14: 2 | B14: =Inputs!C$2 -> 53 | C14: 1262971 | D14: 7169-E10 | E14: 60 | F14: NR | H14: NEW | I14: =IF(K14>0,K14-J14,"NA") -> 1529 | J14: =IF(H14="NEW",203, IF(H14="OLD",192,0)) -> 203 | K14: 1732 | L14: =IF(K14>0,I14/E14,"NA") -> 25.483333 | M14: 954147 | N14: Dec 29/25 | O14: White | P14: =IF(D14=Inputs!F$4,Inputs!I$4,IF(D14=Inputs!F$2,Inputs!I$2,IF(D14=Inputs!F$3,Inputs!I$3,IF(D14=Inputs!F$5,Inputs!I$5,"NA")))) -> 51.892857 | Q14: =IF(ROUNDDOWN(I14/60,0)>24, 24, ROUNDDOWN(I14/60,0)) -> 24 | R14: =IF(O14="MED",72,(IF(D14="7169-E6",3,0)+IF(D14="7168-E7",14,0)+IF(D14="7169-E10",36,0)+IF(D14="7168-E11",59,0))+IF(O14="Brown",11,0)+(Q14-18)) -> 42 | U14: NR 18 | V14: =COUNTIF(R$7:R$82,14)*60 -> 0
A15: 3 | B15: =Inputs!C$2 -> 53 | C15: 1262972 | D15: 7169-E10 | E15: 60 | F15: NR | H15: NEW | I15: =IF(K15>0,K15-J15,"NA") -> 1503 | J15: =IF(H15="NEW",203, IF(H15="OLD",192,0)) -> 203 | K15: 1706 | L15: =IF(K15>0,I15/E15,"NA") -> 25.05 | M15: 954147 | N15: Dec 29/25 | O15: White | P15: =IF(D15=Inputs!F$4,Inputs!I$4,IF(D15=Inputs!F$2,Inputs!I$2,IF(D15=Inputs!F$3,Inputs!I$3,IF(D15=Inputs!F$5,Inputs!I$5,"NA")))) -> 51.892857 | Q15: =IF(ROUNDDOWN(I15/60,0)>24, 24, ROUNDDOWN(I15/60,0)) -> 24 | R15: =IF(O15="MED",72,(IF(D15="7169-E6",3,0)+IF(D15="7168-E7",14,0)+IF(D15="7169-E10",36,0)+IF(D15="7168-E11",59,0))+IF(O15="Brown",11,0)+(Q15-18)) -> 42 | U15: NR 19 | V15: =COUNTIF(R$7:R$82,15)*60 -> 0
A16: 9 | B16: =Inputs!C$2 -> 53 | C16: 1262973 | D16: 7169-E10 | E16: 60 | F16: NR | H16: NEW | I16: =IF(K16>0,K16-J16,"NA") -> 1503 | J16: =IF(H16="NEW",203, IF(H16="OLD",192,0)) -> 203 | K16: 1706 | L16: =IF(K16>0,I16/E16,"NA") -> 25.05 | M16: 954147 | N16: Dec 29/25 | O16: White | P16: =IF(D16=Inputs!F$4,Inputs!I$4,IF(D16=Inputs!F$2,Inputs!I$2,IF(D16=Inputs!F$3,Inputs!I$3,IF(D16=Inputs!F$5,Inputs!I$5,"NA")))) -> 51.892857 | Q16: =IF(ROUNDDOWN(I16/60,0)>24, 24, ROUNDDOWN(I16/60,0)) -> 24 | R16: =IF(O16="MED",72,(IF(D16="7169-E6",3,0)+IF(D16="7168-E7",14,0)+IF(D16="7169-E10",36,0)+IF(D16="7168-E11",59,0))+IF(O16="Brown",11,0)+(Q16-18)) -> 42 | U16: NR 20 | V16: =COUNTIF(R$7:R$82,16)*60 -> 0
A17: 12 | B17: =Inputs!C$2 -> 53 | C17: 1262974 | D17: 7169-E6 | E17: 60 | F17: NR | H17: NEW | I17: =IF(K17>0,K17-J17,"NA") -> 1497 | J17: =IF(H17="NEW",203, IF(H17="OLD",192,0)) -> 203 | K17: 1700 | L17: =IF(K17>0,I17/E17,"NA") -> 24.95 | M17: 954147 | N17: Dec 29/25 | O17: White | P17: =IF(D17=Inputs!F$4,Inputs!I$4,IF(D17=Inputs!F$2,Inputs!I$2,IF(D17=Inputs!F$3,Inputs!I$3,IF(D17=Inputs!F$5,Inputs!I$5,"NA")))) -> 39.464286 | Q17: =IF(ROUNDDOWN(I17/60,0)>24, 24, ROUNDDOWN(I17/60,0)) -> 24 | R17: =IF(O17="MED",72,(IF(D17="7169-E6",3,0)+IF(D17="7168-E7",14,0)+IF(D17="7169-E10",36,0)+IF(D17="7168-E11",59,0))+IF(O17="Brown",11,0)+(Q17-18)) -> 9 | U17: NR 21 | V17: =COUNTIF(R$7:R$82,17)*60 -> 0
A18: 19 | B18: =Inputs!C$2 -> 53 | C18: 1262975 | D18: 7169-E6 | E18: 60 | F18: NR | H18: NEW | I18: =IF(K18>0,K18-J18,"NA") -> 1454 | J18: =IF(H18="NEW",203, IF(H18="OLD",192,0)) -> 203 | K18: 1657 | L18: =IF(K18>0,I18/E18,"NA") -> 24.233333 | M18: 954147 | N18: Dec 29/25 | O18: White | P18: =IF(D18=Inputs!F$4,Inputs!I$4,IF(D18=Inputs!F$2,Inputs!I$2,IF(D18=Inputs!F$3,Inputs!I$3,IF(D18=Inputs!F$5,Inputs!I$5,"NA")))) -> 39.464286 | Q18: =IF(ROUNDDOWN(I18/60,0)>24, 24, ROUNDDOWN(I18/60,0)) -> 24 | R18: =IF(O18="MED",72,(IF(D18="7169-E6",3,0)+IF(D18="7168-E7",14,0)+IF(D18="7169-E10",36,0)+IF(D18="7168-E11",59,0))+IF(O18="Brown",11,0)+(Q18-18)) -> 9 | U18: NR 22 | V18: =COUNTIF(R$7:R$82,18)*60 -> 0
A19: 20 | B19: =Inputs!C$2 -> 53 | C19: 1262976 | D19: 7169-E6 | E19: 60 | F19: NR | H19: NEW | I19: =IF(K19>0,K19-J19,"NA") -> 1473 | J19: =IF(H19="NEW",203, IF(H19="OLD",192,0)) -> 203 | K19: 1676 | L19: =IF(K19>0,I19/E19,"NA") -> 24.55 | M19: 954147 | N19: Dec 29/25 | O19: White | P19: =IF(D19=Inputs!F$4,Inputs!I$4,IF(D19=Inputs!F$2,Inputs!I$2,IF(D19=Inputs!F$3,Inputs!I$3,IF(D19=Inputs!F$5,Inputs!I$5,"NA")))) -> 39.464286 | Q19: =IF(ROUNDDOWN(I19/60,0)>24, 24, ROUNDDOWN(I19/60,0)) -> 24 | R19: =IF(O19="MED",72,(IF(D19="7169-E6",3,0)+IF(D19="7168-E7",14,0)+IF(D19="7169-E10",36,0)+IF(D19="7168-E11",59,0))+IF(O19="Brown",11,0)+(Q19-18)) -> 9 | U19: NR 23 | V19: =COUNTIF(R$7:R$82,19)*60 -> 60
A20: 21 | B20: =Inputs!C$2 -> 53 | C20: 1262977 | D20: 7169-E6 | E20: 60 | F20: NR | H20: NEW | I20: =IF(K20>0,K20-J20,"NA") -> 1457 | J20: =IF(H20="NEW",203, IF(H20="OLD",192,0)) -> 203 | K20: 1660 | L20: =IF(K20>0,I20/E20,"NA") -> 24.283333 | M20: 954147 | N20: Dec 29/25 | O20: White | P20: =IF(D20=Inputs!F$4,Inputs!I$4,IF(D20=Inputs!F$2,Inputs!I$2,IF(D20=Inputs!F$3,Inputs!I$3,IF(D20=Inputs!F$5,Inputs!I$5,"NA")))) -> 39.464286 | Q20: =IF(ROUNDDOWN(I20/60,0)>24, 24, ROUNDDOWN(I20/60,0)) -> 24 | R20: =IF(O20="MED",72,(IF(D20="7169-E6",3,0)+IF(D20="7168-E7",14,0)+IF(D20="7169-E10",36,0)+IF(D20="7168-E11",59,0))+IF(O20="Brown",11,0)+(Q20-18)) -> 9 | U20: NR 24 | V20: =COUNTIF(R$7:R$82,20)*60 -> 1140
A21: 8 | B21: =Inputs!C$2 -> 53 | C21: 1262978 | D21: 7168-E11 | E21: 60 | F21: NR | H21: NEW | I21: =IF(K21>0,K21-J21,"NA") -> 1407 | J21: =IF(H21="NEW",203, IF(H21="OLD",192,0)) -> 203 | K21: 1610 | L21: =IF(K21>0,I21/E21,"NA") -> 23.45 | M21: 954147 | N21: Dec 29/25 | O21: White | P21: =IF(D21=Inputs!F$4,Inputs!I$4,IF(D21=Inputs!F$2,Inputs!I$2,IF(D21=Inputs!F$3,Inputs!I$3,IF(D21=Inputs!F$5,Inputs!I$5,"NA")))) -> 30.607143 | Q21: =IF(ROUNDDOWN(I21/60,0)>24, 24, ROUNDDOWN(I21/60,0)) -> 23 | R21: =IF(O21="MED",72,(IF(D21="7169-E6",3,0)+IF(D21="7168-E7",14,0)+IF(D21="7169-E10",36,0)+IF(D21="7168-E11",59,0))+IF(O21="Brown",11,0)+(Q21-18)) -> 64 | U21: Totals | V21: =SUM(V14:V20) -> 1200
A22: 22 | B22: =Inputs!C$2 -> 53 | C22: 1262979 | D22: 7168-E11 | E22: 60 | F22: NR | H22: NEW | I22: =IF(K22>0,K22-J22,"NA") -> 1431 | J22: =IF(H22="NEW",203, IF(H22="OLD",192,0)) -> 203 | K22: 1634 | L22: =IF(K22>0,I22/E22,"NA") -> 23.85 | M22: 954147 | N22: Dec 29/25 | O22: White | P22: =IF(D22=Inputs!F$4,Inputs!I$4,IF(D22=Inputs!F$2,Inputs!I$2,IF(D22=Inputs!F$3,Inputs!I$3,IF(D22=Inputs!F$5,Inputs!I$5,"NA")))) -> 30.607143 | Q22: =IF(ROUNDDOWN(I22/60,0)>24, 24, ROUNDDOWN(I22/60,0)) -> 23 | R22: =IF(O22="MED",72,(IF(D22="7169-E6",3,0)+IF(D22="7168-E7",14,0)+IF(D22="7169-E10",36,0)+IF(D22="7168-E11",59,0))+IF(O22="Brown",11,0)+(Q22-18)) -> 64
A23: 23 | B23: =Inputs!C$2 -> 53 | C23: 1262980 | D23: 7168-E11 | E23: 60 | F23: NR | H23: NEW | I23: =IF(K23>0,K23-J23,"NA") -> 1417 | J23: =IF(H23="NEW",203, IF(H23="OLD",192,0)) -> 203 | K23: 1620 | L23: =IF(K23>0,I23/E23,"NA") -> 23.616667 | M23: 954147 | N23: Dec 29/25 | O23: White | P23: =IF(D23=Inputs!F$4,Inputs!I$4,IF(D23=Inputs!F$2,Inputs!I$2,IF(D23=Inputs!F$3,Inputs!I$3,IF(D23=Inputs!F$5,Inputs!I$5,"NA")))) -> 30.607143 | Q23: =IF(ROUNDDOWN(I23/60,0)>24, 24, ROUNDDOWN(I23/60,0)) -> 23 | R23: =IF(O23="MED",72,(IF(D23="7169-E6",3,0)+IF(D23="7168-E7",14,0)+IF(D23="7169-E10",36,0)+IF(D23="7168-E11",59,0))+IF(O23="Brown",11,0)+(Q23-18)) -> 64 | T23: Barn 7 Brown | U23: NR Grid Size | V23: NR Total
A24: 24 | B24: =Inputs!C$2 -> 53 | C24: 1262981 | D24: 7168-E11 | E24: 60 | F24: NR | H24: NEW | I24: =IF(K24>0,K24-J24,"NA") -> 1423 | J24: =IF(H24="NEW",203, IF(H24="OLD",192,0)) -> 203 | K24: 1626 | L24: =IF(K24>0,I24/E24,"NA") -> 23.716667 | M24: 954147 | N24: Dec 29/25 | O24: White | P24: =IF(D24=Inputs!F$4,Inputs!I$4,IF(D24=Inputs!F$2,Inputs!I$2,IF(D24=Inputs!F$3,Inputs!I$3,IF(D24=Inputs!F$5,Inputs!I$5,"NA")))) -> 30.607143 | Q24: =IF(ROUNDDOWN(I24/60,0)>24, 24, ROUNDDOWN(I24/60,0)) -> 23 | R24: =IF(O24="MED",72,(IF(D24="7169-E6",3,0)+IF(D24="7168-E7",14,0)+IF(D24="7169-E10",36,0)+IF(D24="7168-E11",59,0))+IF(O24="Brown",11,0)+(Q24-18)) -> 64 | V24: Boxes
A25: 31 | B25: =Inputs!C$2 -> 53 | C25: 1262982 | D25: 7169-E6 | E25: 60 | F25: NR | H25: NEW | I25: =IF(K25>0,K25-J25,"NA") -> 1457 | J25: =IF(H25="NEW",203, IF(H25="OLD",192,0)) -> 203 | K25: 1660 | L25: =IF(K25>0,I25/E25,"NA") -> 24.283333 | M25: 954147 | N25: Dec 29/25 | O25: White | P25: =IF(D25=Inputs!F$4,Inputs!I$4,IF(D25=Inputs!F$2,Inputs!I$2,IF(D25=Inputs!F$3,Inputs!I$3,IF(D25=Inputs!F$5,Inputs!I$5,"NA")))) -> 39.464286 | Q25: =IF(ROUNDDOWN(I25/60,0)>24, 24, ROUNDDOWN(I25/60,0)) -> 24 | R25: =IF(O25="MED",72,(IF(D25="7169-E6",3,0)+IF(D25="7168-E7",14,0)+IF(D25="7169-E10",36,0)+IF(D25="7168-E11",59,0))+IF(O25="Brown",11,0)+(Q25-18)) -> 9 | U25: NR 18 | V25: =COUNTIF(R$7:R$82,25)*60 -> 0
A26: 15 | B26: =Inputs!C$2 -> 53 | C26: 1262983 | D26: 7168-E11 | E26: 60 | F26: NR | H26: NEW | I26: =IF(K26>0,K26-J26,"NA") -> 1413 | J26: =IF(H26="NEW",203, IF(H26="OLD",192,0)) -> 203 | K26: 1616 | L26: =IF(K26>0,I26/E26,"NA") -> 23.55 | M26: 954147 | N26: Dec 29/25 | O26: White | P26: =IF(D26=Inputs!F$4,Inputs!I$4,IF(D26=Inputs!F$2,Inputs!I$2,IF(D26=Inputs!F$3,Inputs!I$3,IF(D26=Inputs!F$5,Inputs!I$5,"NA")))) -> 30.607143 | Q26: =IF(ROUNDDOWN(I26/60,0)>24, 24, ROUNDDOWN(I26/60,0)) -> 23 | R26: =IF(O26="MED",72,(IF(D26="7169-E6",3,0)+IF(D26="7168-E7",14,0)+IF(D26="7169-E10",36,0)+IF(D26="7168-E11",59,0))+IF(O26="Brown",11,0)+(Q26-18)) -> 64 | U26: NR 19 | V26: =COUNTIF(R$7:R$82,26)*60 -> 0
A27: 16 | B27: =Inputs!C$2 -> 53 | C27: 1262984 | D27: 7168-E11 | E27: 60 | F27: NR | H27: NEW | I27: =IF(K27>0,K27-J27,"NA") -> 1419 | J27: =IF(H27="NEW",203, IF(H27="OLD",192,0)) -> 203 | K27: 1622 | L27: =IF(K27>0,I27/E27,"NA") -> 23.65 | M27: 954147 | N27: Dec 29/25 | O27: White | P27: =IF(D27=Inputs!F$4,Inputs!I$4,IF(D27=Inputs!F$2,Inputs!I$2,IF(D27=Inputs!F$3,Inputs!I$3,IF(D27=Inputs!F$5,Inputs!I$5,"NA")))) -> 30.607143 | Q27: =IF(ROUNDDOWN(I27/60,0)>24, 24, ROUNDDOWN(I27/60,0)) -> 23 | R27: =IF(O27="MED",72,(IF(D27="7169-E6",3,0)+IF(D27="7168-E7",14,0)+IF(D27="7169-E10",36,0)+IF(D27="7168-E11",59,0))+IF(O27="Brown",11,0)+(Q27-18)) -> 64 | U27: NR 20 | V27: =COUNTIF(R$7:R$82,27)*60 -> 0
A28: 17 | B28: =Inputs!C$2 -> 53 | C28: 1262985 | D28: 7169-E6 | E28: 60 | F28: NR | H28: NEW | I28: =IF(K28>0,K28-J28,"NA") -> 1473 | J28: =IF(H28="NEW",203, IF(H28="OLD",192,0)) -> 203 | K28: 1676 | L28: =IF(K28>0,I28/E28,"NA") -> 24.55 | M28: 954147 | N28: Dec 29/25 | O28: White | P28: =IF(D28=Inputs!F$4,Inputs!I$4,IF(D28=Inputs!F$2,Inputs!I$2,IF(D28=Inputs!F$3,Inputs!I$3,IF(D28=Inputs!F$5,Inputs!I$5,"NA")))) -> 39.464286 | Q28: =IF(ROUNDDOWN(I28/60,0)>24, 24, ROUNDDOWN(I28/60,0)) -> 24 | R28: =IF(O28="MED",72,(IF(D28="7169-E6",3,0)+IF(D28="7168-E7",14,0)+IF(D28="7169-E10",36,0)+IF(D28="7168-E11",59,0))+IF(O28="Brown",11,0)+(Q28-18)) -> 9 | U28: NR 21 | V28: =COUNTIF(R$7:R$82,28)*60 -> 0
A29: 18 | B29: =Inputs!C$2 -> 53 | C29: 1262986 | D29: 7169-E10 | E29: 60 | F29: NR | H29: NEW | I29: =IF(K29>0,K29-J29,"NA") -> 1509 | J29: =IF(H29="NEW",203, IF(H29="OLD",192,0)) -> 203 | K29: 1712 | L29: =IF(K29>0,I29/E29,"NA") -> 25.15 | M29: 954147 | N29: Dec 29/25 | O29: Brown | P29: =IF(D29=Inputs!F$4,Inputs!I$4,IF(D29=Inputs!F$2,Inputs!I$2,IF(D29=Inputs!F$3,Inputs!I$3,IF(D29=Inputs!F$5,Inputs!I$5,"NA")))) -> 51.892857 | Q29: =IF(ROUNDDOWN(I29/60,0)>24, 24, ROUNDDOWN(I29/60,0)) -> 24 | R29: =IF(O29="MED",72,(IF(D29="7169-E6",3,0)+IF(D29="7168-E7",14,0)+IF(D29="7169-E10",36,0)+IF(D29="7168-E11",59,0))+IF(O29="Brown",11,0)+(Q29-18)) -> 53 | U29: NR 22 | V29: =COUNTIF(R$7:R$82,29)*60 -> 0
A30: 25 | B30: =Inputs!C$2 -> 53 | C30: 1262987 | D30: 7168-E7 | E30: 60 | F30: NR | H30: NEW | I30: =IF(K30>0,K30-J30,"NA") -> 1443 | J30: =IF(H30="NEW",203, IF(H30="OLD",192,0)) -> 203 | K30: 1646 | L30: =IF(K30>0,I30/E30,"NA") -> 24.05 | M30: 954147 | N30: Dec 29/25 | O30: White | P30: =IF(D30=Inputs!F$4,Inputs!I$4,IF(D30=Inputs!F$2,Inputs!I$2,IF(D30=Inputs!F$3,Inputs!I$3,IF(D30=Inputs!F$5,Inputs!I$5,"NA")))) -> 64.892857 | Q30: =IF(ROUNDDOWN(I30/60,0)>24, 24, ROUNDDOWN(I30/60,0)) -> 24 | R30: =IF(O30="MED",72,(IF(D30="7169-E6",3,0)+IF(D30="7168-E7",14,0)+IF(D30="7169-E10",36,0)+IF(D30="7168-E11",59,0))+IF(O30="Brown",11,0)+(Q30-18)) -> 20 | U30: NR 23 | V30: =COUNTIF(R$7:R$82,30)*60 -> 0
A31: 26 | B31: =Inputs!C$2 -> 53 | C31: 1262988 | D31: 7168-E11 | E31: 60 | F31: NR | H31: NEW | I31: =IF(K31>0,K31-J31,"NA") -> 1417 | J31: =IF(H31="NEW",203, IF(H31="OLD",192,0)) -> 203 | K31: 1620 | L31: =IF(K31>0,I31/E31,"NA") -> 23.616667 | M31: 954147 | N31: Dec 29/25 | O31: White | P31: =IF(D31=Inputs!F$4,Inputs!I$4,IF(D31=Inputs!F$2,Inputs!I$2,IF(D31=Inputs!F$3,Inputs!I$3,IF(D31=Inputs!F$5,Inputs!I$5,"NA")))) -> 30.607143 | Q31: =IF(ROUNDDOWN(I31/60,0)>24, 24, ROUNDDOWN(I31/60,0)) -> 23 | R31: =IF(O31="MED",72,(IF(D31="7169-E6",3,0)+IF(D31="7168-E7",14,0)+IF(D31="7169-E10",36,0)+IF(D31="7168-E11",59,0))+IF(O31="Brown",11,0)+(Q31-18)) -> 64 | U31: NR 24 | V31: =COUNTIF(R$7:R$82,31)*60 -> 0
A32: 27 | B32: =Inputs!C$2 -> 53 | C32: 1262989 | D32: 7168-E11 | E32: 60 | F32: NR | H32: NEW | I32: =IF(K32>0,K32-J32,"NA") -> 1423 | J32: =IF(H32="NEW",203, IF(H32="OLD",192,0)) -> 203 | K32: 1626 | L32: =IF(K32>0,I32/E32,"NA") -> 23.716667 | M32: 954147 | N32: Dec 29/25 | O32: White | P32: =IF(D32=Inputs!F$4,Inputs!I$4,IF(D32=Inputs!F$2,Inputs!I$2,IF(D32=Inputs!F$3,Inputs!I$3,IF(D32=Inputs!F$5,Inputs!I$5,"NA")))) -> 30.607143 | Q32: =IF(ROUNDDOWN(I32/60,0)>24, 24, ROUNDDOWN(I32/60,0)) -> 23 | R32: =IF(O32="MED",72,(IF(D32="7169-E6",3,0)+IF(D32="7168-E7",14,0)+IF(D32="7169-E10",36,0)+IF(D32="7168-E11",59,0))+IF(O32="Brown",11,0)+(Q32-18)) -> 64 | U32: Totals | V32: =SUM(V25:V31) -> 0
A33: 28 | B33: =Inputs!C$2 -> 53 | C33: 1262990 | D33: 7168-E11 | E33: 60 | F33: NR | H33: NEW | I33: =IF(K33>0,K33-J33,"NA") -> 1435 | J33: =IF(H33="NEW",203, IF(H33="OLD",192,0)) -> 203 | K33: 1638 | L33: =IF(K33>0,I33/E33,"NA") -> 23.916667 | M33: 954147 | N33: Dec 29/25 | O33: White | P33: =IF(D33=Inputs!F$4,Inputs!I$4,IF(D33=Inputs!F$2,Inputs!I$2,IF(D33=Inputs!F$3,Inputs!I$3,IF(D33=Inputs!F$5,Inputs!I$5,"NA")))) -> 30.607143 | Q33: =IF(ROUNDDOWN(I33/60,0)>24, 24, ROUNDDOWN(I33/60,0)) -> 23 | R33: =IF(O33="MED",72,(IF(D33="7169-E6",3,0)+IF(D33="7168-E7",14,0)+IF(D33="7169-E10",36,0)+IF(D33="7168-E11",59,0))+IF(O33="Brown",11,0)+(Q33-18)) -> 64
A34: 1 | B34: =Inputs!C$2 -> 53 | C34: 1262991 | D34: 7168-E7 | E34: 60 | F34: NR | H34: NEW | I34: =IF(K34>0,K34-J34,"NA") -> 1405 | J34: =IF(H34="NEW",203, IF(H34="OLD",192,0)) -> 203 | K34: 1608 | L34: =IF(K34>0,I34/E34,"NA") -> 23.416667 | M34: 954147 | N34: Dec 29/25 | O34: Mix | P34: =IF(D34=Inputs!F$4,Inputs!I$4,IF(D34=Inputs!F$2,Inputs!I$2,IF(D34=Inputs!F$3,Inputs!I$3,IF(D34=Inputs!F$5,Inputs!I$5,"NA")))) -> 64.892857 | Q34: =IF(ROUNDDOWN(I34/60,0)>24, 24, ROUNDDOWN(I34/60,0)) -> 23 | R34: =IF(O34="MED",72,(IF(D34="7169-E6",3,0)+IF(D34="7168-E7",14,0)+IF(D34="7169-E10",36,0)+IF(D34="7168-E11",59,0))+IF(O34="Brown",11,0)+(Q34-18)) -> 19 | T34: Barn 10 White | U34: NR Grid Size | V34: NR Total
A35: 5 | B35: =Inputs!C$2 -> 53 | C35: 1262992 | D35: 7168-E7 | E35: 60 | F35: NR | H35: NEW | I35: =IF(K35>0,K35-J35,"NA") -> 1469 | J35: =IF(H35="NEW",203, IF(H35="OLD",192,0)) -> 203 | K35: 1672 | L35: =IF(K35>0,I35/E35,"NA") -> 24.483333 | M35: 954147 | N35: Dec 29/25 | O35: White | P35: =IF(D35=Inputs!F$4,Inputs!I$4,IF(D35=Inputs!F$2,Inputs!I$2,IF(D35=Inputs!F$3,Inputs!I$3,IF(D35=Inputs!F$5,Inputs!I$5,"NA")))) -> 64.892857 | Q35: =IF(ROUNDDOWN(I35/60,0)>24, 24, ROUNDDOWN(I35/60,0)) -> 24 | R35: =IF(O35="MED",72,(IF(D35="7169-E6",3,0)+IF(D35="7168-E7",14,0)+IF(D35="7169-E10",36,0)+IF(D35="7168-E11",59,0))+IF(O35="Brown",11,0)+(Q35-18)) -> 20 | V35: Boxes
A36: 7 | B36: =Inputs!C$2 -> 53 | C36: 1262993 | D36: 7168-E7 | E36: 60 | F36: NR | H36: NEW | I36: =IF(K36>0,K36-J36,"NA") -> 1475 | J36: =IF(H36="NEW",203, IF(H36="OLD",192,0)) -> 203 | K36: 1678 | L36: =IF(K36>0,I36/E36,"NA") -> 24.583333 | M36: 954147 | N36: Dec 29/25 | O36: White | P36: =IF(D36=Inputs!F$4,Inputs!I$4,IF(D36=Inputs!F$2,Inputs!I$2,IF(D36=Inputs!F$3,Inputs!I$3,IF(D36=Inputs!F$5,Inputs!I$5,"NA")))) -> 64.892857 | Q36: =IF(ROUNDDOWN(I36/60,0)>24, 24, ROUNDDOWN(I36/60,0)) -> 24 | R36: =IF(O36="MED",72,(IF(D36="7169-E6",3,0)+IF(D36="7168-E7",14,0)+IF(D36="7169-E10",36,0)+IF(D36="7168-E11",59,0))+IF(O36="Brown",11,0)+(Q36-18)) -> 20 | U36: NR 18 | V36: =COUNTIF(R$7:R$82,36)*60 -> 0
A37: 14 | B37: =Inputs!C$2 -> 53 | C37: 1262994 | D37: Graded IP | E37: 60 | G37: MED | H37: NEW | I37: =IF(K37>0,K37-J37,"NA") -> NA | J37: =IF(H37="NEW",203, IF(H37="OLD",192,0)) -> 203 | L37: =IF(K37>0,I37/E37,"NA") -> NA | M37: 954147 | N37: Dec 29/25 | O37: MED | P37: =IF(D37=Inputs!F$4,Inputs!I$4,IF(D37=Inputs!F$2,Inputs!I$2,IF(D37=Inputs!F$3,Inputs!I$3,IF(D37=Inputs!F$5,Inputs!I$5,"NA")))) -> NA | Q37: =IF(ROUNDDOWN(I37/60,0)>24, 24, ROUNDDOWN(I37/60,0)) -> #VALUE! | R37: =IF(O37="MED",72,(IF(D37="7169-E6",3,0)+IF(D37="7168-E7",14,0)+IF(D37="7169-E10",36,0)+IF(D37="7168-E11",59,0))+IF(O37="Brown",11,0)+(Q37-18)) -> 72 | U37: NR 19 | V37: =COUNTIF(R$7:R$82,37)*60 -> 0
A38: 30 | B38: =Inputs!C$2 -> 53 | C38: 1262995 | D38: 7168-E7 | E38: 60 | F38: NR | H38: NEW | I38: =IF(K38>0,K38-J38,"NA") -> 1475 | J38: =IF(H38="NEW",203, IF(H38="OLD",192,0)) -> 203 | K38: 1678 | L38: =IF(K38>0,I38/E38,"NA") -> 24.583333 | M38: 954147 | N38: Dec 29/25 | O38: White | P38: =IF(D38=Inputs!F$4,Inputs!I$4,IF(D38=Inputs!F$2,Inputs!I$2,IF(D38=Inputs!F$3,Inputs!I$3,IF(D38=Inputs!F$5,Inputs!I$5,"NA")))) -> 64.892857 | Q38: =IF(ROUNDDOWN(I38/60,0)>24, 24, ROUNDDOWN(I38/60,0)) -> 24 | R38: =IF(O38="MED",72,(IF(D38="7169-E6",3,0)+IF(D38="7168-E7",14,0)+IF(D38="7169-E10",36,0)+IF(D38="7168-E11",59,0))+IF(O38="Brown",11,0)+(Q38-18)) -> 20 | U38: NR 20 | V38: =COUNTIF(R$7:R$82,38)*60 -> 0
A39: 33 | B39: =Inputs!C$2 -> 53 | C39: 1262996 | D39: 7169-E10 | E39: 60 | F39: NR | H39: NEW | I39: =IF(K39>0,K39-J39,"NA") -> 1513 | J39: =IF(H39="NEW",203, IF(H39="OLD",192,0)) -> 203 | K39: 1716 | L39: =IF(K39>0,I39/E39,"NA") -> 25.216667 | M39: 954220 | N39: Jan 2/26 | O39: Brown | P39: =IF(D39=Inputs!F$4,Inputs!I$4,IF(D39=Inputs!F$2,Inputs!I$2,IF(D39=Inputs!F$3,Inputs!I$3,IF(D39=Inputs!F$5,Inputs!I$5,"NA")))) -> 51.892857 | Q39: =IF(ROUNDDOWN(I39/60,0)>24, 24, ROUNDDOWN(I39/60,0)) -> 24 | R39: =IF(O39="MED",72,(IF(D39="7169-E6",3,0)+IF(D39="7168-E7",14,0)+IF(D39="7169-E10",36,0)+IF(D39="7168-E11",59,0))+IF(O39="Brown",11,0)+(Q39-18)) -> 53 | U39: NR 21 | V39: =COUNTIF(R$7:R$82,39)*60 -> 0
A40: 34 | B40: =Inputs!C$2 -> 53 | C40: 1262997 | D40: 7169-E10 | E40: 60 | F40: NR | H40: NEW | I40: =IF(K40>0,K40-J40,"NA") -> 1507 | J40: =IF(H40="NEW",203, IF(H40="OLD",192,0)) -> 203 | K40: 1710 | L40: =IF(K40>0,I40/E40,"NA") -> 25.116667 | M40: 954220 | N40: Jan 2/26 | O40: White | P40: =IF(D40=Inputs!F$4,Inputs!I$4,IF(D40=Inputs!F$2,Inputs!I$2,IF(D40=Inputs!F$3,Inputs!I$3,IF(D40=Inputs!F$5,Inputs!I$5,"NA")))) -> 51.892857 | Q40: =IF(ROUNDDOWN(I40/60,0)>24, 24, ROUNDDOWN(I40/60,0)) -> 24 | R40: =IF(O40="MED",72,(IF(D40="7169-E6",3,0)+IF(D40="7168-E7",14,0)+IF(D40="7169-E10",36,0)+IF(D40="7168-E11",59,0))+IF(O40="Brown",11,0)+(Q40-18)) -> 42 | U40: NR 22 | V40: =COUNTIF(R$7:R$82,40)*60 -> 0
...

Sheet Inputs
B1: Year | C1: 2025 | G1: Hatch Date | I1: Age | J1: Wks lay | K1: Pallets
B2: Week | C2: 53 | D2: Week 1 | F2: 7169-E6 | G2: 45750 | I2: =(C$3-G2)/7 -> 39.464286 | J2: =I2-19 -> 20.464286 | K2: NEW | L2: 203 | N2: Barn 6 White | O2: NR Grid Size | P2: Nest Run | Q2: J/XL | S2: L | U2: M | W2: S | Y2: PW | AA2: B | AC2: C | AE2: Rej/Loss | AF2: NR Total | AG2: Total | AH2: NR Total
B3: Week Ending | C3: =C2*7+(C1-1900)*365.25-1 -> 46026.25 | F3: 7168-E7 | G3: 45572 | I3: =(C$3-G3)/7 -> 64.892857 | J3: =I3-19 -> 45.892857 | K3: OLD | L3: 192 | P3: J/XL | Q3: % | R3: L | S3: % | T3: M | U3: % | V3: S | W3: % | X3: PW | Y3: % | Z3: B | AA3: % | AB3: C | AC3: % | AD3: Rej/Loss | AE3: % | AF3: Dozens | AG3: % | AH3: boxes
F4: 7169-E10 | G4: 45663 | I4: =(C$3-G4)/7 -> 51.892857 | J4: =I4-19 -> 32.892857 | O4: NR 18 | P4: =AF4*Q4 -> 0 | Q4: 0.0076637186 | R4: =AF4*S4 -> 0 | S4: 0.012894787 | T4: =AF4*U4 -> 0 | U4: 0.13254414 | V4: =AF4*W4 -> 0 | W4: 0.59234214 | X4: =AF4*Y4 -> 0 | Y4: 0.23185875 | Z4: =AF4*AA4 -> 0 | AA4: 0.0053230558 | AB4: =AF4*AC4 -> 0 | AC4: 0.0069773179 | AD4: =AF4*AE4 -> 0 | AE4: 0.010396092 | AF4: =(AH4*15) -> 0 | AG4: =SUM(Q4+S4+U4+W4+Y4+AA4+AC4+AE4) -> 1 | AH4: ='Pallet Information'!V3 -> 0
A5: Prepared by | B5: Pamela Penney | F5: 7168-E11 | G5: 45812 | I5: =(C$3-G5)/7 -> 30.607143 | J5: =I5-19 -> 11.607143 | O5: NR 19 | P5: =AF5*Q5 -> 0 | Q5: 0.017661924 | R5: =AF5*S5 -> 0 | S5: 0.032802624 | T5: =AF5*U5 -> 0 | U5: 0.40487924 | V5: =AF5*W5 -> 0 | W5: 0.49075956 | X5: =AF5*Y5 -> 0 | Y5: 0.033546653 | Z5: =AF5*AA5 -> 0 | AA5: 0.00457031 | AB5: =AF5*AC5 -> 0 | AC5: 0.0070189159 | AD5: =AF5*AE5 -> 0 | AE5: 0.0087607728 | AF5: =(AH5*15) -> 0 | AG5: =SUM(Q5+S5+U5+W5+Y5+AA5+AC5+AE5) -> 1 | AH5: ='Pallet Information'!V4 -> 0
O6: NR 20 | P6: =AF6*Q6 -> 0 | Q6: 0.018025455 | R6: =AF6*S6 -> 0 | S6: 0.087671513 | T6: =AF6*U6 -> 0 | U6: 0.64997329 | V6: =AF6*W6 -> 0 | W6: 0.2207866 | X6: =AF6*Y6 -> 0 | Y6: 0.0068178938 | Z6: =AF6*AA6 -> 0 | AA6: 0.0041829617 | AB6: =AF6*AC6 -> 0 | AC6: 0.0063973155 | AD6: =AF6*AE6 -> 0 | AE6: 0.0061449686 | AF6: =(AH6*15) -> 0 | AG6: =SUM(Q6+S6+U6+W6+Y6+AA6+AC6+AE6) -> 1 | AH6: ='Pallet Information'!V5 -> 0
A7: PRODUCTION (# of stacks) | O7: NR 21 | P7: =AF7*Q7 -> 0 | Q7: 0.026348295 | R7: =AF7*S7 -> 0 | S7: 0.25469986 | T7: =AF7*U7 -> 0 | U7: 0.62709761 | V7: =AF7*W7 -> 0 | W7: 0.072177744 | X7: =AF7*Y7 -> 0 | Y7: 0.0012870032 | Z7: =AF7*AA7 -> 0 | AA7: 0.0035453016 | AB7: =AF7*AC7 -> 0 | AC7: 0.0070032903 | AD7: =AF7*AE7 -> 0 | AE7: 0.0078409029 | AF7: =(AH7*15) -> 0 | AG7: =SUM(Q7+S7+U7+W7+Y7+AA7+AC7+AE7) -> 1 | AH7: ='Pallet Information'!V6 -> 0
A8: SUNDAY | E8: MONDAY | O8: NR 22 | P8: =AF8*Q8 -> 0 | Q8: 0.057422831 | R8: =AF8*S8 -> 0 | S8: 0.50285289 | T8: =AF8*U8 -> 0 | U8: 0.39999177 | V8: =AF8*W8 -> 0 | W8: 0.019053888 | X8: =AF8*Y8 -> 0 | Y8: 0.00033778317 | Z8: =AF8*AA8 -> 0 | AA8: 0.0036004615 | AB8: =AF8*AC8 -> 0 | AC8: 0.0084032775 | AD8: =AF8*AE8 -> 0 | AE8: 0.0083371027 | AF8: =(AH8*15) -> 0 | AG8: =SUM(Q8+S8+U8+W8+Y8+AA8+AC8+AE8) -> 1 | AH8: ='Pallet Information'!V7 -> 0
A9: Barn | B9: White | C9: Brown | E9: Barn | F9: White | G9: Brown | O9: NR 23 | P9: =AF9*Q9 -> 0 | Q9: 0.17257746 | R9: =AF9*S9 -> 0 | S9: 0.60935836 | T9: =AF9*U9 -> 0 | U9: 0.18277475 | V9: =AF9*W9 -> 0 | W9: 0.0037001171 | X9: =AF9*Y9 -> 0 | Y9: 0.00020274585 | Z9: =AF9*AA9 -> 0 | AA9: 0.0032209187 | AB9: =AF9*AC9 -> 0 | AC9: 0.017855662 | AD9: =AF9*AE9 -> 0 | AE9: 0.010309989 | AF9: =(AH9*15) -> 0 | AG9: =SUM(Q9+S9+U9+W9+Y9+AA9+AC9+AE9) -> 1 | AH9: ='Pallet Information'!V8 -> 0
A10: 6 | B10: 264 | E10: 6 | F10: 270 | O10: NR 24 | P10: =AF10*Q10 -> 4611.1882 | Q10: 0.36596731 | R10: =AF10*S10 -> 6266.8635 | S10: 0.49737012 | T10: =AF10*U10 -> 1064.3316 | U10: 0.08447076 | V10: =AF10*W10 -> 18.581094 | W10: 0.00147469 | X10: =AF10*Y10 -> 2.4512127 | Y10: 0.00019454069 | Z10: =AF10*AA10 -> 71.178403 | AA10: 0.0056490796 | AB10: =AF10*AC10 -> 361.84711 | AC10: 0.028718025 | AD10: =AF10*AE10 -> 203.55892 | AE10: 0.01615547 | AF10: =(AH10*15) -> 12600 | AG10: =SUM(Q10+S10+U10+W10+Y10+AA10+AC10+AE10) -> 1 | AH10: ='Pallet Information'!V9 -> 840
A11: 7 | B11: 186 | C11: 18 | E11: 7 | F11: 197 | G11: 22 | O11: Totals | P11: =SUM(P4:P10) -> 4611.1882 | Q11: =P11/AF11 -> 0.36596731 | R11: =SUM(R4:R10) -> 6266.8635 | S11: =R11/AF11 -> 0.49737012 | T11: =SUM(T4:T10) -> 1064.3316 | U11: =T11/AF11 -> 0.08447076 | V11: =SUM(V4:V10) -> 18.581094 | W11: =V11/AF11 -> 0.00147469 | X11: =SUM(X4:X10) -> 2.4512127 | Y11: =X11/AF11 -> 0.00019454069 | Z11: =SUM(Z4:Z10) -> 71.178403 | AA11: =Z11/AF11 -> 0.0056490796 | AB11: =SUM(AB4:AB10) -> 361.84711 | AC11: =AB11/AF11 -> 0.028718025 | AD11: =SUM(AD4:AD10) -> 203.55892 | AE11: =AD11/AF11 -> 0.01615547 | AF11: =SUM(AF4:AF10) -> 12600 | AG11: =Q11+S11+U11+W11+Y11+AA11+AC11+AE11 -> 1 | AH11: =AF11/15 -> 840
A12: 10 | B12: 150 | C12: 10 | E12: 10 | F12: 148 | G12: 12
A13: 11 | B13: 131 | E13: 11 | F13: 152 | N13: Barn 7 White | O13: NR Grid Size | P13: Nest Run | Q13: J/XL | S13: L | U13: M | W13: S | Y13: PW | AA13: B | AC13: C | AE13: Rej/Loss | AF13: NR Total | AG13: Total | AH13: NR Total
A14: TUESDAY | E14: WEDNESDAY | P14: J/XL | Q14: % | R14: L | S14: % | T14: M | U14: % | V14: S | W14: % | X14: PW | Y14: % | Z14: B | AA14: % | AB14: C | AC14: % | AD14: Rej/Loss | AE14: % | AF14: Dozens | AG14: % | AH14: Boxes
A15: Barn | B15: White | C15: Brown | E15: Barn | F15: White | G15: Brown | O15: NR 18 | P15: =AF15*Q15 -> 0 | Q15: 0.0076637186 | R15: =AF15*S15 -> 0 | S15: 0.012894787 | T15: =AF15*U15 -> 0 | U15: 0.13254414 | V15: =AF15*W15 -> 0 | W15: 0.59234214 | X15: =AF15*Y15 -> 0 | Y15: 0.23185875 | Z15: =AF15*AA15 -> 0 | AA15: 0.0053230558 | AB15: =AF15*AC15 -> 0 | AC15: 0.0069773179 | AD15: =AF15*AE15 -> 0 | AE15: 0.010396092 | AF15: =(AH15*15) -> 0 | AG15: =SUM(Q15+S15+U15+W15+Y15+AA15+AC15+AE15) -> 1 | AH15: ='Pallet Information'!V14 -> 0
A16: 6 | B16: 276 | E16: 6 | F16: 270 | O16: NR 19 | P16: =AF16*Q16 -> 0 | Q16: 0.017661924 | R16: =AF16*S16 -> 0 | S16: 0.032802624 | T16: =AF16*U16 -> 0 | U16: 0.40487924 | V16: =AF16*W16 -> 0 | W16: 0.49075956 | X16: =AF16*Y16 -> 0 | Y16: 0.033546653 | Z16: =AF16*AA16 -> 0 | AA16: 0.00457031 | AB16: =AF16*AC16 -> 0 | AC16: 0.0070189159 | AD16: =AF16*AE16 -> 0 | AE16: 0.0087607728 | AF16: =(AH16*15) -> 0 | AG16: =SUM(Q16+S16+U16+W16+Y16+AA16+AC16+AE16) -> 1 | AH16: ='Pallet Information'!V15 -> 0
A17: 7 | B17: 199 | C17: 22 | E17: 7 | F17: 182 | G17: 21 | O17: NR 20 | P17: =AF17*Q17 -> 0 | Q17: 0.018025455 | R17: =AF17*S17 -> 0 | S17: 0.087671513 | T17: =AF17*U17 -> 0 | U17: 0.64997329 | V17: =AF17*W17 -> 0 | W17: 0.2207866 | X17: =AF17*Y17 -> 0 | Y17: 0.0068178938 | Z17: =AF17*AA17 -> 0 | AA17: 0.0041829617 | AB17: =AF17*AC17 -> 0 | AC17: 0.0063973155 | AD17: =AF17*AE17 -> 0 | AE17: 0.0061449686 | AF17: =(AH17*15) -> 0 | AG17: =SUM(Q17+S17+U17+W17+Y17+AA17+AC17+AE17) -> 1 | AH17: ='Pallet Information'!V16 -> 0
A18: 10 | B18: 157 | C18: 11 | E18: 10 | F18: 151 | G18: 11 | O18: NR 21 | P18: =AF18*Q18 -> 0 | Q18: 0.026348295 | R18: =AF18*S18 -> 0 | S18: 0.25469986 | T18: =AF18*U18 -> 0 | U18: 0.62709761 | V18: =AF18*W18 -> 0 | W18: 0.072177744 | X18: =AF18*Y18 -> 0 | Y18: 0.0012870032 | Z18: =AF18*AA18 -> 0 | AA18: 0.0035453016 | AB18: =AF18*AC18 -> 0 | AC18: 0.0070032903 | AD18: =AF18*AE18 -> 0 | AE18: 0.0078409029 | AF18: =(AH18*15) -> 0 | AG18: =SUM(Q18+S18+U18+W18+Y18+AA18+AC18+AE18) -> 1 | AH18: ='Pallet Information'!V17 -> 0
A19: 11 | B19: 145 | E19: 11 | F19: 137 | O19: NR 22 | P19: =AF19*Q19 -> 0 | Q19: 0.057422831 | R19: =AF19*S19 -> 0 | S19: 0.50285289 | T19: =AF19*U19 -> 0 | U19: 0.39999177 | V19: =AF19*W19 -> 0 | W19: 0.019053888 | X19: =AF19*Y19 -> 0 | Y19: 0.00033778317 | Z19: =AF19*AA19 -> 0 | AA19: 0.0036004615 | AB19: =AF19*AC19 -> 0 | AC19: 0.0084032775 | AD19: =AF19*AE19 -> 0 | AE19: 0.0083371027 | AF19: =(AH19*15) -> 0 | AG19: =SUM(Q19+S19+U19+W19+Y19+AA19+AC19+AE19) -> 1 | AH19: ='Pallet Information'!V18 -> 0
O20: NR 23 | P20: =AF20*Q20 -> 155.31971 | Q20: 0.17257746 | R20: =AF20*S20 -> 548.42253 | S20: 0.60935836 | T20: =AF20*U20 -> 164.49727 | U20: 0.18277475 | V20: =AF20*W20 -> 3.3301054 | W20: 0.0037001171 | X20: =AF20*Y20 -> 0.18247127 | Y20: 0.00020274585 | Z20: =AF20*AA20 -> 2.8988268 | AA20: 0.0032209187 | AB20: =AF20*AC20 -> 16.070096 | AC20: 0.017855662 | AD20: =AF20*AE20 -> 9.27899 | AE20: 0.010309989 | AF20: =(AH20*15) -> 900 | AG20: =SUM(Q20+S20+U20+W20+Y20+AA20+AC20+AE20) -> 1 | AH20: ='Pallet Information'!V19 -> 60
A21: THURSDAY | E21: FRIDAY | O21: NR 24 | P21: =AF21*Q21 -> 6258.0411 | Q21: 0.36596731 | R21: =AF21*S21 -> 8505.0291 | S21: 0.49737012 | T21: =AF21*U21 -> 1444.45 | U21: 0.08447076 | V21: =AF21*W21 -> 25.217199 | W21: 0.00147469 | X21: =AF21*Y21 -> 3.3266457 | Y21: 0.00019454069 | Z21: =AF21*AA21 -> 96.599262 | AA21: 0.0056490796 | AB21: =AF21*AC21 -> 491.07822 | AC21: 0.028718025 | AD21: =AF21*AE21 -> 276.25854 | AE21: 0.01615547 | AF21: =(AH21*15) -> 17100 | AG21: =SUM(Q21+S21+U21+W21+Y21+AA21+AC21+AE21) -> 1 | AH21: ='Pallet Information'!V20 -> 1140
A22: Barn | B22: White | C22: Brown | E22: Barn | F22: White | G22: Brown | O22: Totals | P22: =SUM(P15:P21) -> 6413.3608 | Q22: =P22/AF22 -> 0.35629782 | R22: =SUM(R15:R21) -> 9053.4516 | S22: =R22/AF22 -> 0.50296953 | T22: =SUM(T15:T21) -> 1608.9473 | U22: =T22/AF22 -> 0.089385959 | V22: =SUM(V15:V21) -> 28.547305 | W22: =V22/AF22 -> 0.0015859614 | X22: =SUM(X15:X21) -> 3.509117 | Y22: =X22/AF22 -> 0.00019495095 | Z22: =SUM(Z15:Z21) -> 99.498089 | AA22: =Z22/AF22 -> 0.0055276716 | AB22: =SUM(AB15:AB21) -> 507.14832 | AC22: =AB22/AF22 -> 0.028174907 | AD22: =SUM(AD15:AD21) -> 285.53753 | AE22: =AD22/AF22 -> 0.015863196 | AF22: =SUM(AF15:AF21) -> 18000 | AG22: =Q22+S22+U22+W22+Y22+AA22+AC22+AE22 -> 1 | AH22: =AF22/15 -> 1200
A23: 6 | B23: 270 | E23: 6 | F23: 270
A24: 7 | B24: 189 | C24: 22 | E24: 7 | F24: 194 | G24: 22 | N24: Barn 7 Brown | O24: NR Grid Size | P24: Nest Run | Q24: J/XL | S24: L | U24: M | W24: S | Y24: PW | AA24: B | AC24: C | AE24: Rej/Loss | AF24: NR Total | AG24: Total | AH24: NR Total
A25: 10 | B25: 147 | C25: 11 | E25: 10 | F25: 153 | G25: 11 | P25: J/XL | Q25: % | R25: L | S25: % | T25: M | U25: % | V25: S | W25: % | X25: PW | Y25: % | Z25: B | AA25: % | AB25: C | AC25: % | AD25: Rej/Loss | AE25: % | AF25: Dozens | AG25: % | AH25: Boxes
A26: 11 | B26: 139 | E26: 11 | F26: 140 | O26: NR 18 | P26: =AF26*Q26 -> 0 | Q26: 0.0076637186 | R26: =AF26*S26 -> 0 | S26: 0.012894787 | T26: =AF26*U26 -> 0 | U26: 0.13254414 | V26: =AF26*W26 -> 0 | W26: 0.59234214 | X26: =AF26*Y26 -> 0 | Y26: 0.23185875 | Z26: =AF26*AA26 -> 0 | AA26: 0.0053230558 | AB26: =AF26*AC26 -> 0 | AC26: 0.0069773179 | AD26: =AF26*AE26 -> 0 | AE26: 0.010396092 | AF26: =AH26*15 -> 0 | AG26: =SUM(Q26+S26+U26+W26+Y26+AA26+AC26+AE26) -> 1 | AH26: ='Pallet Information'!V25 -> 0
A27: SATURDAY | E27: TOTAL (stacks) | I27: TOTAL (dozens) | O27: NR 19 | P27: =AF27*Q27 -> 0 | Q27: 0.017661924 | R27: =AF27*S27 -> 0 | S27: 0.032802624 | T27: =AF27*U27 -> 0 | U27: 0.40487924 | V27: =AF27*W27 -> 0 | W27: 0.49075956 | X27: =AF27*Y27 -> 0 | Y27: 0.033546653 | Z27: =AF27*AA27 -> 0 | AA27: 0.00457031 | AB27: =AF27*AC27 -> 0 | AC27: 0.0070189159 | AD27: =AF27*AE27 -> 0 | AE27: 0.0087607728 | AF27: =AH27*15 -> 0 | AG27: =SUM(Q27+S27+U27+W27+Y27+AA27+AC27+AE27) -> 1 | AH27: ='Pallet Information'!V26 -> 0
A28: Barn | B28: White | C28: Brown | E28: Barn | F28: White | G28: Brown | I28: Barn | J28: White | K28: Brown | O28: NR 20 | P28: =AF28*Q28 -> 0 | Q28: 0.018025455 | R28: =AF28*S28 -> 0 | S28: 0.087671513 | T28: =AF28*U28 -> 0 | U28: 0.64997329 | V28: =AF28*W28 -> 0 | W28: 0.2207866 | X28: =AF28*Y28 -> 0 | Y28: 0.0068178938 | Z28: =AF28*AA28 -> 0 | AA28: 0.0041829617 | AB28: =AF28*AC28 -> 0 | AC28: 0.0063973155 | AD28: =AF28*AE28 -> 0 | AE28: 0.0061449686 | AF28: =AH28*15 -> 0 | AG28: =SUM(Q28+S28+U28+W28+Y28+AA28+AC28+AE28) -> 1 | AH28: ='Pallet Information'!V27 -> 0
A29: 6 | B29: 270 | E29: 6 | F29: =B10+F10+B16+F16+B23+F23+B29 -> 1890 | G29: =C10+G10+C16+G16+C23+G23+C29 -> 0 | I29: 6 | J29: =F29*15 -> 28350 | K29: =G29*15 -> 0 | O29: NR 21 | P29: =AF29*Q29 -> 0 | Q29: 0.026348295 | R29: =AF29*S29 -> 0 | S29: 0.25469986 | T29: =AF29*U29 -> 0 | U29: 0.62709761 | V29: =AF29*W29 -> 0 | W29: 0.072177744 | X29: =AF29*Y29 -> 0 | Y29: 0.0012870032 | Z29: =AF29*AA29 -> 0 | AA29: 0.0035453016 | AB29: =AF29*AC29 -> 0 | AC29: 0.0070032903 | AD29: =AF29*AE29 -> 0 | AE29: 0.0078409029 | AF29: =AH29*15 -> 0 | AG29: =SUM(Q29+S29+U29+W29+Y29+AA29+AC29+AE29) -> 1 | AH29: ='Pallet Information'!V28 -> 0
A30: 7 | B30: 189 | C30: 21 | E30: 7 | F30: =B11+F11+B17+F17+B24+F24+B30 -> 1336 | G30: =C11+G11+C17+G17+C24+G24+C30 -> 148 | I30: 7 | J30: =F30*15 -> 20040 | K30: =G30*15 -> 2220 | O30: NR 22 | P30: =AF30*Q30 -> 0 | Q30: 0.057422831 | R30: =AF30*S30 -> 0 | S30: 0.50285289 | T30: =AF30*U30 -> 0 | U30: 0.39999177 | V30: =AF30*W30 -> 0 | W30: 0.019053888 | X30: =AF30*Y30 -> 0 | Y30: 0.00033778317 | Z30: =AF30*AA30 -> 0 | AA30: 0.0036004615 | AB30: =AF30*AC30 -> 0 | AC30: 0.0084032775 | AD30: =AF30*AE30 -> 0 | AE30: 0.0083371027 | AF30: =AH30*15 -> 0 | AG30: =SUM(Q30+S30+U30+W30+Y30+AA30+AC30+AE30) -> 1 | AH30: ='Pallet Information'!V29 -> 0
A31: 10 | B31: 148 | C31: 11 | E31: 10 | F31: =B12+F12+B18+F18+B25+F25+B31 -> 1054 | G31: =C12+G12+C18+G18+C25+G25+C31 -> 77 | I31: 10 | J31: =F31*15 -> 15810 | K31: =G31*15 -> 1155 | O31: NR 23 | P31: =AF31*Q31 -> 0 | Q31: 0.17257746 | R31: =AF31*S31 -> 0 | S31: 0.60935836 | T31: =AF31*U31 -> 0 | U31: 0.18277475 | V31: =AF31*W31 -> 0 | W31: 0.0037001171 | X31: =AF31*Y31 -> 0 | Y31: 0.00020274585 | Z31: =AF31*AA31 -> 0 | AA31: 0.0032209187 | AB31: =AF31*AC31 -> 0 | AC31: 0.017855662 | AD31: =AF31*AE31 -> 0 | AE31: 0.010309989 | AF31: =AH31*15 -> 0 | AG31: =SUM(Q31+S31+U31+W31+Y31+AA31+AC31+AE31) -> 1 | AH31: ='Pallet Information'!V30 -> 0
A32: 11 | B32: 143 | E32: 11 | F32: =B13+F13+B19+F19+B26+F26+B32 -> 987 | G32: =C13+G13+C19+G19+C26+G26+C32 -> 0 | I32: 11 | J32: =F32*15 -> 14805 | K32: =G32*180/12 -> 0 | O32: NR 24 | P32: =AF32*Q32 -> 0 | Q32: 0.36596731 | R32: =AF32*S32 -> 0 | S32: 0.49737012 | T32: =AF32*U32 -> 0 | U32: 0.08447076 | V32: =AF32*W32 -> 0 | W32: 0.00147469 | X32: =AF32*Y32 -> 0 | Y32: 0.00019454069 | Z32: =AF32*AA32 -> 0 | AA32: 0.0056490796 | AB32: =AF32*AC32 -> 0 | AC32: 0.028718025 | AD32: =AF32*AE32 -> 0 | AE32: 0.01615547 | AF32: =AH32*15 -> 0 | AG32: =SUM(Q32+S32+U32+W32+Y32+AA32+AC32+AE32) -> 1 | AH32: ='Pallet Information'!V31 -> 0
O33: Totals | P33: =SUM(P26:P32) -> 0 | Q33: =P33/AF33 -> #DIV/0! | R33: =SUM(R26:R32) -> 0 | S33: =R33/AF33 -> #DIV/0! | T33: =SUM(T26:T32) -> 0 | U33: =T33/AF33 -> #DIV/0! | V33: =SUM(V26:V32) -> 0 | W33: =V33/AF33 -> #DIV/0! | X33: =SUM(X26:X32) -> 0 | Y33: =X33/AF33 -> #DIV/0! | Z33: =SUM(Z26:Z32) -> 0 | AA33: =Z33/AF33 -> #DIV/0! | AB33: =SUM(AB26:AB32) -> 0 | AC33: =AB33/AF33 -> #DIV/0! | AD33: =SUM(AD26:AD32) -> 0 | AE33: =AD33/AF33 -> #DIV/0! | AF33: =SUM(AF26:AF32) -> 0 | AG33: =Q33+S33+U33+W33+Y33+AA33+AC33+AE33 -> #DIV/0! | AH33: =AF33/15 -> 0
G34: NEST RUN TOTALS (Boxes/Stacks)
