Workbook

Sheet Hilly Acres Farm Ltd.
A1: Hilly Acres Farm Ltd. | F1: Week # | G1: =Inputs!C2 -> 47
A2: WEEKLY SUMMARY REPORT | F2: Week ending | G2: =Inputs!C3 -> 45984.25
N3: TOTAL
C4: Prod | D4: Marketing | E4: Housing | H4: TOTAL DZ | I4: NESTRUN | J4: TOTAL DZ | M4: TOTAL DZ | N4: MKTABLE
A5: BARN | C5: # | D5: Type | E5: Type | F5: Egg Type | G5: Colour | H5: RECEIVED | I5: DOZEN | J5: FOR GRADE | K5: REJECTS | L5: LOSS | M5: REJECTS/LOSS | N5: EGGS | O5: JUMBO | P5: EX LG | Q5: LARGE | R5: MEDIUM | S5: SMALL | T5: B GRADE | U5: CRACKS | V5: PEE WEE
A7: Theodore & Aaron Eyking Barn 6 | C7: 7169 | D7: RE | E7: Enriched | F7: Regular | G7: White | H7: =IFERROR(M7+N7,"") -> 28170 | I7: 0 | J7: =IFERROR(H7-I7,"") -> 28170 | K7: =IFERROR(($E$26/($H$27+$H$28)*$H$27)*R28,"") -> 422.16615 | L7: =IFERROR(($E$26/($H$27+$H$28)*$H$27)*S28,"") -> 0 | M7: =IFERROR(K7+L7,"") -> 422.16615 | N7: =IFERROR(O7+P7+Q7+R7+S7+T7+U7+V7,"") -> 27747.834 | O7: =IFERROR(($E$26/($H$27+$H$28)*$H$27)*J28,"") -> 0 | P7: =IFERROR(($E$26/($H$27+$H$28)*$H$27)*K28,"") -> 9219.7408 | Q7: =IFERROR(($E$26/($H$27+$H$28)*$H$27)*L28,"") -> 14641.858 | R7: =IFERROR(($E$26/($H$27+$H$28)*$H$27)*M28,"") -> 2933.386 | S7: =IFERROR(($E$26/($H$27+$H$28)*$H$27)*N28,"") -> 54.080074 | T7: =IFERROR(($E$26/($H$27+$H$28)*$H$27)*O28,"") -> 145.45431 | U7: =IFERROR(($E$26/($H$27+$H$28)*$H$27)*P28,"") -> 747.7882 | V7: =IFERROR(($E$26/($H$27+$H$28)*$H$27)*Q28,"") -> 5.5264391
A8: Theodore & Aaron Eyking Barn 6 | C8: 7169 | D8: RE | E8: Enriched | F8: Regular | G8: Brown | H8: =IFERROR(M8+N8,"") -> 0 | I8: 0 | J8: =IFERROR(H8-I8,"") -> 0 | K8: =IFERROR(($E$26/($H$27+$H$28)*$H$28)*R28,"") -> 0 | L8: =IFERROR(($E$26/($H$27+$H$28)*$H$28)*S28,"") -> 0 | M8: =IFERROR(K8+L8,"") -> 0 | N8: =IFERROR(O8+P8+Q8+R8+S8+T8+U8+V8,"") -> 0 | O8: =IFERROR(($E$26/($H$27+$H$28)*$H$28)*J28,"") -> 0 | P8: =IFERROR(($E$26/($H$27+$H$28)*$H$28)*K28,"") -> 0 | Q8: =IFERROR(($E$26/($H$27+$H$28)*$H$28)*L28,"") -> 0 | R8: =IFERROR(($E$26/($H$27+$H$28)*$H$28)*M28,"") -> 0 | S8: =IFERROR(($E$26/($H$27+$H$28)*$H$28)*N28,"") -> 0 | T8: =IFERROR(($E$26/($H$27+$H$28)*$H$28)*O28,"") -> 0 | U8: =IFERROR(($E$26/($H$27+$H$28)*$H$28)*P28,"") -> 0 | V8: =IFERROR(($E$26/($H$27+$H$28)*$H$28)*Q28,"") -> 0
A10: Chris & Nico Eyking Barn 7 | C10: 7168 | D10: RE | E10: Enriched | F10: Regular | G10: White | H10: =IFERROR(M10+N10,"") -> 20405.004 | I10: 0 | J10: =IFERROR(H10-I10,"") -> 20405.004 | K10: =IFERROR(($E$30/($H$31+$H$32)*$H$31)*R32,"") -> 312.61286 | L10: =IFERROR(($E$30/($H$31+$H$32)*$H$31)*S32,"") -> 0 | M10: =IFERROR(K10+L10,"") -> 312.61286 | N10: =IFERROR(O10+P10+Q10+R10+S10+T10+U10+V10,"") -> 20092.392 | O10: =IFERROR(($E$30/($H$31+$H$32)*$H$31)*J32,"") -> 0 | P10: =IFERROR(($E$30/($H$31+$H$32)*$H$31)*K32,"") -> 6903.8331 | Q10: =IFERROR(($E$30/($H$31+$H$32)*$H$31)*L32,"") -> 10475.285 | R10: =IFERROR(($E$30/($H$31+$H$32)*$H$31)*M32,"") -> 2010.1824 | S10: =IFERROR(($E$30/($H$31+$H$32)*$H$31)*N32,"") -> 36.578178 | T10: =IFERROR(($E$30/($H$31+$H$32)*$H$31)*O32,"") -> 108.1914 | U10: =IFERROR(($E$30/($H$31+$H$32)*$H$31)*P32,"") -> 554.32763 | V10: =IFERROR(($E$30/($H$31+$H$32)*$H$31)*Q32,"") -> 3.9935216
A11: Chris & Nico Eyking Barn 7 | C11: 7168 | D11: RE | E11: Enriched | F11: Regular | G11: Brown | H11: =IFERROR(M11+N11,"") -> 2259.9956 | I11: 0 | J11: =IFERROR(H11-I11,"") -> 2259.9956 | K11: =IFERROR(($E$30/($H$31+$H$32)*$H$32)*R32,"") -> 34.624039 | L11: =IFERROR(($E$30/($H$31+$H$32)*$H$32)*S32,"") -> 0 | M11: =IFERROR(K11+L11,"") -> 34.624039 | N11: =IFERROR(O11+P11+Q11+R11+S11+T11+U11+V11,"") -> 2225.3715 | O11: =IFERROR(($E$30/($H$31+$H$32)*$H$32)*J32,"") -> 0 | P11: =IFERROR(($E$30/($H$31+$H$32)*$H$32)*K32,"") -> 764.64733 | Q11: =IFERROR(($E$30/($H$31+$H$32)*$H$32)*L32,"") -> 1160.2104 | R11: =IFERROR(($E$30/($H$31+$H$32)*$H$32)*M32,"") -> 222.64162 | S11: =IFERROR(($E$30/($H$31+$H$32)*$H$32)*N32,"") -> 4.0512865 | T11: =IFERROR(($E$30/($H$31+$H$32)*$H$32)*O32,"") -> 11.982947 | U11: =IFERROR(($E$30/($H$31+$H$32)*$H$32)*P32,"") -> 61.395624 | V11: =IFERROR(($E$30/($H$31+$H$32)*$H$32)*Q32,"") -> 0.44231018
A13: Theodore & Aaron Eyking Barn 10 | C13: 7169 | D13: RE | E13: Enriched | F13: Regular | G13: White | H13: =IFERROR(M13+N13,"") -> 16208.26 | I13: 0 | J13: =IFERROR(H13-I13,"") -> 16208.26 | K13: =IFERROR(($E$34/($H$35+$H$36)*$H$35)*R36,"") -> 261.85206 | L13: =IFERROR(($E$34/($H$35+$H$36)*$H$35)*S36,"") -> 0 | M13: =IFERROR(K13+L13,"") -> 261.85206 | N13: =IFERROR(O13+P13+Q13+R13+S13+T13+U13+V13,"") -> 15946.408 | O13: =IFERROR(($E$34/($H$35+$H$36)*$H$35)*J36,"") -> 0 | P13: =IFERROR(($E$34/($H$35+$H$36)*$H$35)*K36,"") -> 5931.6935 | Q13: =IFERROR(($E$34/($H$35+$H$36)*$H$35)*L36,"") -> 8061.5043 | R13: =IFERROR(($E$34/($H$35+$H$36)*$H$35)*M36,"") -> 1369.1241 | S13: =IFERROR(($E$34/($H$35+$H$36)*$H$35)*N36,"") -> 23.902159 | T13: =IFERROR(($E$34/($H$35+$H$36)*$H$35)*O36,"") -> 91.561752 | U13: =IFERROR(($E$34/($H$35+$H$36)*$H$35)*P36,"") -> 465.46921 | V13: =IFERROR(($E$34/($H$35+$H$36)*$H$35)*Q36,"") -> 3.1531661
A14: Theodore & Aaron Eyking Barn 10 | C14: 7169 | D14: RE | E14: Enriched | F14: Regular | G14: Brown | H14: =IFERROR(M14+N14,"") -> 1086.7398 | I14: 0 | J14: =IFERROR(H14-I14,"") -> 1086.7398 | K14: =IFERROR(($E$34/($H$35+$H$36)*$H$36)*R36,"") -> 17.556793 | L14: =IFERROR(($E$34/($H$35+$H$36)*$H$36)*S36,"") -> 0 | M14: =IFERROR(K14+L14,"") -> 17.556793 | N14: =IFERROR(O14+P14+Q14+R14+S14+T14+U14+V14,"") -> 1069.183 | O14: =IFERROR(($E$34/($H$35+$H$36)*$H$36)*J36,"") -> 0 | P14: =IFERROR(($E$34/($H$35+$H$36)*$H$36)*K36,"") -> 397.71125 | Q14: =IFERROR(($E$34/($H$35+$H$36)*$H$36)*L36,"") -> 540.51191 | R14: =IFERROR(($E$34/($H$35+$H$36)*$H$36)*M36,"") -> 91.797738 | S14: =IFERROR(($E$34/($H$35+$H$36)*$H$36)*N36,"") -> 1.6026044 | T14: =IFERROR(($E$34/($H$35+$H$36)*$H$36)*O36,"") -> 6.1390798 | U14: =IFERROR(($E$34/($H$35+$H$36)*$H$36)*P36,"") -> 31.209021 | V14: =IFERROR(($E$34/($H$35+$H$36)*$H$36)*Q36,"") -> 0.21141511
A16: Chris & Nico Eyking Barn 11 | C16: 7168 | D16: RE | E16: Enriched | F16: Regular | G16: White | H16: =IFERROR(M16+N16,"") -> 13050 | I16: 0 | J16: =IFERROR(H16-I16,"") -> 13050 | K16: =IFERROR(($E$38/($H$39)*$H$39)*R40,"") -> 90.279278 | L16: =IFERROR(($E$38/($H$39)*$H$39)*S40,"") -> 0 | M16: =IFERROR(K16+L16,"") -> 90.279278 | N16: =IFERROR(O16+P16+Q16+R16+S16+T16+U16+V16,"") -> 12959.721 | O16: =IFERROR(($E$38/($H$39)*$H$39)*J40,"") -> 0 | P16: =IFERROR(($E$38/($H$39)*$H$39)*K40,"") -> 308.09557 | Q16: =IFERROR(($E$38/($H$39)*$H$39)*L40,"") -> 2300.1405 | R16: =IFERROR(($E$38/($H$39)*$H$39)*M40,"") -> 8166.3124 | S16: =IFERROR(($E$38/($H$39)*$H$39)*N40,"") -> 1989.4723 | T16: =IFERROR(($E$38/($H$39)*$H$39)*O40,"") -> 50.992 | U16: =IFERROR(($E$38/($H$39)*$H$39)*P40,"") -> 88.086569 | V16: =IFERROR(($E$38/($H$39)*$H$39)*Q40,"") -> 56.621378
A19: Totals | H19: =SUM(H7:H18) -> 81180 | I19: =SUM(I7:I18) -> 0 | J19: =SUM(J7:J18) -> 81180 | K19: =SUM(K7:K18) -> 1139.0912 | L19: =SUM(L7:L18) -> 0 | M19: =SUM(M7:M18) -> 1139.0912 | N19: =SUM(N7:N18) -> 80040.909 | O19: =SUM(O7:O18) -> 0 | ... V19: =SUM(V7:V18) -> 69.94823
N21: =M19+N19 -> 81180
A22: **Email this to Lorraine Ryan, IP Office, email address: lorraine@nsegg.ca
H24: BIRD INVENTORY FOR WEEK | J24: JUMBO | K24: EX LG | L24: LARGE | M24: MEDIUM | N24: SMALL | O24: B | P24: C | Q24: PEE WEE | R24: REJECTS/ LOSS | T24: TOTAL DOZEN
A26: Barn 6 total dozen production for the week | E26: =Inputs!J29 -> 28170
A27: Theodore & Aaron Eyking Barn 6 | C27: 7169 | D27: RE | E27: Enriched | F27: Regular | G27: White | H27: ='Bird Inventory'!H3 -> 49042 | K27: =$E26*K28 -> 9219.7408 | L27: =$E26*L28 -> 14641.858 | M27: =$E26*M28 -> 2933.386 | N27: =$E26*N28 -> 54.080074 | O27: =$E26*O28 -> 145.45431 | P27: =$E26*P28 -> 747.7882 | Q27: =$E26*Q28 -> 5.5264391 | R27: =$E26*R28 -> 422.16615 | T27: =SUM(J27:S27) -> 28170
K28: =Inputs!Q11 -> 0.32728934 | L28: =Inputs!S11 -> 0.51976777 | M28: =Inputs!U11 -> 0.10413156 | N28: =Inputs!W11 -> 0.0019197754 | O28: =Inputs!AA11 -> 0.0051634474 | P28: =Inputs!AC11 -> 0.026545552 | Q28: =Inputs!Y11 -> 0.00019618172 | R28: =Inputs!AE11 -> 0.014986374 | T28: =SUM(J28:S28) -> 1
A30: Barn 7 total dozen production for the week | E30: =Inputs!J30+Inputs!K30 -> 22665
A31: Chris & Nico Eyking Barn 7 | C31: 7168 | D31: RE | E31: Enriched | F31: Regular | G31: White | H31: ='Bird Inventory'!H5 -> 34508 | K31: =$E30*K32 -> 7668.4805 | L31: =$E30*L32 -> 11635.496 | M31: =$E30*M32 -> 2232.824 | N31: =$E30*N32 -> 40.629464 | O31: =$E30*O32 -> 120.17435 | P31: =$E30*P32 -> 615.72325 | Q31: =$E30*Q32 -> 4.4358318 | R31: =$E30*R32 -> 347.2369 | T31: =SUM(J31:S31) -> 22665
A32: Chris & Nico Eyking Barn 7 | C32: 7168 | D32: RE | E32: Enriched | F32: Regular | G32: Brown | H32: ='Bird Inventory'!H6 -> 3822 | K32: =Inputs!Q82 -> 0.33834019 | L32: =Inputs!S82 -> 0.51336844 | M32: =Inputs!U82 -> 0.098514186 | N32: =Inputs!W82 -> 0.0017926082 | O32: =Inputs!AA82 -> 0.0053021995 | P32: =Inputs!AC82 -> 0.027166259 | Q32: =Inputs!Y82 -> 0.00019571285 | R32: =Inputs!AE82 -> 0.015320401 | T32: =SUM(J32:S32) -> 1
A34: Barn 10 total dozen production for the week | E34: =Inputs!J31+Inputs!K31 -> 17295
A35: Theodore & Aaron Eyking Barn 10 | C35: 7169 | D35: RE | E35: Enriched | F35: Regular | G35: White | H35: ='Bird Inventory'!H8 -> 29680 | K35: =$E$34*K36 -> 6329.4047 | L35: =$E$34*L36 -> 8602.0162 | M35: =$E$34*M36 -> 1460.9218 | N35: =$E$34*N36 -> 25.504764 | O35: =$E$34*O36 -> 97.700832 | P35: =$E$34*P36 -> 496.67824 | Q35: =$E$34*Q36 -> 3.3645812 | R35: =$E$34*R36 -> 279.40886 | T35: =SUM(J35:S35) -> 17295
A36: Theodore & Aaron Eyking Barn 10 | C36: 7169 | D36: RE | E36: Enriched | F36: Regular | G36: Brown | H36: ='Bird Inventory'!H9 -> 1990 | K36: =Inputs!Q89 -> 0.36596731 | L36: =Inputs!S89 -> 0.49737012 | M36: =Inputs!U89 -> 0.08447076 | N36: =Inputs!W89 -> 0.00147469 | O36: =Inputs!AA89 -> 0.0056490796 | P36: =Inputs!AC89 -> 0.028718025 | Q36: =Inputs!Y89 -> 0.00019454069 | R36: =Inputs!AE89 -> 0.01615547 | T36: =SUM(J36:S36) -> 1
A38: Barn 11 total dozen production for the week | E38: =Inputs!J32 -> 13050
A39: Chris & Nico Eyking Barn 11 | C39: 7168 | D39: RE | E39: Enriched | F39: Regular | G39: White | H39: ='Bird Inventory'!H11 -> 24802 | K39: =$E38*K40 -> 308.09557 | L39: =$E38*L40 -> 2300.1405 | M39: =$E38*M40 -> 8166.3124 | N39: =$E38*N40 -> 1989.4723 | O39: =$E38*O40 -> 50.992 | P39: =$E38*P40 -> 88.086569 | Q39: =$E38*Q40 -> 56.621378 | R39: =$E38*R40 -> 90.279278 | T39: =SUM(J39:S39) -> 13050
K40: =Inputs!Q67 -> 0.023608856 | L40: =Inputs!S67 -> 0.17625598 | M40: =Inputs!U67 -> 0.62577107 | N40: =Inputs!W67 -> 0.15244998 | O40: =Inputs!AA67 -> 0.0039074329 | P40: =Inputs!AC67 -> 0.0067499287 | Q40: =Inputs!Y67 -> 0.0043388029 | R40: =Inputs!AE67 -> 0.0069179524 | T40: =SUM(J40:S40) -> 1

Sheet Declaration Summary
A1: NS IP DECLARATION
A3: DATE: | B3: =Inputs!C3 -> 45984.25
A5: TO: | B5: Egg Farmers of Nova Scotia | F5: PREPARED BY
B6: Email: Lorraine @nsegg.ca | F6: =Inputs!B5 -> Pamela Penney
A7: FROM: | B7: Hilly Acres Farm Ltd.
A9: RE: | B9: SURPLUS EGGS WEEK # | E9: =Inputs!C2 -> 47
B12: Boxes | C12: Dozens
A13: Nest Run | B13: =C13/15 -> 1860 | C13: ='Grade out Information'!Z26 -> 27900
A15: Graded X Large White | B15: =C15/15 -> 0 | C15: ='Grade out Information'!C11 -> 0
A16: Graded X Large Brown | B16: =C16/15 -> 0 | C16: ='Grade out Information'!C12 -> 0
A18: Graded Large White | B18: =C18/15 -> 0 | C18: ='Grade out Information'!D11 -> 0
A19: Graded Large Brown | B19: =C19/15 -> 0 | C19: ='Grade out Information'!D12 -> 0
A21: Graded Medium White | B21: =C21/15 -> 60 | C21: ='Grade out Information'!E11 -> 900
A22: Graded Medium Brown | B22: =C22/15 -> 0 | C22: ='Grade out Information'!E12 -> 0
A24: Graded Small White | B24: =C24/15 -> 0 | C24: ='Grade out Information'!F11 -> 0
A25: Graded Small Brown | B25: =C25/15 -> 0 | C25: ='Grade out Information'!F12 -> 0
A27: TOTAL: | B27: =SUM(B13:B26) -> 1920 | C27: =SUM(C13:C26) -> 28800
B29: Left | C29: Left | D29: Left | E29: Declared | F29: Already | G29: Total
A30: BOXES | B30: From WK # | C30: From WK # | D30: From WK # | E30: WK # | F30: Shipped wk # | G30: on
G31: Hand
A32: Nest Run | E32: 0 | G32: =SUM(B32:E32)-F32 -> 0
A34: Graded X Large- White | E34: =('Grade out Information'!C11)/15 -> 0 | G34: =SUM(B34:E34)-F34 -> 0
A35: Graded X Large- Brown | E35: =('Grade out Information'!C12)/15 -> 0 | G35: =SUM(B35:E35)-F35 -> 0
A36: Graded Large- White | E36: =('Grade out Information'!D11)/15 -> 0 | G36: =SUM(B36:E36)-F36 -> 0
A37: Graded Large- Brown | E37: =('Grade out Information'!D12)/15 -> 0 | G37: =SUM(B37:E37)-F37 -> 0
A38: Graded Medium- White | E38: 0 | G38: =SUM(B38:E38)-F38 -> 0
A39: Graded Medium- Brown | E39: =('Grade out Information'!E12)/15 -> 0 | G39: =SUM(B39:E39)-F39 -> 0
A40: Graded Small- White | E40: =('Grade out Information'!F11)/15 -> 0 | G40: =SUM(B40:E40)-F40 -> 0
A41: Graded Small- Brown | E41: =('Grade out Information'!F12)/15 -> 0 | G41: =SUM(B41:E41)-F41 -> 0
A42: TOTAL: | B42: =SUM(B32:B41) -> 0 | C42: =SUM(C32:C41) -> 0 | D42: =SUM(D32:D41) -> 0 | E42: =SUM(E32:E41) -> 0 | F42: =SUM(F32:F41) -> 0 | G42: =SUM(G32:G41) -> 0

Sheet Grade out Information
A1: IP Breakdown to determine percentages and weights for the various IP Shippers
A3: Egg Farmers of Nova Scotia
A4: Hilly Acres Farm Ltd.
A7: Week | B7: Location | C7: Graded IP Dozens | G7: Graded Total | H7: Graded Total | I7: % of total | J7: Nest Run | K7: J/XL | M7: L | O7: M | Q7: S | S7: PW | U7: B | W7: C | X7: Reject/ | Z7: NR Total | AA7: Total | AB7: NR Total | AC7: % of total | AD7: Grand Total | AE7: Grand Total | AF7: % of total
A8: =Inputs!C2 -> 47 | C8: XL | D8: L | E8: M | F8: S | G8: Dozens | H8: Boxes | I8: Graded | J8: J/XL | K8: % | L8: L | M8: % | N8: M | O8: % | P8: S | Q8: % | R8: PW | S8: % | T8: B | U8: % | V8: C | W8: % | X8: loss | Y8: % | Z8: Dozens | AA8: % | AB8: Boxes | AC8: NR | AD8: Dozens | AE8: Boxes | AF8: IP
B9: GRADED IP INFORMATION
B11: Graded - White | C11: =Inputs!O73*15 -> 0 | D11: =Inputs!P73*15 -> 0 | E11: =Inputs!Q73*15 -> 900 | F11: =Inputs!R73*15 -> 0 | G11: =SUM(C11:F11) -> 900 | H11: =G11/15 -> 60
B12: Graded - Brown | C12: =Inputs!O74*15 -> 0 | D12: =Inputs!P74*15 -> 0 | E12: =Inputs!Q74*15 -> 0 | F12: =Inputs!R74*15 -> 0 | G12: =SUM(C12:F12) -> 0 | H12: =G12/15 -> 0
B14: NR GRADE OUT INFORMATION
B15: Theodore & Aaron Eyking Barn 6 - White | I15: =J15+L15+N15+P15+R15+T15+V15 -> 4432.5613 | J15: =Inputs!P11 -> 1472.802 | K15: =J15/Z15 -> 0.32728934 | L15: =Inputs!R11 -> 2338.955 | M15: =L15/Z15 -> 0.51976777 | N15: =Inputs!T11 -> 468.59201 | O15: =N15/Z15 -> 0.10413156 | P15: =Inputs!V11 -> 8.6389894 | Q15: =P15/Z15 -> 0.0019197754 | R15: =Inputs!X11 -> 0.88281774 | S15: =R15/Z15 -> 0.00019618172 | T15: =Inputs!Z11 -> 23.235513 | U15: =T15/Z15 -> 0.0051634474 | V15: =Inputs!AB11 -> 119.45498 | W15: =V15/Z15 -> 0.026545552 | X15: =Inputs!AD11 -> 67.438683 | Y15: =X15/Z15 -> 0.014986374 | Z15: =AB15*15 -> 4500 | AA15: =K15+M15+O15+Q15+S15+U15+W15+Y15 -> 1 | AB15: =Inputs!AH11 -> 300
B17: Chris & Nico Eyking Barn 7 - White | I17: =J17+L17+N17+P17+R17+T17+V17 -> 3547.1012 | J17: =Inputs!P22 -> 1143.4315 | K17: =J17/Z17 -> 0.31761985 | L17: =Inputs!R22 -> 1891.3219 | M17: =L17/Z17 -> 0.52536718 | N17: =Inputs!T22 -> 392.56832 | O17: =N17/Z17 -> 0.10904676 | P17: =Inputs!V22 -> 7.3117684 | Q17: =P17/Z17 -> 0.0020310468 | R17: =Inputs!X22 -> 0.70773112 | S17: =R17/Z17 -> 0.00019659198 | T17: =Inputs!Z22 -> 18.151342 | U17: =T17/Z17 -> 0.0050420394 | V17: =Inputs!AB22 -> 93.608763 | W17: =V17/Z17 -> 0.026002434 | X17: =Inputs!AD22 -> 52.89876 | Y17: =X17/Z17 -> 0.0146941 | Z17: =AB17*15 -> 3600 | AA17: =K17+M17+O17+Q17+S17+U17+W17+Y17 -> 1 | AB17: =Inputs!AH22 -> 240
B18: Chris & Nico Eyking Barn 7 - Brown | I18: =J18+L18+N18+P18+R18+T18+V18 -> 2656.3802 | J18: =Inputs!P33 -> 988.11175 | K18: =J18/Z18 -> 0.36596731 | L18: =Inputs!R33 -> 1342.8993 | M18: =L18/Z18 -> 0.49737012 | N18: =Inputs!T33 -> 228.07105 | O18: =N18/Z18 -> 0.08447076 | P18: =Inputs!V33 -> 3.981663 | Q18: =P18/Z18 -> 0.00147469 | R18: =Inputs!X33 -> 0.52525986 | S18: =R18/Z18 -> 0.00019454069 | T18: =Inputs!Z33 -> 15.252515 | U18: =T18/Z18 -> 0.0056490796 | V18: =Inputs!AB33 -> 77.538666 | W18: =V18/Z18 -> 0.028718025 | X18: =Inputs!AD33 -> 43.61977 | Y18: =X18/Z18 -> 0.01615547 | Z18: =AB18*15 -> 2700 | AA18: =K18+M18+O18+Q18+S18+U18+W18+Y18 -> 1 | AB18: =Inputs!AH33 -> 180
B20: Theodore & Aaron Eyking Barn 10 - White | I20: =J20+L20+N20+P20+R20+T20+V20 -> 2656.3802 | J20: =Inputs!P44 -> 988.11175 | K20: =J20/Z20 -> 0.36596731 | L20: =Inputs!R44 -> 1342.8993 | M20: =L20/Z20 -> 0.49737012 | N20: =Inputs!T44 -> 228.07105 | O20: =N20/Z20 -> 0.08447076 | P20: =Inputs!V44 -> 3.981663 | Q20: =P20/Z20 -> 0.00147469 | R20: =Inputs!X44 -> 0.52525986 | S20: =R20/Z20 -> 0.00019454069 | T20: =Inputs!Z44 -> 15.252515 | U20: =T20/Z20 -> 0.0056490796 | V20: =Inputs!AB44 -> 77.538666 | W20: =V20/Z20 -> 0.028718025 | X20: =Inputs!AD44 -> 43.61977 | Y20: =X20/Z20 -> 0.01615547 | Z20: =AB20*15 -> 2700 | AA20: =K20+M20+O20+Q20+S20+U20+W20+Y20 -> 1 | AB20: =Inputs!AH44 -> 180
B21: Theodore & Aaron Eyking Barn 10 - Brown | I21: =J21+L21+N21+P21+R21+T21+V21 -> 0 | J21: =Inputs!P55 -> 0 | K21: =J21/Z21 -> #DIV/0! | L21: =Inputs!R55 -> 0 | M21: =L21/Z21 -> #DIV/0! | N21: =Inputs!T55 -> 0 | O21: =N21/Z21 -> #DIV/0! | P21: =Inputs!V55 -> 0 | Q21: =P21/Z21 -> #DIV/0! | R21: =Inputs!X55 -> 0 | S21: =R21/Z21 -> #DIV/0! | T21: =Inputs!Z55 -> 0 | U21: =T21/Z21 -> #DIV/0! | V21: =Inputs!AB55 -> 0 | W21: =V21/Z21 -> #DIV/0! | X21: =Inputs!AD55 -> 0 | Y21: =X21/Z21 -> #DIV/0! | Z21: =AB21*15 -> 0 | AA21: =K21+M21+O21+Q21+S21+U21+W21+Y21 -> #DIV/0! | AB21: =Inputs!AH55 -> 0
B23: Chris & Nico Eyking Barn 11 - White | I23: =J23+L23+N23+P23+R23+T23+V23 -> 14300.381 | J23: =Inputs!P67 -> 339.96753 | K23: =J23/Z23 -> 0.023608856 | L23: =Inputs!R67 -> 2538.0861 | M23: =L23/Z23 -> 0.17625598 | N23: =Inputs!T67 -> 9011.1034 | O23: =N23/Z23 -> 0.62577107 | P23: =Inputs!V67 -> 2195.2798 | Q23: =P23/Z23 -> 0.15244998 | R23: =Inputs!X67 -> 62.478762 | S23: =R23/Z23 -> 0.0043388029 | T23: =Inputs!Z67 -> 56.267034 | U23: =T23/Z23 -> 0.0039074329 | V23: =Inputs!AB67 -> 97.198973 | W23: =V23/Z23 -> 0.0067499287 | X23: =Inputs!AD67 -> 99.618514 | Y23: =X23/Z23 -> 0.0069179524 | Z23: =AB23*15 -> 14400 | AA23: =K23+M23+O23+Q23+S23+U23+W23+Y23 -> 1 | AB23: =Inputs!AH67 -> 960
B26: Totals | C26: =SUM(C11:C25) -> 0 | D26: =SUM(D11:D25) -> 0 | E26: =SUM(E11:E25) -> 900 | F26: =SUM(F11:F25) -> 0 | G26: =G11+G12 -> 900 | H26: =SUM(H11+H12) -> 60 | J26: =SUM(J15:J25) -> 4932.4245 | L26: =SUM(L15:L25) -> 9454.1615 | N26: =SUM(N15:N25) -> 10328.406 | P26: =SUM(P15:P25) -> 2219.1938 | R26: =SUM(R15:R25) -> 65.11983 | T26: =SUM(T15:T25) -> 128.15892 | V26: =SUM(V15:V25) -> 465.34005 | X26: =SUM(X15:X25) -> 307.1955 | Z26: =SUM(Z15:Z25) -> 27900 | AB26: =SUM(AB15:AB25) -> 1860 | AC26: =IF(AB33=0,0,AB33/(H33+AB33)) -> 0 | AD26: =G26+Z26 -> 28800 | AE26: =H26+AB26 -> 1920 | AF26: =I26+AC26 -> 0
A30: J/XL | B30: =J26 -> 4932.4245
A31: L | B31: =L26 -> 9454.1615
A32: M | B32: =N26 -> 10328.406
A33: S | B33: =P26 -> 2219.1938
A34: PW | B34: =R26 -> 65.11983
A35: B | B35: =T26 -> 128.15892
A36: C | B36: =V26 -> 465.34005
A37: Rejects/loss | B37: =X26 -> 307.1955
A39: TOTAL | B39: =SUM(B30:B37) -> 27900

Sheet Bird Inventory
A1: Bird Inventory
A3: Theodore & Aaron Eyking Barn 6 | C3: 7169 | D3: RE | E3: Enriched | F3: Regular | G3: White | H3: 49042
A5: Chris & Nico Eyking Barn 7 | C5: 7168 | D5: RE | E5: Enriched | F5: Regular | G5: White | H5: 34508
A6: Chris & Nico Eyking Barn 7 | C6: 7168 | D6: RE | E6: Enriched | F6: Regular | G6: Brown | H6: 3822
A8: Theodore & Aaron Eyking Barn 10 | C8: 7168 | D8: RE | E8: Enriched | F8: Regular | G8: White | H8: 29680
A9: Theodore & Aaron Eyking Barn 10 | C9: 7168 | D9: RE | E9: Enriched | F9: Regular | G9: Brown | H9: 1990
A11: Chris & Nico Eyking Barn 11 | C11: 7168 | D11: RE | E11: Enriched | F11: Regular | G11: White | H11: 24802

Sheet Pallet Information
A1: NO# | B1: WK | C1: TAG# | D1: BARN | E1: QUAN | F1: NR | G1: GRADED IP | H1: PACK | I1: NET | J1: Packaging | K1: GROSS | L1: WT | M1: IP# | N1: SHIP DATE | O1: CLR | P1: AGE | Q1: Class
A2: Sample for Grading Station
B3: 5 | C3: 123456 | D3: 7168-C3 | E3: 60 | F3: NR | H3: OLD | I3: =K3-192 -> 1408 | J3: =IF(H3="NEW",203, IF(H3="OLD",192,0)) -> 192 | K3: 1600 | L3: =I3/E3 -> 23.466667 | M3: 789456 | N3: 43663 | O3: White | P3: 50
B4: 5 | C4: 123457 | D4: 7169-E6 | E4: 60 | G4: X L | H4: OLD | I4: =K4-J4 -> 1458 | J4: =IF(H4="NEW",203, IF(H4="OLD",192,0)) -> 192 | K4: 1650 | M4: 789456 | N4: 43663 | O4: White | P4: 30
B5: 5 | C5: 123458 | D5: 7168-C10 | E5: 60 | G5: LARGE | H5: NEW | I5: =K5-J5 -> 1497 | J5: =IF(H5="NEW",203, IF(H5="OLD",192,0)) -> 203 | K5: 1700 | M5: 789456 | N5: 43663 | O5: Brown
A7: 4 | B7: =Inputs!C$2 -> 47 | C7: 941220 | D7: 7168-E11 | E7: 60 | F7: NR | H7: NEW | I7: =IF(K7>0,K7-J7,"NA") -> 1227 | J7: =IF(H7="NEW",203, IF(H7="OLD",192,0)) -> 203 | K7: 1430 | L7: =IF(K7>0,I7/E7,"NA") -> 20.45 | M7: 135251 | N7: Nov 21/25 | O7: White | P7: =IF(D7=Inputs!F$4,Inputs!I$4,IF(D7=Inputs!F$2,Inputs!I$2,IF(D7=Inputs!F$3,Inputs!I$3,IF(D7=Inputs!F$5,Inputs!I$5,"NA")))) -> 24.607143 | Q7: =ROUNDDOWN(I7/60,0) -> 20
A8: 6 | B8: =Inputs!C$2 -> 47 | C8: 941221 | D8: 7168-E11 | E8: 60 | F8: NR | H8: NEW | I8: =IF(K8>0,K8-J8,"NA") -> 1233 | J8: =IF(H8="NEW",203, IF(H8="OLD",192,0)) -> 203 | K8: 1436 | L8: =IF(K8>0,I8/E8,"NA") -> 20.55 | M8: 135251 | N8: Nov 21/25 | O8: White | P8: =IF(D8=Inputs!F$4,Inputs!I$4,IF(D8=Inputs!F$2,Inputs!I$2,IF(D8=Inputs!F$3,Inputs!I$3,IF(D8=Inputs!F$5,Inputs!I$5,"NA")))) -> 24.607143 | Q8: =ROUNDDOWN(I8/60,0) -> 20
A9: 10 | B9: =Inputs!C$2 -> 47 | C9: 941222 | D9: 7168-E7 | E9: 60 | F9: NR | H9: NEW | I9: =IF(K9>0,K9-J9,"NA") -> 1497 | J9: =IF(H9="NEW",203, IF(H9="OLD",192,0)) -> 203 | K9: 1700 | L9: =IF(K9>0,I9/E9,"NA") -> 24.95 | M9: 135251 | N9: Nov 21/25 | O9: Brown | P9: =IF(D9=Inputs!F$4,Inputs!I$4,IF(D9=Inputs!F$2,Inputs!I$2,IF(D9=Inputs!F$3,Inputs!I$3,IF(D9=Inputs!F$5,Inputs!I$5,"NA")))) -> 58.892857 | Q9: =ROUNDDOWN(I9/60,0) -> 24
A10: 11 | B10: =Inputs!C$2 -> 47 | C10: 941223 | D10: 7168-E11 | E10: 60 | F10: NR | H10: NEW | I10: =IF(K10>0,K10-J10,"NA") -> 1239 | J10: =IF(H10="NEW",203, IF(H10="OLD",192,0)) -> 203 | K10: 1442 | L10: =IF(K10>0,I10/E10,"NA") -> 20.65 | M10: 135251 | N10: Nov 21/25 | O10: White | P10: =IF(D10=Inputs!F$4,Inputs!I$4,IF(D10=Inputs!F$2,Inputs!I$2,IF(D10=Inputs!F$3,Inputs!I$3,IF(D10=Inputs!F$5,Inputs!I$5,"NA")))) -> 24.607143 | Q10: =ROUNDDOWN(I10/60,0) -> 20
A11: 13 | B11: =Inputs!C$2 -> 47 | C11: 941224 | D11: 7169-E6 | E11: 60 | F11: NR | H11: NEW | I11: =IF(K11>0,K11-J11,"NA") -> 1353 | J11: =IF(H11="NEW",203, IF(H11="OLD",192,0)) -> 203 | K11: 1556 | L11: =IF(K11>0,I11/E11,"NA") -> 22.55 | M11: 135251 | N11: Nov 21/25 | O11: White | P11: =IF(D11=Inputs!F$4,Inputs!I$4,IF(D11=Inputs!F$2,Inputs!I$2,IF(D11=Inputs!F$3,Inputs!I$3,IF(D11=Inputs!F$5,Inputs!I$5,"NA")))) -> 33.464286 | Q11: =ROUNDDOWN(I11/60,0) -> 22
A12: 29 | B12: =Inputs!C$2 -> 47 | C12: 941225 | D12: 7169-E6 | E12: 60 | F12: NR | H12: NEW | I12: =IF(K12>0,K12-J12,"NA") -> 1479 | J12: =IF(H12="NEW",203, IF(H12="OLD",192,0)) -> 203 | K12: 1682 | L12: =IF(K12>0,I12/E12,"NA") -> 24.65 | M12: 135251 | N12: Nov 21/25 | O12: White | P12: =IF(D12=Inputs!F$4,Inputs!I$4,IF(D12=Inputs!F$2,Inputs!I$2,IF(D12=Inputs!F$3,Inputs!I$3,IF(D12=Inputs!F$5,Inputs!I$5,"NA")))) -> 33.464286 | Q12: =ROUNDDOWN(I12/60,0) -> 24
A13: 32 | B13: =Inputs!C$2 -> 47 | C13: 941226 | D13: 7169-E6 | E13: 60 | F13: NR | H13: NEW | I13: =IF(K13>0,K13-J13,"NA") -> 1479 | J13: =IF(H13="NEW",203, IF(H13="OLD",192,0)) -> 203 | K13: 1682 | L13: =IF(K13>0,I13/E13,"NA") -> 24.65 | M13: 135251 | N13: Nov 21/25 | O13: White | P13: =IF(D13=Inputs!F$4,Inputs!I$4,IF(D13=Inputs!F$2,Inputs!I$2,IF(D13=Inputs!F$3,Inputs!I$3,IF(D13=Inputs!F$5,Inputs!I$5,"NA")))) -> 33.464286 | Q13: =ROUNDDOWN(I13/60,0) -> 24
A14: 2 | B14: =Inputs!C$2 -> 47 | C14: 941227 | D14: 7169-E6 | E14: 60 | F14: NR | H14: NEW | I14: =IF(K14>0,K14-J14,"NA") -> 1469 | J14: =IF(H14="NEW",203, IF(H14="OLD",192,0)) -> 203 | K14: 1672 | L14: =IF(K14>0,I14/E14,"NA") -> 24.483333 | M14: 135251 | N14: Nov 21/25 | O14: White | P14: =IF(D14=Inputs!F$4,Inputs!I$4,IF(D14=Inputs!F$2,Inputs!I$2,IF(D14=Inputs!F$3,Inputs!I$3,IF(D14=Inputs!F$5,Inputs!I$5,"NA")))) -> 33.464286 | Q14: =ROUNDDOWN(I14/60,0) -> 24
A15: 3 | B15: =Inputs!C$2 -> 47 | C15: 941228 | D15: 7169-E10 | E15: 60 | F15: NR | H15: NEW | I15: =IF(K15>0,K15-J15,"NA") -> 1503 | J15: =IF(H15="NEW",203, IF(H15="OLD",192,0)) -> 203 | K15: 1706 | L15: =IF(K15>0,I15/E15,"NA") -> 25.05 | M15: 135251 | N15: Nov 21/25 | O15: White | P15: =IF(D15=Inputs!F$4,Inputs!I$4,IF(D15=Inputs!F$2,Inputs!I$2,IF(D15=Inputs!F$3,Inputs!I$3,IF(D15=Inputs!F$5,Inputs!I$5,"NA")))) -> 45.892857 | Q15: =ROUNDDOWN(I15/60,0) -> 25
A16: 9 | B16: =Inputs!C$2 -> 47 | C16: 941229 | D16: 7169-E10 | E16: 60 | F16: NR | H16: NEW | I16: =IF(K16>0,K16-J16,"NA") -> 1461 | J16: =IF(H16="NEW",203, IF(H16="OLD",192,0)) -> 203 | K16: 1664 | L16: =IF(K16>0,I16/E16,"NA") -> 24.35 | M16: 135251 | N16: Nov 21/25 | O16: White | P16: =IF(D16=Inputs!F$4,Inputs!I$4,IF(D16=Inputs!F$2,Inputs!I$2,IF(D16=Inputs!F$3,Inputs!I$3,IF(D16=Inputs!F$5,Inputs!I$5,"NA")))) -> 45.892857 | Q16: =ROUNDDOWN(I16/60,0) -> 24
A17: 12 | B17: =Inputs!C$2 -> 47 | C17: 941230 | D17: 7169-E10 | E17: 60 | F17: NR | H17: NEW | I17: =IF(K17>0,K17-J17,"NA") -> 1459 | J17: =IF(H17="NEW",203, IF(H17="OLD",192,0)) -> 203 | K17: 1662 | L17: =IF(K17>0,I17/E17,"NA") -> 24.316667 | M17: 135251 | N17: Nov 21/25 | O17: White | P17: =IF(D17=Inputs!F$4,Inputs!I$4,IF(D17=Inputs!F$2,Inputs!I$2,IF(D17=Inputs!F$3,Inputs!I$3,IF(D17=Inputs!F$5,Inputs!I$5,"NA")))) -> 45.892857 | Q17: =ROUNDDOWN(I17/60,0) -> 24
A18: 19 | B18: =Inputs!C$2 -> 47 | C18: 941231 | D18: 7168-E7 | E18: 60 | F18: NR | H18: NEW | I18: =IF(K18>0,K18-J18,"NA") -> 1453 | J18: =IF(H18="NEW",203, IF(H18="OLD",192,0)) -> 203 | K18: 1656 | L18: =IF(K18>0,I18/E18,"NA") -> 24.216667 | M18: 135251 | N18: Nov 21/25 | O18: White | P18: =IF(D18=Inputs!F$4,Inputs!I$4,IF(D18=Inputs!F$2,Inputs!I$2,IF(D18=Inputs!F$3,Inputs!I$3,IF(D18=Inputs!F$5,Inputs!I$5,"NA")))) -> 58.892857 | Q18: =ROUNDDOWN(I18/60,0) -> 24
... A37: 14 | B37: =Inputs!C$2 -> 47 | C37: 941250 | D37: 7168-E11 | E37: 60 | F37: NR | H37: NEW | I37: =IF(K37>0,K37-J37,"NA") -> 1299 | J37: =IF(H37="NEW",203, IF(H37="OLD",192,0)) -> 203 | K37: 1502 | L37: =IF(K37>0,I37/E37,"NA") -> 21.65 | M37: 135251 | N37: Nov 21/25 | O37: White | P37: =IF(D37=Inputs!F$4,Inputs!I$4,IF(D37=Inputs!F$2,Inputs!I$2,IF(D37=Inputs!F$3,Inputs!I$3,IF(D37=Inputs!F$5,Inputs!I$5,"NA")))) -> 24.607143 | Q37: =ROUNDDOWN(I37/60,0) -> 21
A38: 30 | B38: =Inputs!C$2 -> 47 | C38: 1262851 | D38: Graded IP | E38: 60 | G38: MED | H38: NEW | I38: =IF(K38>0,K38-J38,"NA") -> NA | J38: =IF(H38="NEW",203, IF(H38="OLD",192,0)) -> 203 | L38: =IF(K38>0,I38/E38,"NA") -> NA | M38: 135251 | N38: Nov 21/25 | O38: MED | P38: =IF(D38=Inputs!F$4,Inputs!I$4,IF(D38=Inputs!F$2,Inputs!I$2,IF(D38=Inputs!F$3,Inputs!I$3,IF(D38=Inputs!F$5,Inputs!I$5,"NA")))) -> NA
A39: 33 | B39: =Inputs!C$2 -> 47 | I39: =IF(K39>0,K39-J39,"NA") -> NA | J39: =IF(H39="NEW",203, IF(H39="OLD",192,0)) -> 0 | L39: =IF(K39>0,I39/E39,"NA") -> NA | P39: =IF(D39=Inputs!F$4,Inputs!I$4,IF(D39=Inputs!F$2,Inputs!I$2,IF(D39=Inputs!F$3,Inputs!I$3,IF(D39=Inputs!F$5,Inputs!I$5,"NA")))) -> NA
A40: 34 | B40: =Inputs!C$2 -> 47 | I40: =IF(K40>0,K40-J40,"NA") -> NA | J40: =IF(H40="NEW",203, IF(H40="OLD",192,0)) -> 0 | L40: =IF(K40>0,I40/E40,"NA") -> NA | P40: =IF(D40=Inputs!F$4,Inputs!I$4,IF(D40=Inputs!F$2,Inputs!I$2,IF(D40=Inputs!F$3,Inputs!I$3,IF(D40=Inputs!F$5,Inputs!I$5,"NA")))) -> NA
A41: 35 | B41: =Inputs!C$2 -> 47 | I41: =IF(K41>0,K41-J41,"NA") -> NA | J41: =IF(H41="NEW",203, IF(H41="OLD",192,0)) -> 0 | L41: =IF(K41>0,I41/E41,"NA") -> NA | P41: =IF(D41=Inputs!F$4,Inputs!I$4,IF(D41=Inputs!F$2,Inputs!I$2,IF(D41=Inputs!F$3,Inputs!I$3,IF(D41=Inputs!F$5,Inputs!I$5,"NA")))) -> NA
A42: 36 | B42: =Inputs!C$2 -> 47 | I42: =IF(K42>0,K42-J42,"NA") -> NA | J42: =IF(H42="NEW",203, IF(H42="OLD",192,0)) -> 0 | L42: =IF(K42>0,I42/E42,"NA") -> NA | P42: =IF(D42=Inputs!F$4,Inputs!I$4,IF(D42=Inputs!F$2,Inputs!I$2,IF(D42=Inputs!F$3,Inputs!I$3,IF(D42=Inputs!F$5,Inputs!I$5,"NA")))) -> NA
A43: 37 | B43: =Inputs!C$2 -> 47 | I43: =IF(K43>0,K43-J43,"NA") -> NA | J43: =IF(H43="NEW",203, IF(H43="OLD",192,0)) -> 0 | L43: =IF(K43>0,I43/E43,"NA") -> NA | P43: =IF(D43=Inputs!F$4,Inputs!I$4,IF(D43=Inputs!F$2,Inputs!I$2,IF(D43=Inputs!F$3,Inputs!I$3,IF(D43=Inputs!F$5,Inputs!I$5,"NA")))) -> NA
A44: 38 | B44: =Inputs!C$2 -> 47 | I44: =IF(K44>0,K44-J44,"NA") -> NA | J44: =IF(H44="NEW",203, IF(H44="OLD",192,0)) -> 0 | L44: =IF(K44>0,I44/E44,"NA") -> NA | P44: =IF(D44=Inputs!F$4,Inputs!I$4,IF(D44=Inputs!F$2,Inputs!I$2,IF(D44=Inputs!F$3,Inputs!I$3,IF(D44=Inputs!F$5,Inputs!I$5,"NA")))) -> NA
A45: 39 | B45: =Inputs!C$2 -> 47 | I45: =IF(K45>0,K45-J45,"NA") -> NA | J45: =IF(H45="NEW",203, IF(H45="OLD",192,0)) -> 0 | L45: =IF(K45>0,I45/E45,"NA") -> NA | P45: =IF(D45=Inputs!F$4,Inputs!I$4,IF(D45=Inputs!F$2,Inputs!I$2,IF(D45=Inputs!F$3,Inputs!I$3,IF(D45=Inputs!F$5,Inputs!I$5,"NA")))) -> NA
A46: 40 | B46: =Inputs!C$2 -> 47 | I46: =IF(K46>0,K46-J46,"NA") -> NA | J46: =IF(H46="NEW",203, IF(H46="OLD",192,0)) -> 0 | L46: =IF(K46>0,I46/E46,"NA") -> NA | P46: =IF(D46=Inputs!F$4,Inputs!I$4,IF(D46=Inputs!F$2,Inputs!I$2,IF(D46=Inputs!F$3,Inputs!I$3,IF(D46=Inputs!F$5,Inputs!I$5,"NA")))) -> NA
A47: 41 | B47: =Inputs!C$2 -> 47 | I47: =IF(K47>0,K47-J47,"NA") -> NA | J47: =IF(H47="NEW",203, IF(H47="OLD",192,0)) -> 0 | L47: =IF(K47>0,I47/E47,"NA") -> NA | P47: =IF(D47=Inputs!F$4,Inputs!I$4,IF(D47=Inputs!F$2,Inputs!I$2,IF(D47=Inputs!F$3,Inputs!I$3,IF(D47=Inputs!F$5,Inputs!I$5,"NA")))) -> NA
A48: 42 | B48: =Inputs!C$2 -> 47 | I48: =IF(K48>0,K48-J48,"NA") -> NA | J48: =IF(H48="NEW",203, IF(H48="OLD",192,0)) -> 0 | L48: =IF(K48>0,I48/E48,"NA") -> NA | P48: =IF(D48=Inputs!F$4,Inputs!I$4,IF(D48=Inputs!F$2,Inputs!I$2,IF(D48=Inputs!F$3,Inputs!I$3,IF(D48=Inputs!F$5,Inputs!I$5,"NA")))) -> NA
A49: 43 | B49: =Inputs!C$2 -> 47 | I49: =IF(K49>0,K49-J49,"NA") -> NA | J49: =IF(H49="NEW",203, IF(H49="OLD",192,0)) -> 0 | L49: =IF(K49>0,I49/E49,"NA") -> NA | P49: =IF(D49=Inputs!F$4,Inputs!I$4,IF(D49=Inputs!F$2,Inputs!I$2,IF(D49=Inputs!F$3,Inputs!I$3,IF(D49=Inputs!F$5,Inputs!I$5,"NA")))) -> NA
A50: 44 | B50: =Inputs!C$2 -> 47 | I50: =IF(K50>0,K50-J50,"NA") -> NA | J50: =IF(H50="NEW",203, IF(H50="OLD",192,0)) -> 0 | L50: =IF(K50>0,I50/E50,"NA") -> NA | P50: =IF(D50=Inputs!F$4,Inputs!I$4,IF(D50=Inputs!F$2,Inputs!I$2,IF(D50=Inputs!F$3,Inputs!I$3,IF(D50=Inputs!F$5,Inputs!I$5,"NA")))) -> NA
... A82: 76 | B82: =Inputs!C$2 -> 47 | I82: =IF(K82>0,K82-J82,"NA") -> NA | J82: =IF(H82="NEW",203, IF(H82="OLD",192,0)) -> 0 | L82: =IF(K82>0,I82/E82,"NA") -> NA | P82: =IF(D82=Inputs!F$4,Inputs!I$4,IF(D82=Inputs!F$2,Inputs!I$2,IF(D82=Inputs!F$3,Inputs!I$3,IF(D82=Inputs!F$5,Inputs!I$5,"NA")))) -> NA

Sheet Inputs
B1: Year | C1: 2025 | G1: Hatch Date | I1: Age | J1: Wks lay | K1: Pallets
B2: Week | C2: 47 | F2: 7169-E6 | G2: 45750 | I2: =(C$3-G2)/7 -> 33.464286 | J2: =I2-19 -> 14.464286 | K2: NEW | L2: 203 | N2: Barn 6 White | O2: NR Grid Size | P2: Nest Run | Q2: J/XL | S2: L | U2: M | W2: S | Y2: PW | AA2: B | AC2: C | AE2: Rej/Loss | AF2: NR Total | AG2: Total | AH2: NR Total
B3: Week Ending | C3: =C2*7+(C1-1900)*365.25-1 -> 45984.25 | F3: 7168-E7 | G3: 45572 | I3: =(C$3-G3)/7 -> 58.892857 | J3: =I3-19 -> 39.892857 | K3: OLD | L3: 192 | P3: J/XL | Q3: % | R3: L | S3: % | T3: M | U3: % | V3: S | W3: % | X3: PW | Y3: % | Z3: B | AA3: % | AB3: C | AC3: % | AD3: Rej/Loss | AE3: % | AF3: Dozens | AG3: % | AH3: boxes
F4: 7169-E10 | G4: 45663 | I4: =(C$3-G4)/7 -> 45.892857 | J4: =I4-19 -> 26.892857 | O4: NR 18 | P4: =AF4*Q4 -> 0 | Q4: 0.0076637186 | R4: =AF4*S4 -> 0 | S4: 0.012894787 | T4: =AF4*U4 -> 0 | U4: 0.13254414 | V4: =AF4*W4 -> 0 | W4: 0.59234214 | X4: =AF4*Y4 -> 0 | Y4: 0.23185875 | Z4: =AF4*AA4 -> 0 | AA4: 0.0053230558 | AB4: =AF4*AC4 -> 0 | AC4: 0.0069773179 | AD4: =AF4*AE4 -> 0 | AE4: 0.010396092 | AF4: =(AH4*15) -> 0 | AG4: =SUM(Q4+S4+U4+W4+Y4+AA4+AC4+AE4) -> 1
A5: Prepared by | B5: Pamela Penney | F5: 7168-E11 | G5: 45812 | I5: =(C$3-G5)/7 -> 24.607143 | J5: =I5-19 -> 5.6071429 | O5: NR 19 | P5: =AF5*Q5 -> 0 | Q5: 0.017661924 | R5: =AF5*S5 -> 0 | S5: 0.032802624 | T5: =AF5*U5 -> 0 | U5: 0.40487924 | V5: =AF5*W5 -> 0 | W5: 0.49075956 | X5: =AF5*Y5 -> 0 | Y5: 0.033546653 | Z5: =AF5*AA5 -> 0 | AA5: 0.00457031 | AB5: =AF5*AC5 -> 0 | AC5: 0.0070189159 | AD5: =AF5*AE5 -> 0 | AE5: 0.0087607728 | AF5: =(AH5*15) -> 0 | AG5: =SUM(Q5+S5+U5+W5+Y5+AA5+AC5+AE5) -> 1
O6: NR 20 | P6: =AF6*Q6 -> 0 | Q6: 0.018025455 | R6: =AF6*S6 -> 0 | S6: 0.087671513 | T6: =AF6*U6 -> 0 | U6: 0.64997329 | V6: =AF6*W6 -> 0 | W6: 0.2207866 | X6: =AF6*Y6 -> 0 | Y6: 0.0068178938 | Z6: =AF6*AA6 -> 0 | AA6: 0.0041829617 | AB6: =AF6*AC6 -> 0 | AC6: 0.0063973155 | AD6: =AF6*AE6 -> 0 | AE6: 0.0061449686 | AF6: =(AH6*15) -> 0 | AG6: =SUM(Q6+S6+U6+W6+Y6+AA6+AC6+AE6) -> 1
A7: PRODUCTION (# of stacks) | O7: NR 21 | P7: =AF7*Q7 -> 0 | Q7: 0.026348295 | R7: =AF7*S7 -> 0 | S7: 0.25469986 | T7: =AF7*U7 -> 0 | U7: 0.62709761 | V7: =AF7*W7 -> 0 | W7: 0.072177744 | X7: =AF7*Y7 -> 0 | Y7: 0.0012870032 | Z7: =AF7*AA7 -> 0 | AA7: 0.0035453016 | AB7: =AF7*AC7 -> 0 | AC7: 0.0070032903 | AD7: =AF7*AE7 -> 0 | AE7: 0.0078409029 | AF7: =(AH7*15) -> 0 | AG7: =SUM(Q7+S7+U7+W7+Y7+AA7+AC7+AE7) -> 1
A8: SUNDAY | E8: MONDAY | O8: NR 22 | P8: =AF8*Q8 -> 0 | Q8: 0.057422831 | R8: =AF8*S8 -> 0 | S8: 0.50285289 | T8: =AF8*U8 -> 0 | U8: 0.39999177 | V8: =AF8*W8 -> 0 | W8: 0.019053888 | X8: =AF8*Y8 -> 0 | Y8: 0.00033778317 | Z8: =AF8*AA8 -> 0 | AA8: 0.0036004615 | AB8: =AF8*AC8 -> 0 | AC8: 0.0084032775 | AD8: =AF8*AE8 -> 0 | AE8: 0.0083371027 | AF8: =(AH8*15) -> 0 | AG8: =SUM(Q8+S8+U8+W8+Y8+AA8+AC8+AE8) -> 1
A9: Barn | B9: White | C9: Brown | E9: Barn | F9: White | G9: Brown | O9: NR 23 | P9: =AF9*Q9 -> 155.31971 | Q9: 0.17257746 | R9: =AF9*S9 -> 548.42253 | S9: 0.60935836 | T9: =AF9*U9 -> 164.49727 | U9: 0.18277475 | V9: =AF9*W9 -> 3.3301054 | W9: 0.0037001171 | X9: =AF9*Y9 -> 0.18247127 | Y9: 0.00020274585 | Z9: =AF9*AA9 -> 2.8988268 | AA9: 0.0032209187 | AB9: =AF9*AC9 -> 16.070096 | AC9: 0.017855662 | AD9: =AF9*AE9 -> 9.27899 | AE9: 0.010309989 | AF9: =(AH9*15) -> 900 | AG9: =SUM(Q9+S9+U9+W9+Y9+AA9+AC9+AE9) -> 1 | AH9: 60
A10: 6 | B10: 260 | E10: 6 | F10: 270 | O10: NR 24 | P10: =AF10*Q10 -> 1317.4823 | Q10: 0.36596731 | R10: =AF10*S10 -> 1790.5324 | S10: 0.49737012 | T10: =AF10*U10 -> 304.09474 | U10: 0.08447076 | V10: =AF10*W10 -> 5.3088841 | W10: 0.00147469 | X10: =AF10*Y10 -> 0.70034647 | Y10: 0.00019454069 | Z10: =AF10*AA10 -> 20.336687 | AA10: 0.0056490796 | AB10: =AF10*AC10 -> 103.38489 | AC10: 0.028718025 | AD10: =AF10*AE10 -> 58.159693 | AE10: 0.01615547 | AF10: =(AH10*15) -> 3600 | AG10: =SUM(Q10+S10+U10+W10+Y10+AA10+AC10+AE10) -> 1 | AH10: 240
A11: 7 | B11: 182 | C11: 18 | E11: 7 | F11: 196 | G11: 22 | O11: Totals | P11: =SUM(P4:P10) -> 1472.802 | Q11: =P11/AF11 -> 0.32728934 | R11: =SUM(R4:R10) -> 2338.955 | S11: =R11/AF11 -> 0.51976777 | T11: =SUM(T4:T10) -> 468.59201 | U11: =T11/AF11 -> 0.10413156 | V11: =SUM(V4:V10) -> 8.6389894 | W11: =V11/AF11 -> 0.0019197754 | X11: =SUM(X4:X10) -> 0.88281774 | Y11: =X11/AF11 -> 0.00019618172 | Z11: =SUM(Z4:Z10) -> 23.235513 | AA11: =Z11/AF11 -> 0.0051634474 | AB11: =SUM(AB4:AB10) -> 119.45498 | AC11: =AB11/AF11 -> 0.026545552 | AD11: =SUM(AD4:AD10) -> 67.438683 | AE11: =AD11/AF11 -> 0.014986374 | AF11: =SUM(AF4:AF10) -> 4500 | AG11: =Q11+S11+U11+W11+Y11+AA11+AC11+AE11 -> 1 | AH11: =AF11/15 -> 300
A12: 10 | B12: 146 | C12: 10 | E12: 10 | F12: 151 | G12: 11
A13: 11 | B13: 105 | E13: 11 | F13: 110 | N13: Barn 7 White | O13: NR Grid Size | P13: Nest Run | Q13: J/XL | S13: L | U13: M | W13: S | Y13: PW | AA13: B | AC13: C | AE13: Rej/Loss | AF13: NR Total | AG13: Total | AH13: NR Total
A14: TUESDAY | E14: WEDNESDAY | P14: J/XL | Q14: % | R14: L | S14: % | T14: M | U14: % | V14: S | W14: % | X14: PW | Y14: % | Z14: B | AA14: % | AB14: C | AC14: % | AD14: Rej/Loss | AE14: % | AF14: Dozens | AG14: % | AH14: Boxes
A15: Barn | B15: White | C15: Brown | E15: Barn | F15: White | G15: Brown | O15: NR 18 | P15: =AF15*Q15 -> 0 | Q15: 0.0076637186 | R15: =AF15*S15 -> 0 | S15: 0.012894787 | T15: =AF15*U15 -> 0 | U15: 0.13254414 | V15: =AF15*W15 -> 0 | W15: 0.59234214 | X15: =AF15*Y15 -> 0 | Y15: 0.23185875 | Z15: =AF15*AA15 -> 0 | AA15: 0.0053230558 | AB15: =AF15*AC15 -> 0 | AC15: 0.0069773179 | AD15: =AF15*AE15 -> 0 | AE15: 0.010396092 | AF15: =(AH15*15) -> 0 | AG15: =SUM(Q15+S15+U15+W15+Y15+AA15+AC15+AE15) -> 1
A16: 6 | B16: 270 | E16: 6 | F16: 266 | O16: NR 19 | P16: =AF16*Q16 -> 0 | Q16: 0.017661924 | R16: =AF16*S16 -> 0 | S16: 0.032802624 | T16: =AF16*U16 -> 0 | U16: 0.40487924 | V16: =AF16*W16 -> 0 | W16: 0.49075956 | X16: =AF16*Y16 -> 0 | Y16: 0.033546653 | Z16: =AF16*AA16 -> 0 | AA16: 0.00457031 | AB16: =AF16*AC16 -> 0 | AC16: 0.0070189159 | AD16: =AF16*AE16 -> 0 | AE16: 0.0087607728 | AF16: =(AH16*15) -> 0 | AG16: =SUM(Q16+S16+U16+W16+Y16+AA16+AC16+AE16) -> 1
A17: 7 | B17: 204 | C17: 25 | E17: 7 | F17: 194 | G17: 22 | O17: NR 20 | P17: =AF17*Q17 -> 0 | Q17: 0.018025455 | R17: =AF17*S17 -> 0 | S17: 0.087671513 | T17: =AF17*U17 -> 0 | U17: 0.64997329 | V17: =AF17*W17 -> 0 | W17: 0.2207866 | X17: =AF17*Y17 -> 0 | Y17: 0.0068178938 | Z17: =AF17*AA17 -> 0 | AA17: 0.0041829617 | AB17: =AF17*AC17 -> 0 | AC17: 0.0063973155 | AD17: =AF17*AE17 -> 0 | AE17: 0.0061449686 | AF17: =(AH17*15) -> 0 | AG17: =SUM(Q17+S17+U17+W17+Y17+AA17+AC17+AE17) -> 1
A18: 10 | B18: 156 | C18: 12 | E18: 10 | F18: 157 | G18: 11 | O18: NR 21 | P18: =AF18*Q18 -> 0 | Q18: 0.026348295 | R18: =AF18*S18 -> 0 | S18: 0.25469986 | T18: =AF18*U18 -> 0 | U18: 0.62709761 | V18: =AF18*W18 -> 0 | W18: 0.072177744 | X18: =AF18*Y18 -> 0 | Y18: 0.0012870032 | Z18: =AF18*AA18 -> 0 | AA18: 0.0035453016 | AB18: =AF18*AC18 -> 0 | AC18: 0.0070032903 | AD18: =AF18*AE18 -> 0 | AE18: 0.0078409029 | AF18: =(AH18*15) -> 0 | AG18: =SUM(Q18+S18+U18+W18+Y18+AA18+AC18+AE18) -> 1
A19: 11 | B19: 153 | E19: 11 | F19: 115 | O19: NR 22 | P19: =AF19*Q19 -> 0 | Q19: 0.057422831 | R19: =AF19*S19 -> 0 | S19: 0.50285289 | T19: =AF19*U19 -> 0 | U19: 0.39999177 | V19: =AF19*W19 -> 0 | W19: 0.019053888 | X19: =AF19*Y19 -> 0 | Y19: 0.00033778317 | Z19: =AF19*AA19 -> 0 | AA19: 0.0036004615 | AB19: =AF19*AC19 -> 0 | AC19: 0.0084032775 | AD19: =AF19*AE19 -> 0 | AE19: 0.0083371027 | AF19: =(AH19*15) -> 0 | AG19: =SUM(Q19+S19+U19+W19+Y19+AA19+AC19+AE19) -> 1
O20: NR 23 | P20: =AF20*Q20 -> 155.31971 | Q20: 0.17257746 | R20: =AF20*S20 -> 548.42253 | S20: 0.60935836 | T20: =AF20*U20 -> 164.49727 | U20: 0.18277475 | V20: =AF20*W20 -> 3.3301054 | W20: 0.0037001171 | X20: =AF20*Y20 -> 0.18247127 | Y20: 0.00020274585 | Z20: =AF20*AA20 -> 2.8988268 | AA20: 0.0032209187 | AB20: =AF20*AC20 -> 16.070096 | AC20: 0.017855662 | AD20: =AF20*AE20 -> 9.27899 | AE20: 0.010309989 | AF20: =(AH20*15) -> 900 | AG20: =SUM(Q20+S20+U20+W20+Y20+AA20+AC20+AE20) -> 1 | AH20: 60
A21: THURSDAY | E21: FRIDAY | O21: NR 24 | P21: =AF21*Q21 -> 988.11175 | Q21: 0.36596731 | R21: =AF21*S21 -> 1342.8993 | S21: 0.49737012 | T21: =AF21*U21 -> 228.07105 | U21: 0.08447076 | V21: =AF21*W21 -> 3.981663 | W21: 0.00147469 | X21: =AF21*Y21 -> 0.52525986 | Y21: 0.00019454069 | Z21: =AF21*AA21 -> 15.252515 | AA21: 0.0056490796 | AB21: =AF21*AC21 -> 77.538666 | AC21: 0.028718025 | AD21: =AF21*AE21 -> 43.61977 | AE21: 0.01615547 | AF21: =(AH21*15) -> 2700 | AG21: =SUM(Q21+S21+U21+W21+Y21+AA21+AC21+AE21) -> 1 | AH21: 180
A22: Barn | B22: White | C22: Brown | E22: Barn | F22: White | G22: Brown | O22: Totals | P22: =SUM(P15:P21) -> 1143.4315 | Q22: =P22/AF22 -> 0.31761985 | R22: =SUM(R15:R21) -> 1891.3219 | S22: =R22/AF22 -> 0.52536718 | T22: =SUM(T15:T21) -> 392.56832 | U22: =T22/AF22 -> 0.10904676 | V22: =SUM(V15:V21) -> 7.3117684 | W22: =V22/AF22 -> 0.0020310468 | X22: =SUM(X15:X21) -> 0.70773112 | Y22: =X22/AF22 -> 0.00019659198 | Z22: =SUM(Z15:Z21) -> 18.151342 | AA22: =Z22/AF22 -> 0.0050420394 | AB22: =SUM(AB15:AB21) -> 93.608763 | AC22: =AB22/AF22 -> 0.026002434 | AD22: =SUM(AD15:AD21) -> 52.89876 | AE22: =AD22/AF22 -> 0.0146941 | AF22: =SUM(AF15:AF21) -> 3600 | AG22: =Q22+S22+U22+W22+Y22+AA22+AC22+AE22 -> 1 | AH22: =AF22/15 -> 240
A23: 6 | B23: 270 | E23: 6 | F23: 270
A24: 7 | B24: 192 | C24: 22 | E24: 7 | F24: 196 | G24: 22 | N24: Barn 7 Brown | O24: NR Grid Size | P24: Nest Run | Q24: J/XL | S24: L | U24: M | W24: S | Y24: PW | AA24: B | AC24: C | AE24: Rej/Loss | AF24: NR Total | AG24: Total | AH24: NR Total
A25: 10 | B25: 160 | C25: 11 | E25: 10 | F25: 154 | G25: 11 | P25: J/XL | Q25: % | R25: L | S25: % | T25: M | U25: % | V25: S | W25: % | X25: PW | Y25: % | Z25: B | AA25: % | AB25: C | AC25: % | AD25: Rej/Loss | AE25: % | AF25: Dozens | AG25: % | AH25: Boxes
A26: 11 | B26: 126 | E26: 11 | F26: 132 | O26: NR 18 | P26: =AF26*Q26 -> 0 | Q26: 0.0076637186 | R26: =AF26*S26 -> 0 | S26: 0.012894787 | T26: =AF26*U26 -> 0 | U26: 0.13254414 | V26: =AF26*W26 -> 0 | W26: 0.59234214 | X26: =AF26*Y26 -> 0 | Y26: 0.23185875 | Z26: =AF26*AA26 -> 0 | AA26: 0.0053230558 | AB26: =AF26*AC26 -> 0 | AC26: 0.0069773179 | AD26: =AF26*AE26 -> 0 | AE26: 0.010396092 | AF26: =AH26*15 -> 0 | AG26: =SUM(Q26+S26+U26+W26+Y26+AA26+AC26+AE26) -> 1
A27: SATURDAY | E27: TOTAL (stacks) | I27: TOTAL (dozens) | O27: NR 19 | P27: =AF27*Q27 -> 0 | Q27: 0.017661924 | R27: =AF27*S27 -> 0 | S27: 0.032802624 | T27: =AF27*U27 -> 0 | U27: 0.40487924 | V27: =AF27*W27 -> 0 | W27: 0.49075956 | X27: =AF27*Y27 -> 0 | Y27: 0.033546653 | Z27: =AF27*AA27 -> 0 | AA27: 0.00457031 | AB27: =AF27*AC27 -> 0 | AC27: 0.0070189159 | AD27: =AF27*AE27 -> 0 | AE27: 0.0087607728 | AF27: =AH27*15 -> 0 | AG27: =SUM(Q27+S27+U27+W27+Y27+AA27+AC27+AE27) -> 1
A28: Barn | B28: White | C28: Brown | E28: Barn | F28: White | G28: Brown | I28: Barn | J28: White | K28: Brown | O28: NR 20 | P28: =AF28*Q28 -> 0 | Q28: 0.018025455 | R28: =AF28*S28 -> 0 | S28: 0.087671513 | T28: =AF28*U28 -> 0 | U28: 0.64997329 | V28: =AF28*W28 -> 0 | W28: 0.2207866 | X28: =AF28*Y28 -> 0 | Y28: 0.0068178938 | Z28: =AF28*AA28 -> 0 | AA28: 0.0041829617 | AB28: =AF28*AC28 -> 0 | AC28: 0.0063973155 | AD28: =AF28*AE28 -> 0 | AE28: 0.0061449686 | AF28: =AH28*15 -> 0 | AG28: =SUM(Q28+S28+U28+W28+Y28+AA28+AC28+AE28) -> 1
A29: 6 | B29: 272 | E29: 6 | F29: =B10+F10+B16+F16+B23+F23+B29 -> 1878 | G29: =C10+G10+C16+G16+C23+G23+C29 -> 0 | I29: 6 | J29: =F29*15 -> 28170 | K29: =G29*15 -> 0 | O29: NR 21 | P29: =AF29*Q29 -> 0 | Q29: 0.026348295 | R29: =AF29*S29 -> 0 | S29: 0.25469986 | T29: =AF29*U29 -> 0 | U29: 0.62709761 | V29: =AF29*W29 -> 0 | W29: 0.072177744 | X29: =AF29*Y29 -> 0 | Y29: 0.0012870032 | Z29: =AF29*AA29 -> 0 | AA29: 0.0035453016 | AB29: =AF29*AC29 -> 0 | AC29: 0.0070032903 | AD29: =AF29*AE29 -> 0 | AE29: 0.0078409029 | AF29: =AH29*15 -> 0 | AG29: =SUM(Q29+S29+U29+W29+Y29+AA29+AC29+AE29) -> 1
A30: 7 | B30: 194 | C30: 22 | E30: 7 | F30: =B11+F11+B17+F17+B24+F24+B30 -> 1358 | G30: =C11+G11+C17+G17+C24+G24+C30 -> 153 | I30: 7 | J30: =F30*15 -> 20370 | K30: =G30*15 -> 2295 | O30: NR 22 | P30: =AF30*Q30 -> 0 | Q30: 0.057422831 | R30: =AF30*S30 -> 0 | S30: 0.50285289 | T30: =AF30*U30 -> 0 | U30: 0.39999177 | V30: =AF30*W30 -> 0 | W30: 0.019053888 | X30: =AF30*Y30 -> 0 | Y30: 0.00033778317 | Z30: =AF30*AA30 -> 0 | AA30: 0.0036004615 | AB30: =AF30*AC30 -> 0 | AC30: 0.0084032775 | AD30: =AF30*AE30 -> 0 | AE30: 0.0083371027 | AF30: =AH30*15 -> 0 | AG30: =SUM(Q30+S30+U30+W30+Y30+AA30+AC30+AE30) -> 1
A31: 10 | B31: 152 | C31: 11 | E31: 10 | F31: =B12+F12+B18+F18+B25+F25+B31 -> 1076 | G31: =C12+G12+C18+G18+C25+G25+C31 -> 77 | I31: 10 | J31: =F31*15 -> 16140 | K31: =G31*15 -> 1155 | O31: NR 23 | P31: =AF31*Q31 -> 0 | Q31: 0.17257746 | R31: =AF31*S31 -> 0 | S31: 0.60935836 | T31: =AF31*U31 -> 0 | U31: 0.18277475 | V31: =AF31*W31 -> 0 | W31: 0.0037001171 | X31: =AF31*Y31 -> 0 | Y31: 0.00020274585 | Z31: =AF31*AA31 -> 0 | AA31: 0.0032209187 | AB31: =AF31*AC31 -> 0 | AC31: 0.017855662 | AD31: =AF31*AE31 -> 0 | AE31: 0.010309989 | AF31: =AH31*15 -> 0 | AG31: =SUM(Q31+S31+U31+W31+Y31+AA31+AC31+AE31) -> 1
A32: 11 | B32: 129 | E32: 11 | F32: =B13+F13+B19+F19+B26+F26+B32 -> 870 | G32: =C13+G13+C19+G19+C26+G26+C32 -> 0 | I32: 11 | J32: =F32*15 -> 13050 | K32: =G32*180/12 -> 0 | O32: NR 24 | P32: =AF32*Q32 -> 988.11175 | Q32: 0.36596731 | R32: =AF32*S32 -> 1342.8993 | S32: 0.49737012 | T32: =AF32*U32 -> 228.07105 | U32: 0.08447076 | V32: =AF32*W32 -> 3.981663 | W32: 0.00147469 | X32: =AF32*Y32 -> 0.52525986 | Y32: 0.00019454069 | Z32: =AF32*AA32 -> 15.252515 | AA32: 0.0056490796 | AB32: =AF32*AC32 -> 77.538666 | AC32: 0.028718025 | AD32: =AF32*AE32 -> 43.61977 | AE32: 0.01615547 | AF32: =AH32*15 -> 2700 | AG32: =SUM(Q32+S32+U32+W32+Y32+AA32+AC32+AE32) -> 1 | AH32: 180
O33: Totals | P33: =SUM(P26:P32) -> 988.11175 | Q33: =P33/AF33 -> 0.36596731 | R33: =SUM(R26:R32) -> 1342.8993 | S33: =R33/AF33 -> 0.49737012 | T33: =SUM(T26:T32) -> 228.07105 | U33: =T33/AF33 -> 0.08447076 | V33: =SUM(V26:V32) -> 3.981663 | W33: =V33/AF33 -> 0.00147469 | X33: =SUM(X26:X32) -> 0.52525986 | Y33: =X33/AF33 -> 0.00019454069 | Z33: =SUM(Z26:Z32) -> 15.252515 | AA33: =Z33/AF33 -> 0.0056490796 | AB33: =SUM(AB26:AB32) -> 77.538666 | AC33: =AB33/AF33 -> 0.028718025 | AD33: =SUM(AD26:AD32) -> 43.61977 | AE33: =AD33/AF33 -> 0.01615547 | AF33: =SUM(AF26:AF32) -> 2700 | AG33: =Q33+S33+U33+W33+Y33+AA33+AC33+AE33 -> 1 | AH33: =AF33/15 -> 180
G34: NEST RUN TOTALS (Boxes/Stacks)
G35: Barn 6 White | I35: 300 | N35: Barn 10 White | O35: NR Grid Size | P35: Nest Run | Q35: J/XL | S35: L | U35: M | W35: S | Y35: PW | AA35: B | AC35: C | AE35: Rej/Loss | AF35: NR Total | AG35: Total | AH35: NR Total
G36: Barn 7 White | I36: 240 | P36: J/XL | Q36: % | R36: L | S36: % | T36: M | U36: % | V36: S | W36: % | X36: PW | Y36: % | Z36: B | AA36: % | AB36: C | AC36: % | AD36: Rej/Loss | AE36: % | AF36: Dozens | AG36: % | AH36: Boxes
G37: Barn 7 Brown | I37: 180 | O37: NR 18 | P37: =AF37*Q37 -> 0 | Q37: 0.0076637186 | R37: =AF37*S37 -> 0 | S37: 0.012894787 | T37: =AF37*U37 -> 0 | U37: 0.13254414 | V37: =AF37*W37 -> 0 | W37: 0.59234214 | X37: =AF37*Y37 -> 0 | Y37: 0.23185875 | Z37: =AF37*AA37 -> 0 | AA37: 0.0053230558 | AB37: =AF37*AC37 -> 0 | AC37: 0.0069773179 | AD37: =AF37*AE37 -> 0 | AE37: 0.010396092 | AF37: =(AH37*15) -> 0 | AG37: =SUM(Q37+S37+U37+W37+Y37+AA37+AC37+AE37) -> 1
G38: Barn 10 White | I38: 180 | O38: NR 19 | P38: =AF38*Q38 -> 0 | Q38: 0.017661924 | R38: =AF38*S38 -> 0 | S38: 0.032802624 | T38: =AF38*U38 -> 0 | U38: 0.40487924 | V38: =AF38*W38 -> 0 | W38: 0.49075956 | X38: =AF38*Y38 -> 0 | Y38: 0.033546653 | Z38: =AF38*AA38 -> 0 | AA38: 0.00457031 | AB38: =AF38*AC38 -> 0 | AC38: 0.0070189159 | AD38: =AF38*AE38 -> 0 | AE38: 0.0087607728 | AF38: =(AH38*15) -> 0 | AG38: =SUM(Q38+S38+U38+W38+Y38+AA38+AC38+AE38) -> 1
G39: Barn 10 Brown | I39: 0 | O39: NR 20 | P39: =AF39*Q39 -> 0 | Q39: 0.018025455 | R39: =AF39*S39 -> 0 | S39: 0.087671513 | T39: =AF39*U39 -> 0 | U39: 0.64997329 | V39: =AF39*W39 -> 0 | W39: 0.2207866 | X39: =AF39*Y39 -> 0 | Y39: 0.0068178938 | Z39: =AF39*AA39 -> 0 | AA39: 0.0041829617 | AB39: =AF39*AC39 -> 0 | AC39: 0.0063973155 | AD39: =AF39*AE39 -> 0 | AE39: 0.0061449686 | AF39: =(AH39*15) -> 0 | AG39: =SUM(Q39+S39+U39+W39+Y39+AA39+AC39+AE39) -> 1
G40: Barn 11 White | I40: 960 | O40: NR 21 | P40: =AF40*Q40 -> 0 | Q40: 0.026348295 | R40: =AF40*S40 -> 0 | S40: 0.25469986 | T40: =AF40*U40 -> 0 | U40: 0.62709761 | V40: =AF40*W40 -> 0 | W40: 0.072177744 | X40: =AF40*Y40 -> 0 | Y40: 0.0012870032 | Z40: =AF40*AA40 -> 0 | AA40: 0.0035453016 | AB40: =AF40*AC40 -> 0 | AC40: 0.0070032903 | AD40: =AF40*AE40 -> 0 | AE40: 0.0078409029 | AF40: =(AH40*15) -> 0 | AG40: =SUM(Q40+S40+U40+W40+Y40+AA40+AC40+AE40) -> 1
...

Sheet Procedures
A1: Procedure Information for Tabs
A3: Please save the completed workbook by each week number,year_grading station, I.e. Week 39, 2019_Hilly Acres Farm Ltd.
A5: Producer Number
A6: This tab is for information only.
A7: The information is used in the dropdowns on the pallet information tab.
A9: Hilly Acres Farm Ltd. (Weekly Summary Report)
A10: The reporting under this tab replaces the previous combined weekly marketing reports.
A11: You will note the reporting must be entered separately for each laying facility (barn).
A12: Enter the week # and week ending date in the yellow highlighted area.
A13: Enter the total weekly egg production in dozens from each laying facility (barn) in the green highlighted area
A14: Enter the weekly bird inventory number(s) for each laying facility in the orange highlighted area,
A15: Enter the individual grade out (by dozens and size) for each laying facility in the blue highlighted area.
... A39: 3. Complete the remaining yellow highlighted sections.

Sheet Producer Number
A1: Producer Number | B1: Producer Name
A2: 7169-E6 | B2: Theodore & Aaron Eyking Barn 6 - Enriched
A3: 7168-E7 | B3: Chris & Nico Eyking Barn 7 - Enriched
A4: 7169-E10 | B4: Theodore & Aaron Eyking Barn 10 - Enriched
A5: 7168-E11 | B5: Chris & Nico Eyking Barn 11 - Enriched
A6: Graded IP | B6: Graded IP
A8: Grades
A9: X L
A10: LARGE
A11: MED
A12: SMALL
A15: Packaging
A16: NEW | B16: Packaging weight - 203 (new pallet)
A17: OLD | B17: Packaging weight- 192 (old pallet)
