Workbook

Sheet Hilly Acres Farm Ltd.
A1: Hilly Acres Farm Ltd. | F1: Week # | G1: =Inputs!C2 -> 46
A2: WEEKLY SUMMARY REPORT | F2: Week ending | G2: =Inputs!C3 -> 45977.25
N3: TOTAL
C4: Prod | D4: Marketing | E4: Housing | H4: TOTAL DZ | I4: NESTRUN | J4: TOTAL DZ | M4: TOTAL DZ | N4: MKTABLE
A5: BARN | C5: # | D5: Type | E5: Type | F5: Egg Type | G5: Colour | H5: RECEIVED | I5: DOZEN | J5: FOR GRADE | K5: REJECTS | L5: LOSS | M5: REJECTS/LOSS | N5: EGGS | O5: JUMBO | P5: EX LG | Q5: LARGE | R5: MEDIUM | S5: SMALL | T5: B GRADE | U5: CRACKS | V5: PEE WEE
A7: Theodore & Aaron Eyking Barn 6 | C7: 7169 | D7: RE | E7: Enriched | F7: Regular | G7: White | H7: =IFERROR(M7+N7,"") -> 26130 | I7: 0 | J7: =IFERROR(H7-I7,"") -> 26130 | K7: =IFERROR(($E$26/($H$27+$H$28)*$H$27)*R28,"") -> 261.3 | L7: =IFERROR(($E$26/($H$27+$H$28)*$H$27)*S28,"") -> 52.26 | M7: =IFERROR(K7+L7,"") -> 313.56 | N7: =IFERROR(O7+P7+Q7+R7+S7+T7+U7+V7,"") -> 25816.44 | O7: =IFERROR(($E$26/($H$27+$H$28)*$H$27)*J28,"") -> 496.47 | P7: =IFERROR(($E$26/($H$27+$H$28)*$H$27)*K28,"") -> 6114.42 | Q7: =IFERROR(($E$26/($H$27+$H$28)*$H$27)*L28,"") -> 17376.45 | R7: =IFERROR(($E$26/($H$27+$H$28)*$H$27)*M28,"") -> 1776.84 | S7: =IFERROR(($E$26/($H$27+$H$28)*$H$27)*N28,"") -> 26.13 | T7: =IFERROR(($E$26/($H$27+$H$28)*$H$27)*O28,"") -> 0 | U7: =IFERROR(($E$26/($H$27+$H$28)*$H$27)*P28,"") -> 26.13 | V7: =IFERROR(($E$26/($H$27+$H$28)*$H$27)*Q28,"") -> 0
A8: Theodore & Aaron Eyking Barn 6 | C8: 7169 | D8: RE | E8: Enriched | F8: Regular | G8: Brown | H8: =IFERROR(M8+N8,"") -> 0 | I8: 0 | J8: =IFERROR(H8-I8,"") -> 0 | K8: =IFERROR(($E$26/($H$27+$H$28)*$H$28)*R28,"") -> 0 | L8: =IFERROR(($E$26/($H$27+$H$28)*$H$28)*S28,"") -> 0 | M8: =IFERROR(K8+L8,"") -> 0 | N8: =IFERROR(O8+P8+Q8+R8+S8+T8+U8+V8,"") -> 0 | O8: =IFERROR(($E$26/($H$27+$H$28)*$H$28)*J28,"") -> 0 | P8: =IFERROR(($E$26/($H$27+$H$28)*$H$28)*K28,"") -> 0 | Q8: =IFERROR(($E$26/($H$27+$H$28)*$H$28)*L28,"") -> 0 | R8: =IFERROR(($E$26/($H$27+$H$28)*$H$28)*M28,"") -> 0 | S8: =IFERROR(($E$26/($H$27+$H$28)*$H$28)*N28,"") -> 0 | T8: =IFERROR(($E$26/($H$27+$H$28)*$H$28)*O28,"") -> 0 | U8: =IFERROR(($E$26/($H$27+$H$28)*$H$28)*P28,"") -> 0 | V8: =IFERROR(($E$26/($H$27+$H$28)*$H$28)*Q28,"") -> 0
A10: Chris & Nico Eyking Barn 7 | C10: 7168 | D10: RE | E10: Enriched | F10: Regular | G10: White | H10: =IFERROR(M10+N10,"") -> 21795.948 | I10: 0 | J10: =IFERROR(H10-I10,"") -> 21795.948 | K10: =IFERROR(($E$30/($H$31+$H$32)*$H$31)*R32,"") -> 217.95948 | L10: =IFERROR(($E$30/($H$31+$H$32)*$H$31)*S32,"") -> 43.591896 | M10: =IFERROR(K10+L10,"") -> 261.55137 | N10: =IFERROR(O10+P10+Q10+R10+S10+T10+U10+V10,"") -> 21534.396 | O10: =IFERROR(($E$30/($H$31+$H$32)*$H$31)*J32,"") -> 414.12301 | P10: =IFERROR(($E$30/($H$31+$H$32)*$H$31)*K32,"") -> 5100.2518 | Q10: =IFERROR(($E$30/($H$31+$H$32)*$H$31)*L32,"") -> 14494.305 | R10: =IFERROR(($E$30/($H$31+$H$32)*$H$31)*M32,"") -> 1482.1245 | S10: =IFERROR(($E$30/($H$31+$H$32)*$H$31)*N32,"") -> 21.795948 | T10: =IFERROR(($E$30/($H$31+$H$32)*$H$31)*O32,"") -> 0 | U10: =IFERROR(($E$30/($H$31+$H$32)*$H$31)*P32,"") -> 21.795948 | V10: =IFERROR(($E$30/($H$31+$H$32)*$H$31)*Q32,"") -> 0
A11: Chris & Nico Eyking Barn 7 | C11: 7168 | D11: RE | E11: Enriched | F11: Regular | G11: Brown | H11: =IFERROR(M11+N11,"") -> 2414.0522 | I11: 0 | J11: =IFERROR(H11-I11,"") -> 2414.0522 | K11: =IFERROR(($E$30/($H$31+$H$32)*$H$32)*R32,"") -> 24.140522 | L11: =IFERROR(($E$30/($H$31+$H$32)*$H$32)*S32,"") -> 4.8281044 | M11: =IFERROR(K11+L11,"") -> 28.968626 | N11: =IFERROR(O11+P11+Q11+R11+S11+T11+U11+V11,"") -> 2385.0836 | O11: =IFERROR(($E$30/($H$31+$H$32)*$H$32)*J32,"") -> 45.866991 | P11: =IFERROR(($E$30/($H$31+$H$32)*$H$32)*K32,"") -> 564.88821 | Q11: =IFERROR(($E$30/($H$31+$H$32)*$H$32)*L32,"") -> 1605.3447 | R11: =IFERROR(($E$30/($H$31+$H$32)*$H$32)*M32,"") -> 164.15555 | S11: =IFERROR(($E$30/($H$31+$H$32)*$H$32)*N32,"") -> 2.4140522 | T11: =IFERROR(($E$30/($H$31+$H$32)*$H$32)*O32,"") -> 0 | U11: =IFERROR(($E$30/($H$31+$H$32)*$H$32)*P32,"") -> 2.4140522 | V11: =IFERROR(($E$30/($H$31+$H$32)*$H$32)*Q32,"") -> 0
A13: Theodore & Aaron Eyking Barn 10 | C13: 7169 | D13: RE | E13: Enriched | F13: Regular | G13: White | H13: =IFERROR(M13+N13,"") -> 17051.708 | I13: 0 | J13: =IFERROR(H13-I13,"") -> 17051.708 | K13: =IFERROR(($E$34/($H$35+$H$36)*$H$35)*R36,"") -> 102.31025 | L13: =IFERROR(($E$34/($H$35+$H$36)*$H$35)*S36,"") -> 34.103416 | M13: =IFERROR(K13+L13,"") -> 136.41367 | N13: =IFERROR(O13+P13+Q13+R13+S13+T13+U13+V13,"") -> 16915.295 | O13: =IFERROR(($E$34/($H$35+$H$36)*$H$35)*J36,"") -> 1040.1542 | P13: =IFERROR(($E$34/($H$35+$H$36)*$H$35)*K36,"") -> 6087.4598 | Q13: =IFERROR(($E$34/($H$35+$H$36)*$H$35)*L36,"") -> 9054.4571 | R13: =IFERROR(($E$34/($H$35+$H$36)*$H$35)*M36,"") -> 699.12004 | S13: =IFERROR(($E$34/($H$35+$H$36)*$H$35)*N36,"") -> 17.051708 | T13: =IFERROR(($E$34/($H$35+$H$36)*$H$35)*O36,"") -> 0 | U13: =IFERROR(($E$34/($H$35+$H$36)*$H$35)*P36,"") -> 17.051708 | V13: =IFERROR(($E$34/($H$35+$H$36)*$H$35)*Q36,"") -> 0
A14: Theodore & Aaron Eyking Barn 10 | C14: 7169 | D14: RE | E14: Enriched | F14: Regular | G14: Brown | H14: =IFERROR(M14+N14,"") -> 1143.2918 | I14: 0 | J14: =IFERROR(H14-I14,"") -> 1143.2918 | K14: =IFERROR(($E$34/($H$35+$H$36)*$H$36)*R36,"") -> 6.8597506 | L14: =IFERROR(($E$34/($H$35+$H$36)*$H$36)*S36,"") -> 2.2865835 | M14: =IFERROR(K14+L14,"") -> 9.1463341 | N14: =IFERROR(O14+P14+Q14+R14+S14+T14+U14+V14,"") -> 1134.1454 | O14: =IFERROR(($E$34/($H$35+$H$36)*$H$36)*J36,"") -> 69.740797 | P14: =IFERROR(($E$34/($H$35+$H$36)*$H$36)*K36,"") -> 408.15516 | Q14: =IFERROR(($E$34/($H$35+$H$36)*$H$36)*L36,"") -> 607.08792 | R14: =IFERROR(($E$34/($H$35+$H$36)*$H$36)*M36,"") -> 46.874962 | S14: =IFERROR(($E$34/($H$35+$H$36)*$H$36)*N36,"") -> 1.1432918 | T14: =IFERROR(($E$34/($H$35+$H$36)*$H$36)*O36,"") -> 0 | U14: =IFERROR(($E$34/($H$35+$H$36)*$H$36)*P36,"") -> 1.1432918 | V14: =IFERROR(($E$34/($H$35+$H$36)*$H$36)*Q36,"") -> 0
A16: Chris & Nico Eyking Barn 11 | C16: 7168 | D16: RE | E16: Enriched | F16: Regular | G16: White | H16: =IFERROR(M16+N16,"") -> 0 | I16: 0 | J16: =IFERROR(H16-I16,"") -> 0 | K16: =IFERROR(($E$38/($H$39)*$H$39)*R40,"") -> 0 | L16: =IFERROR(($E$38/($H$39)*$H$39)*S40,"") -> 0 | M16: =IFERROR(K16+L16,"") -> 0 | N16: =IFERROR(O16+P16+Q16+R16+S16+T16+U16+V16,"") -> 0 | O16: =IFERROR(($E$38/($H$39)*$H$39)*J40,"") -> 0 | P16: =IFERROR(($E$38/($H$39)*$H$39)*K40,"") -> 0 | Q16: =IFERROR(($E$38/($H$39)*$H$39)*L40,"") -> 0 | R16: =IFERROR(($E$38/($H$39)*$H$39)*M40,"") -> 0 | S16: =IFERROR(($E$38/($H$39)*$H$39)*N40,"") -> 0 | T16: =IFERROR(($E$38/($H$39)*$H$39)*O40,"") -> 0 | U16: =IFERROR(($E$38/($H$39)*$H$39)*P40,"") -> 0 | V16: =IFERROR(($E$38/($H$39)*$H$39)*Q40,"") -> 0
A19: Totals | H19: =SUM(H7:H18) -> 68535 | I19: =SUM(I7:I18) -> 0 | J19: =SUM(J7:J18) -> 68535 | K19: =SUM(K7:K18) -> 612.57 | L19: =SUM(L7:L18) -> 137.07 | M19: =SUM(M7:M18) -> 749.64 | N19: =SUM(N7:N18) -> 67785.36 | O19: =SUM(O7:O18) -> 2066.355 | ... V19: =SUM(V7:V18) -> 0
N21: =M19+N19 -> 68535
A22: **Email this to Lorraine Ryan, IP Office, email address: lorraine@nsegg.ca
H24: BIRD INVENTORY FOR WEEK | J24: JUMBO | K24: EX LG | L24: LARGE | M24: MEDIUM | N24: SMALL | O24: B GRADE | P24: CRACKS | Q24: PEE WEE | R24: REJECTS | S24: LOSS | T24: TOTAL DOZEN
A26: Barn 6 total dozen production for the week | E26: =Inputs!J29 -> 26130
A27: Theodore & Aaron Eyking Barn 6 | C27: 7169 | D27: RE | E27: Enriched | F27: Regular | G27: White | H27: ='Bird Inventory'!H3 -> 49042 | J27: =$E26*J28 -> 496.47 | K27: =$E26*K28 -> 6114.42 | L27: =$E26*L28 -> 17376.45 | M27: =$E26*M28 -> 1776.84 | N27: =$E26*N28 -> 26.13 | O27: =$E26*O28 -> 0 | P27: =$E26*P28 -> 26.13 | Q27: =$E26*Q28 -> 0 | ... S27: =$E26*S28 -> 52.26 | T27: =SUM(J27:S27) -> 26130
J28: =Inputs!B37 -> 0.019 | K28: =Inputs!B38 -> 0.234 | L28: =Inputs!B39 -> 0.665 | M28: =Inputs!B40 -> 0.068 | N28: =Inputs!B41 -> 0.001 | O28: 0 | P28: =Inputs!B49 -> 0.001 | Q28: =Inputs!B42 -> 0 | R28: =Inputs!B48+Inputs!B50 -> 0.01 | S28: =Inputs!B47 -> 0.002 | T28: =SUM(J28:S28) -> 1
A30: Barn 7 total dozen production for the week | E30: =Inputs!J30+Inputs!K30 -> 24210
A31: Chris & Nico Eyking Barn 7 | C31: 7168 | D31: RE | E31: Enriched | F31: Regular | G31: White | H31: ='Bird Inventory'!H5 -> 34508 | J31: =$E30*J32 -> 459.99 | K31: =$E30*K32 -> 5665.14 | L31: =$E30*L32 -> 16099.65 | M31: =$E30*M32 -> 1646.28 | N31: =$E30*N32 -> 24.21 | O31: =$E30*O32 -> 0 | P31: =$E30*P32 -> 24.21 | Q31: =$E30*Q32 -> 0 | ... S31: =$E30*S32 -> 48.42 | T31: =SUM(J31:S31) -> 24210
A32: Chris & Nico Eyking Barn 7 | C32: 7168 | D32: RE | E32: Enriched | F32: Regular | G32: Brown | H32: ='Bird Inventory'!H6 -> 3822 | J32: =Inputs!C37 -> 0.019 | K32: =Inputs!C38 -> 0.234 | L32: =Inputs!C39 -> 0.665 | M32: =Inputs!C40 -> 0.068 | N32: =Inputs!C41 -> 0.001 | O32: 0 | P32: =Inputs!C49 -> 0.001 | Q32: =Inputs!C42 -> 0 | R32: =Inputs!C48+Inputs!C50 -> 0.01 | S32: =Inputs!C47 -> 0.002 | T32: =SUM(J32:S32) -> 1
A34: Barn 10 total dozen production for the week | E34: =Inputs!J31+Inputs!K31 -> 18195
A35: Theodore & Aaron Eyking Barn 10 | C35: 7169 | D35: RE | E35: Enriched | F35: Regular | G35: White | H35: ='Bird Inventory'!H8 -> 29680 | J35: =$E$34*J36 -> 1109.895 | K35: =$E$34*K36 -> 6495.615 | L35: =$E$34*L36 -> 9661.545 | M35: =$E$34*M36 -> 745.995 | N35: =$E$34*N36 -> 18.195 | O35: =$E$34*O36 -> 0 | P35: =$E$34*P36 -> 18.195 | Q35: =$E$34*Q36 -> 0 | ... S35: =$E$34*S36 -> 36.39 | T35: =SUM(J35:S35) -> 18195
A36: Theodore & Aaron Eyking Barn 10 | C36: 7169 | D36: RE | E36: Enriched | F36: Regular | G36: Brown | H36: ='Bird Inventory'!H9 -> 1990 | J36: =Inputs!D37 -> 0.061 | K36: =Inputs!D38 -> 0.357 | L36: =Inputs!D39 -> 0.531 | M36: =Inputs!D40 -> 0.041 | N36: =Inputs!D41 -> 0.001 | O36: 0 | P36: =Inputs!D49 -> 0.001 | Q36: =Inputs!D42 -> 0 | R36: =Inputs!D50+Inputs!D48 -> 0.006 | S36: =Inputs!D47 -> 0.002 | T36: =SUM(J36:S36) -> 1
A38: Barn 11 total dozen production for the week | E38: =Inputs!J32 -> 10155
A39: Chris & Nico Eyking Barn 11 | C39: 7168 | D39: RE | E39: Enriched | F39: Regular | G39: White | H39: ='Bird Inventory'!H11 -> 24802 | J39: =$E38*J40 -> 0 | K39: =$E38*K40 -> 0 | L39: =$E38*L40 -> 0 | M39: =$E38*M40 -> 0 | N39: =$E38*N40 -> 0 | O39: =$E38*O40 -> 0 | P39: =$E38*P40 -> 0 | Q39: =$E38*Q40 -> 0 | ... S39: =$E38*S40 -> 0 | T39: =SUM(J39:S39) -> 0
J40: =Inputs!E37 -> 0 | K40: =Inputs!E38 -> 0 | L40: =Inputs!E39 -> 0 | M40: =Inputs!E40 -> 0 | N40: =Inputs!E41 -> 0 | O40: 0 | P40: =Inputs!E49 -> 0 | Q40: =Inputs!E42 -> 0 | R40: =Inputs!E48+Inputs!E50 -> 0 | S40: =Inputs!E47 -> 0 | T40: =SUM(J40:S40) -> 0

Sheet Declaration Summary
A1: NS IP DECLARATION
A3: DATE: | B3: =Inputs!C3 -> 45977.25
A5: TO: | B5: Egg Farmers of Nova Scotia | F5: PREPARED BY
B6: Email: Lorraine @nsegg.ca | F6: =Inputs!B5 -> Pamela Penney
A7: FROM: | B7: Hilly Acres Farm Ltd.
A9: RE: | B9: SURPLUS EGGS WEEK # | E9: =Inputs!C2 -> 46
B12: Boxes | C12: Dozens
A13: Nest Run | B13: =C13/15 -> 1200 | C13: ='Grade out Information'!X26 -> 18000
A15: Graded X Large White | B15: =C15/15 -> 0 | C15: ='Grade out Information'!C11 -> 0
A16: Graded X Large Brown | B16: =C16/15 -> 0 | C16: ='Grade out Information'!C12 -> 0
A18: Graded Large White | B18: =C18/15 -> 0 | C18: ='Grade out Information'!D11 -> 0
A19: Graded Large Brown | B19: =C19/15 -> 0 | C19: ='Grade out Information'!D12 -> 0
A21: Graded Medium White | B21: =C21/15 -> 0 | C21: ='Grade out Information'!E11 -> 0
A22: Graded Medium Brown | B22: =C22/15 -> 0 | C22: ='Grade out Information'!E12 -> 0
A24: Graded Small White | B24: =C24/15 -> 0 | C24: ='Grade out Information'!F11 -> 0
A25: Graded Small Brown | B25: =C25/15 -> 0 | C25: ='Grade out Information'!F12 -> 0
A27: TOTAL: | B27: =SUM(B13:B26) -> 1200 | C27: =SUM(C13:C26) -> 18000
B29: Left | C29: Left | D29: Left | E29: Declared | F29: Already | G29: Total
A30: BOXES | B30: From WK # | C30: From WK # | D30: From WK # | E30: WK # | F30: Shipped wk # | G30: on
G31: Hand
A32: Nest Run | E32: 0 | G32: =SUM(B32:E32)-F32 -> 0
A34: Graded X Large- White | E34: =('Grade out Information'!C11)/15 -> 0 | G34: =SUM(B34:E34)-F34 -> 0
A35: Graded X Large- Brown | E35: =('Grade out Information'!C12)/15 -> 0 | G35: =SUM(B35:E35)-F35 -> 0
A36: Graded Large- White | E36: =('Grade out Information'!D11)/15 -> 0 | G36: =SUM(B36:E36)-F36 -> 0
A37: Graded Large- Brown | E37: =('Grade out Information'!D12)/15 -> 0 | G37: =SUM(B37:E37)-F37 -> 0
A38: Graded Medium- White | E38: 0 | G38: =SUM(B38:E38)-F38 -> 0
A39: Graded Medium- Brown | E39: =('Grade out Information'!E12)/15 -> 0 | G39: =SUM(B39:E39)-F39 -> 0
A40: Graded Small- White | E40: =('Grade out Information'!F11)/15 -> 0 | G40: =SUM(B40:E40)-F40 -> 0
A41: Graded Small- Brown | E41: =('Grade out Information'!F12)/15 -> 0 | G41: =SUM(B41:E41)-F41 -> 0
A42: TOTAL: | B42: =SUM(B32:B41) -> 0 | C42: =SUM(C32:C41) -> 0 | D42: =SUM(D32:D41) -> 0 | E42: =SUM(E32:E41) -> 0 | F42: =SUM(F32:F41) -> 0 | G42: =SUM(G32:G41) -> 0

Sheet Grade out Information
A1: IP Breakdown to determine percentages and weights for the various IP Shippers
A3: Egg Farmers of Nova Scotia
A4: Hilly Acres Farm Ltd.
A7: Week | B7: Location | C7: Graded IP Dozens | G7: Graded Total | H7: Graded Total | I7: % of total | J7: Nest Run | K7: J/XL | M7: L | O7: M | Q7: S | S7: PW | U7: B | W7: UG | X7: NR Total | Y7: Total | Z7: NR Total | AA7: % of total | AB7: Grand Total | AC7: Grand Total | AD7: % of total
A8: =Inputs!C2 -> 46 | C8: XL | D8: L | E8: M | F8: S | G8: Dozens | H8: Boxes | I8: Graded | J8: J/XL | K8: % | L8: L | M8: % | N8: M | O8: % | P8: S | Q8: % | R8: PW | S8: % | T8: B | U8: % | V8: UG | W8: % | X8: Dozens | Y8: % | Z8: Boxes | AA8: NR | AB8: Dozens | AC8: Boxes | AD8: IP
B9: GRADED IP INFORMATION
B11: Graded - White | E11: =Inputs!I41*15 -> 0 | G11: =SUM(C11:F11) -> 0 | H11: =G11/15 -> 0
B12: Graded - Brown | G12: =SUM(C12:F12) -> 0 | H12: =G12/15 -> 0
B14: NR GRADE OUT INFORMATION
B15: Theodore & Aaron Eyking Barn 6 - White | I15: =J15+L15+N15+P15+R15+T15+V15 -> 5400 | J15: =X15*K15 -> 1366.2 | K15: =Inputs!B36 -> 0.253 | L15: =X15*M15 -> 3591 | M15: =Inputs!B39 -> 0.665 | N15: =X15*O15 -> 367.2 | O15: =Inputs!B40 -> 0.068 | P15: =X15*Q15 -> 5.4 | Q15: =Inputs!B41 -> 0.001 | R15: =X15*S15 -> 0 | S15: =Inputs!B42 -> 0 | T15: =X15*U15 -> 0 | U15: 0 | V15: =X15*W15 -> 70.2 | W15: =Inputs!B43 -> 0.013 | X15: =Z15*15 -> 5400 | Y15: =K15+M15+O15+Q15+S15+U15+W15 -> 1 | Z15: =Inputs!I35 -> 360
B17: Chris & Nico Eyking Barn 7 - White | I17: =J17+L17+N17+P17+R17+T17+V17 -> 2700 | J17: =X17*K17 -> 683.1 | K17: =Inputs!C36 -> 0.253 | L17: =X17*M17 -> 1795.5 | M17: =Inputs!C39 -> 0.665 | N17: =X17*O17 -> 183.6 | O17: =Inputs!C40 -> 0.068 | P17: =X17*Q17 -> 2.7 | Q17: =Inputs!C41 -> 0.001 | R17: =X17*S17 -> 0 | S17: =Inputs!C42 -> 0 | T17: =X17*U17 -> 0 | U17: 0 | V17: =X17*W17 -> 35.1 | W17: =Inputs!C43 -> 0.013 | X17: =Z17*15 -> 2700 | Y17: =K17+M17+O17+Q17+S17+U17+W17 -> 1 | Z17: =Inputs!I36 -> 180
B18: Chris & Nico Eyking Barn 7 - Brown | I18: =J18+L18+N18+P18+R18+T18+V18 -> 900 | J18: =X18*K18 -> 227.7 | K18: =K17 -> 0.253 | L18: =X18*M18 -> 598.5 | M18: =M17 -> 0.665 | N18: =X18*O18 -> 61.2 | O18: =O17 -> 0.068 | P18: =X18*Q18 -> 0.9 | Q18: =Q17 -> 0.001 | R18: =X18*S18 -> 0 | S18: =S17 -> 0 | T18: =X18*U18 -> 0 | U18: 0 | V18: =X18*W18 -> 11.7 | W18: =W17 -> 0.013 | X18: =Z18*15 -> 900 | Y18: =K18+M18+O18+Q18+S18+U18+W18 -> 1 | Z18: =Inputs!I37 -> 60
B20: Theodore & Aaron Eyking Barn 10 - White | I20: =J20+L20+N20+P20+R20+T20+V20 -> 3450 | J20: =X20*K20 -> 1442.1 | K20: =Inputs!D36 -> 0.418 | L20: =X20*M20 -> 1831.95 | M20: =Inputs!D39 -> 0.531 | N20: =X20*O20 -> 141.45 | O20: =Inputs!D40 -> 0.041 | P20: =X20*Q20 -> 3.45 | Q20: =Inputs!D41 -> 0.001 | R20: =X20*S20 -> 0 | S20: =Inputs!D42 -> 0 | T20: =X20*U20 -> 0 | U20: 0 | V20: =X20*W20 -> 31.05 | W20: =Inputs!D43 -> 0.009 | X20: =Z20*15 -> 3450 | Y20: =K20+M20+O20+Q20+S20+U20+W20 -> 1 | Z20: =Inputs!I38 -> 230
B21: Theodore & Aaron Eyking Barn 10 - Brown | I21: =J21+L21+N21+P21+R21+T21+V21 -> 150 | J21: =X21*K21 -> 62.7 | K21: =K20 -> 0.418 | L21: =X21*M21 -> 79.65 | M21: =M20 -> 0.531 | N21: =X21*O21 -> 6.15 | O21: =O20 -> 0.041 | P21: =X21*Q21 -> 0.15 | Q21: =Q20 -> 0.001 | R21: =X21*S21 -> 0 | S21: =S20 -> 0 | T21: =X21*U21 -> 0 | U21: 0 | V21: =X21*W21 -> 1.35 | W21: =W20 -> 0.009 | X21: =Z21*15 -> 150 | Y21: =K21+M21+O21+Q21+S21+U21+W21 -> 1 | Z21: =Inputs!I39 -> 10
B23: Chris & Nico Eyking Barn 11 - White | I23: =J23+L23+N23+P23+R23+T23+V23 -> 0 | J23: =X23*K23 -> 0 | K23: =Inputs!E36 -> 0 | L23: =X23*M23 -> 0 | M23: =Inputs!E39 -> 0 | N23: =X23*O23 -> 0 | O23: =Inputs!E40 -> 0 | P23: =X23*Q23 -> 0 | Q23: =Inputs!E41 -> 0 | R23: =X23*S23 -> 0 | S23: =Inputs!E42 -> 0 | T23: =X23*U23 -> 0 | U23: 0 | V23: =X23*W23 -> 0 | W23: =Inputs!E43 -> 0 | X23: =Z23*15 -> 5400 | Y23: =K23+M23+O23+Q23+S23+U23+W23 -> 0 | Z23: =Inputs!I40 -> 360
B26: Totals | C26: =SUM(C11:C25) -> 0 | D26: =SUM(D11:D25) -> 0 | E26: =SUM(E11:E25) -> 0 | F26: =SUM(F11:F25) -> 0 | G26: =G11+G12 -> 0 | H26: =SUM(H11+H12) -> 0 | J26: =SUM(J15:J25) -> 3781.8 | L26: =SUM(L15:L25) -> 7896.6 | N26: =SUM(N15:N25) -> 759.6 | P26: =SUM(P15:P25) -> 12.6 | R26: =SUM(R15:R25) -> 0 | T26: =SUM(T15:T25) -> 0 | V26: =SUM(V15:V25) -> 149.4 | X26: =SUM(X15:X25) -> 18000 | Z26: =SUM(Z15:Z25) -> 1200 | AA26: =IF(Z33=0,0,Z33/(H33+Z33)) -> 0 | AB26: =G26+X26 -> 18000 | AC26: =H26+Z26 -> 1200 | AD26: =I26+AA26 -> 0
A30: J/XL | B30: =J26 -> 3781.8
A31: L | B31: =L26 -> 7896.6
A32: M | B32: =N26 -> 759.6
A33: S | B33: =P26 -> 12.6
A34: PW | B34: =R26 -> 0
A35: B | B35: =T26 -> 0
A36: UG | B36: =V26 -> 149.4
A38: TOTAL | B38: =SUM(B30:B36) -> 12600

Sheet Bird Inventory
A1: Bird Inventory
A3: Theodore & Aaron Eyking Barn 6 | C3: 7169 | D3: RE | E3: Enriched | F3: Regular | G3: White | H3: 49042
A5: Chris & Nico Eyking Barn 7 | C5: 7168 | D5: RE | E5: Enriched | F5: Regular | G5: White | H5: 34508
A6: Chris & Nico Eyking Barn 7 | C6: 7168 | D6: RE | E6: Enriched | F6: Regular | G6: Brown | H6: 3822
A8: Theodore & Aaron Eyking Barn 10 | C8: 7168 | D8: RE | E8: Enriched | F8: Regular | G8: White | H8: 29680
A9: Theodore & Aaron Eyking Barn 10 | C9: 7168 | D9: RE | E9: Enriched | F9: Regular | G9: Brown | H9: 1990
A11: Chris & Nico Eyking Barn 11 | C11: 7168 | D11: RE | E11: Enriched | F11: Regular | G11: White | H11: 24802

Sheet Pallet Information
A1: NO# | B1: WK | C1: TAG# | D1: BARN | E1: QUAN | F1: NR | G1: GRADED IP | H1: PACK | I1: NET | J1: Packaging | K1: GROSS | L1: WT | M1: IP# | N1: SHIP DATE | O1: CLR | P1: AGE
A2: Sample for Grading Station
B3: 5 | C3: 123456 | D3: 7168-C3 | E3: 60 | F3: NR | H3: OLD | I3: =K3-192 -> 1408 | J3: =IF(H3="NEW",203, IF(H3="OLD",192,0)) -> 192 | K3: 1600 | L3: =I3/E3 -> 23.466667 | M3: 789456 | N3: 43663 | O3: White | P3: 50
B4: 5 | C4: 123457 | D4: 7169-E6 | E4: 60 | G4: X L | H4: OLD | I4: =K4-J4 -> 1458 | J4: =IF(H4="NEW",203, IF(H4="OLD",192,0)) -> 192 | K4: 1650 | M4: 789456 | N4: 43663 | O4: White | P4: 30
B5: 5 | C5: 123458 | D5: 7168-C10 | E5: 60 | G5: LARGE | H5: NEW | I5: =K5-J5 -> 1497 | J5: =IF(H5="NEW",203, IF(H5="OLD",192,0)) -> 203 | K5: 1700 | M5: 789456 | N5: 43663 | O5: Brown
A7: 1 | B7: =Inputs!C$2 -> 46 | C7: 941200 | D7: 7169-E10 | E7: 60 | F7: NR | H7: NEW | I7: =IF(K7>0,K7-J7,"NA") -> 1463 | J7: =IF(H7="NEW",203, IF(H7="OLD",192,0)) -> 203 | K7: 1666 | L7: =IF(K7>0,I7/E7,"NA") -> 24.383333 | M7: 952645 | N7: Nov 14/25 | O7: White | P7: =IF(D7=Inputs!F$4,Inputs!I$4,IF(D7=Inputs!F$2,Inputs!I$2,IF(D7=Inputs!F$3,Inputs!I$3,IF(D7=Inputs!F$5,Inputs!I$5,"NA")))) -> 44.892857
A8: 2 | B8: =Inputs!C$2 -> 46 | C8: 941201 | D8: 7169-E10 | E8: 60 | F8: NR | H8: NEW | I8: =IF(K8>0,K8-J8,"NA") -> 1509 | J8: =IF(H8="NEW",203, IF(H8="OLD",192,0)) -> 203 | K8: 1712 | L8: =IF(K8>0,I8/E8,"NA") -> 25.15 | M8: 952645 | N8: Nov 14/25 | O8: White | P8: =IF(D8=Inputs!F$4,Inputs!I$4,IF(D8=Inputs!F$2,Inputs!I$2,IF(D8=Inputs!F$3,Inputs!I$3,IF(D8=Inputs!F$5,Inputs!I$5,"NA")))) -> 44.892857
A9: 3 | B9: =Inputs!C$2 -> 46 | C9: 941202 | D9: 7169-E10 | E9: 60 | F9: NR | H9: NEW | I9: =IF(K9>0,K9-J9,"NA") -> 1479 | J9: =IF(H9="NEW",203, IF(H9="OLD",192,0)) -> 203 | K9: 1682 | L9: =IF(K9>0,I9/E9,"NA") -> 24.65 | M9: 952645 | N9: Nov 14/25 | O9: White | P9: =IF(D9=Inputs!F$4,Inputs!I$4,IF(D9=Inputs!F$2,Inputs!I$2,IF(D9=Inputs!F$3,Inputs!I$3,IF(D9=Inputs!F$5,Inputs!I$5,"NA")))) -> 44.892857
A10: 4 | B10: =Inputs!C$2 -> 46 | C10: 941203 | D10: 7168-E7 | E10: 60 | F10: NR | H10: NEW | I10: =IF(K10>0,K10-J10,"NA") -> 1457 | J10: =IF(H10="NEW",203, IF(H10="OLD",192,0)) -> 203 | K10: 1660 | L10: =IF(K10>0,I10/E10,"NA") -> 24.283333 | M10: 952645 | N10: Nov 14/25 | O10: White | P10: =IF(D10=Inputs!F$4,Inputs!I$4,IF(D10=Inputs!F$2,Inputs!I$2,IF(D10=Inputs!F$3,Inputs!I$3,IF(D10=Inputs!F$5,Inputs!I$5,"NA")))) -> 57.892857
A11: 5 | B11: =Inputs!C$2 -> 46 | C11: 941204 | D11: 7168-E7 | E11: 60 | F11: NR | H11: NEW | I11: =IF(K11>0,K11-J11,"NA") -> 1459 | J11: =IF(H11="NEW",203, IF(H11="OLD",192,0)) -> 203 | K11: 1662 | L11: =IF(K11>0,I11/E11,"NA") -> 24.316667 | M11: 952645 | N11: Nov 14/25 | O11: White | P11: =IF(D11=Inputs!F$4,Inputs!I$4,IF(D11=Inputs!F$2,Inputs!I$2,IF(D11=Inputs!F$3,Inputs!I$3,IF(D11=Inputs!F$5,Inputs!I$5,"NA")))) -> 57.892857
A12: 6 | B12: =Inputs!C$2 -> 46 | C12: 941205 | D12: 7168-E7 | E12: 60 | F12: NR | H12: NEW | I12: =IF(K12>0,K12-J12,"NA") -> 1471 | J12: =IF(H12="NEW",203, IF(H12="OLD",192,0)) -> 203 | K12: 1674 | L12: =IF(K12>0,I12/E12,"NA") -> 24.516667 | M12: 952645 | N12: Nov 14/25 | O12: White | P12: =IF(D12=Inputs!F$4,Inputs!I$4,IF(D12=Inputs!F$2,Inputs!I$2,IF(D12=Inputs!F$3,Inputs!I$3,IF(D12=Inputs!F$5,Inputs!I$5,"NA")))) -> 57.892857
A13: 7 | B13: =Inputs!C$2 -> 46 | C13: 941206 | D13: 7169-E6 | E13: 60 | F13: NR | H13: NEW | I13: =IF(K13>0,K13-J13,"NA") -> 1455 | J13: =IF(H13="NEW",203, IF(H13="OLD",192,0)) -> 203 | K13: 1658 | L13: =IF(K13>0,I13/E13,"NA") -> 24.25 | M13: 952645 | N13: Nov 14/25 | O13: White | P13: =IF(D13=Inputs!F$4,Inputs!I$4,IF(D13=Inputs!F$2,Inputs!I$2,IF(D13=Inputs!F$3,Inputs!I$3,IF(D13=Inputs!F$5,Inputs!I$5,"NA")))) -> 32.464286
A14: 8 | B14: =Inputs!C$2 -> 46 | C14: 941207 | D14: 7169-E6 | E14: 60 | F14: NR | H14: NEW | I14: =IF(K14>0,K14-J14,"NA") -> 1449 | J14: =IF(H14="NEW",203, IF(H14="OLD",192,0)) -> 203 | K14: 1652 | L14: =IF(K14>0,I14/E14,"NA") -> 24.15 | M14: 952645 | N14: Nov 14/25 | O14: White | P14: =IF(D14=Inputs!F$4,Inputs!I$4,IF(D14=Inputs!F$2,Inputs!I$2,IF(D14=Inputs!F$3,Inputs!I$3,IF(D14=Inputs!F$5,Inputs!I$5,"NA")))) -> 32.464286
A15: 9 | B15: =Inputs!C$2 -> 46 | C15: 941208 | D15: 7169-E6 | E15: 60 | F15: NR | H15: NEW | I15: =IF(K15>0,K15-J15,"NA") -> 1463 | J15: =IF(H15="NEW",203, IF(H15="OLD",192,0)) -> 203 | K15: 1666 | L15: =IF(K15>0,I15/E15,"NA") -> 24.383333 | M15: 952645 | N15: Nov 14/25 | O15: White | P15: =IF(D15=Inputs!F$4,Inputs!I$4,IF(D15=Inputs!F$2,Inputs!I$2,IF(D15=Inputs!F$3,Inputs!I$3,IF(D15=Inputs!F$5,Inputs!I$5,"NA")))) -> 32.464286
A16: 10 | B16: =Inputs!C$2 -> 46 | C16: 941209 | D16: 7169-E6 | E16: 60 | F16: NR | H16: NEW | I16: =IF(K16>0,K16-J16,"NA") -> 1465 | J16: =IF(H16="NEW",203, IF(H16="OLD",192,0)) -> 203 | K16: 1668 | L16: =IF(K16>0,I16/E16,"NA") -> 24.416667 | M16: 952645 | N16: Nov 14/25 | O16: White | P16: =IF(D16=Inputs!F$4,Inputs!I$4,IF(D16=Inputs!F$2,Inputs!I$2,IF(D16=Inputs!F$3,Inputs!I$3,IF(D16=Inputs!F$5,Inputs!I$5,"NA")))) -> 32.464286
A17: 11 | B17: =Inputs!C$2 -> 46 | C17: 941210 | D17: 7168-E11 | E17: 60 | F17: NR | H17: NEW | I17: =IF(K17>0,K17-J17,"NA") -> 1194 | J17: =IF(H17="NEW",203, IF(H17="OLD",192,0)) -> 203 | K17: 1397 | L17: =IF(K17>0,I17/E17,"NA") -> 19.9 | M17: 952645 | N17: Nov 14/25 | O17: White | P17: =IF(D17=Inputs!F$4,Inputs!I$4,IF(D17=Inputs!F$2,Inputs!I$2,IF(D17=Inputs!F$3,Inputs!I$3,IF(D17=Inputs!F$5,Inputs!I$5,"NA")))) -> 23.607143
A18: 12 | B18: =Inputs!C$2 -> 46 | C18: 941211 | D18: 7168-E11 | E18: 60 | F18: NR | H18: NEW | I18: =IF(K18>0,K18-J18,"NA") -> 1197 | J18: =IF(H18="NEW",203, IF(H18="OLD",192,0)) -> 203 | K18: 1400 | L18: =IF(K18>0,I18/E18,"NA") -> 19.95 | M18: 952645 | N18: Nov 14/25 | O18: White | P18: =IF(D18=Inputs!F$4,Inputs!I$4,IF(D18=Inputs!F$2,Inputs!I$2,IF(D18=Inputs!F$3,Inputs!I$3,IF(D18=Inputs!F$5,Inputs!I$5,"NA")))) -> 23.607143
... A26: 20 | B26: =Inputs!C$2 -> 46 | C26: 941219 | D26: 7168-E11 | E26: 60 | F26: NR | H26: NEW | I26: =IF(K26>0,K26-J26,"NA") -> 1223 | J26: =IF(H26="NEW",203, IF(H26="OLD",192,0)) -> 203 | K26: 1426 | L26: =IF(K26>0,I26/E26,"NA") -> 20.383333 | M26: 952645 | N26: Nov 14/25 | O26: White | P26: =IF(D26=Inputs!F$4,Inputs!I$4,IF(D26=Inputs!F$2,Inputs!I$2,IF(D26=Inputs!F$3,Inputs!I$3,IF(D26=Inputs!F$5,Inputs!I$5,"NA")))) -> 23.607143
A27: 21 | B27: =Inputs!C$2 -> 46 | E27: 60 | I27: =IF(K27>0,K27-J27,"NA") -> NA | J27: =IF(H27="NEW",203, IF(H27="OLD",192,0)) -> 0 | L27: =IF(K27>0,I27/E27,"NA") -> NA | P27: =IF(D27=Inputs!F$4,Inputs!I$4,IF(D27=Inputs!F$2,Inputs!I$2,IF(D27=Inputs!F$3,Inputs!I$3,IF(D27=Inputs!F$5,Inputs!I$5,"NA")))) -> NA
A28: 22 | B28: =Inputs!C$2 -> 46 | E28: 60 | I28: =IF(K28>0,K28-J28,"NA") -> NA | J28: =IF(H28="NEW",203, IF(H28="OLD",192,0)) -> 0 | L28: =IF(K28>0,I28/E28,"NA") -> NA | P28: =IF(D28=Inputs!F$4,Inputs!I$4,IF(D28=Inputs!F$2,Inputs!I$2,IF(D28=Inputs!F$3,Inputs!I$3,IF(D28=Inputs!F$5,Inputs!I$5,"NA")))) -> NA
A29: 23 | B29: =Inputs!C$2 -> 46 | E29: 60 | I29: =IF(K29>0,K29-J29,"NA") -> NA | J29: =IF(H29="NEW",203, IF(H29="OLD",192,0)) -> 0 | L29: =IF(K29>0,I29/E29,"NA") -> NA | P29: =IF(D29=Inputs!F$4,Inputs!I$4,IF(D29=Inputs!F$2,Inputs!I$2,IF(D29=Inputs!F$3,Inputs!I$3,IF(D29=Inputs!F$5,Inputs!I$5,"NA")))) -> NA
A30: 24 | B30: =Inputs!C$2 -> 46 | E30: 60 | I30: =IF(K30>0,K30-J30,"NA") -> NA | J30: =IF(H30="NEW",203, IF(H30="OLD",192,0)) -> 0 | L30: =IF(K30>0,I30/E30,"NA") -> NA | P30: =IF(D30=Inputs!F$4,Inputs!I$4,IF(D30=Inputs!F$2,Inputs!I$2,IF(D30=Inputs!F$3,Inputs!I$3,IF(D30=Inputs!F$5,Inputs!I$5,"NA")))) -> NA
A31: 25 | B31: =Inputs!C$2 -> 46 | E31: 60 | I31: =IF(K31>0,K31-J31,"NA") -> NA | J31: =IF(H31="NEW",203, IF(H31="OLD",192,0)) -> 0 | L31: =IF(K31>0,I31/E31,"NA") -> NA | P31: =IF(D31=Inputs!F$4,Inputs!I$4,IF(D31=Inputs!F$2,Inputs!I$2,IF(D31=Inputs!F$3,Inputs!I$3,IF(D31=Inputs!F$5,Inputs!I$5,"NA")))) -> NA
A32: 26 | B32: =Inputs!C$2 -> 46 | E32: 60 | I32: =IF(K32>0,K32-J32,"NA") -> NA | J32: =IF(H32="NEW",203, IF(H32="OLD",192,0)) -> 0 | L32: =IF(K32>0,I32/E32,"NA") -> NA | P32: =IF(D32=Inputs!F$4,Inputs!I$4,IF(D32=Inputs!F$2,Inputs!I$2,IF(D32=Inputs!F$3,Inputs!I$3,IF(D32=Inputs!F$5,Inputs!I$5,"NA")))) -> NA
A33: 27 | B33: =Inputs!C$2 -> 46 | E33: 60 | I33: =IF(K33>0,K33-J33,"NA") -> NA | J33: =IF(H33="NEW",203, IF(H33="OLD",192,0)) -> 0 | L33: =IF(K33>0,I33/E33,"NA") -> NA | P33: =IF(D33=Inputs!F$4,Inputs!I$4,IF(D33=Inputs!F$2,Inputs!I$2,IF(D33=Inputs!F$3,Inputs!I$3,IF(D33=Inputs!F$5,Inputs!I$5,"NA")))) -> NA
A34: 28 | B34: =Inputs!C$2 -> 46 | E34: 60 | I34: =IF(K34>0,K34-J34,"NA") -> NA | J34: =IF(H34="NEW",203, IF(H34="OLD",192,0)) -> 0 | L34: =IF(K34>0,I34/E34,"NA") -> NA | P34: =IF(D34=Inputs!F$4,Inputs!I$4,IF(D34=Inputs!F$2,Inputs!I$2,IF(D34=Inputs!F$3,Inputs!I$3,IF(D34=Inputs!F$5,Inputs!I$5,"NA")))) -> NA
A35: 29 | B35: =Inputs!C$2 -> 46 | E35: 60 | I35: =IF(K35>0,K35-J35,"NA") -> NA | J35: =IF(H35="NEW",203, IF(H35="OLD",192,0)) -> 0 | L35: =IF(K35>0,I35/E35,"NA") -> NA | P35: =IF(D35=Inputs!F$4,Inputs!I$4,IF(D35=Inputs!F$2,Inputs!I$2,IF(D35=Inputs!F$3,Inputs!I$3,IF(D35=Inputs!F$5,Inputs!I$5,"NA")))) -> NA
A36: 30 | B36: =Inputs!C$2 -> 46 | E36: 60 | I36: =IF(K36>0,K36-J36,"NA") -> NA | J36: =IF(H36="NEW",203, IF(H36="OLD",192,0)) -> 0 | L36: =IF(K36>0,I36/E36,"NA") -> NA | P36: =IF(D36=Inputs!F$4,Inputs!I$4,IF(D36=Inputs!F$2,Inputs!I$2,IF(D36=Inputs!F$3,Inputs!I$3,IF(D36=Inputs!F$5,Inputs!I$5,"NA")))) -> NA
A37: 31 | B37: =Inputs!C$2 -> 46 | E37: 60 | I37: =IF(K37>0,K37-J37,"NA") -> NA | J37: =IF(H37="NEW",203, IF(H37="OLD",192,0)) -> 0 | L37: =IF(K37>0,I37/E37,"NA") -> NA | P37: =IF(D37=Inputs!F$4,Inputs!I$4,IF(D37=Inputs!F$2,Inputs!I$2,IF(D37=Inputs!F$3,Inputs!I$3,IF(D37=Inputs!F$5,Inputs!I$5,"NA")))) -> NA
A38: 32 | B38: =Inputs!C$2 -> 46 | E38: 60 | I38: =IF(K38>0,K38-J38,"NA") -> NA | J38: =IF(H38="NEW",203, IF(H38="OLD",192,0)) -> 0 | L38: =IF(K38>0,I38/E38,"NA") -> NA | P38: =IF(D38=Inputs!F$4,Inputs!I$4,IF(D38=Inputs!F$2,Inputs!I$2,IF(D38=Inputs!F$3,Inputs!I$3,IF(D38=Inputs!F$5,Inputs!I$5,"NA")))) -> NA
A39: 33 | B39: =Inputs!C$2 -> 46 | I39: =IF(K39>0,K39-J39,"NA") -> NA | J39: =IF(H39="NEW",203, IF(H39="OLD",192,0)) -> 0 | L39: =IF(K39>0,I39/E39,"NA") -> NA | P39: =IF(D39=Inputs!F$4,Inputs!I$4,IF(D39=Inputs!F$2,Inputs!I$2,IF(D39=Inputs!F$3,Inputs!I$3,IF(D39=Inputs!F$5,Inputs!I$5,"NA")))) -> NA
A40: 34 | B40: =Inputs!C$2 -> 46 | I40: =IF(K40>0,K40-J40,"NA") -> NA | J40: =IF(H40="NEW",203, IF(H40="OLD",192,0)) -> 0 | L40: =IF(K40>0,I40/E40,"NA") -> NA | P40: =IF(D40=Inputs!F$4,Inputs!I$4,IF(D40=Inputs!F$2,Inputs!I$2,IF(D40=Inputs!F$3,Inputs!I$3,IF(D40=Inputs!F$5,Inputs!I$5,"NA")))) -> NA
A41: 35 | B41: =Inputs!C$2 -> 46 | I41: =IF(K41>0,K41-J41,"NA") -> NA | J41: =IF(H41="NEW",203, IF(H41="OLD",192,0)) -> 0 | L41: =IF(K41>0,I41/E41,"NA") -> NA | P41: =IF(D41=Inputs!F$4,Inputs!I$4,IF(D41=Inputs!F$2,Inputs!I$2,IF(D41=Inputs!F$3,Inputs!I$3,IF(D41=Inputs!F$5,Inputs!I$5,"NA")))) -> NA
A42: 36 | B42: =Inputs!C$2 -> 46 | I42: =IF(K42>0,K42-J42,"NA") -> NA | J42: =IF(H42="NEW",203, IF(H42="OLD",192,0)) -> 0 | L42: =IF(K42>0,I42/E42,"NA") -> NA | P42: =IF(D42=Inputs!F$4,Inputs!I$4,IF(D42=Inputs!F$2,Inputs!I$2,IF(D42=Inputs!F$3,Inputs!I$3,IF(D42=Inputs!F$5,Inputs!I$5,"NA")))) -> NA
A43: 37 | B43: =Inputs!C$2 -> 46 | I43: =IF(K43>0,K43-J43,"NA") -> NA | J43: =IF(H43="NEW",203, IF(H43="OLD",192,0)) -> 0 | L43: =IF(K43>0,I43/E43,"NA") -> NA | P43: =IF(D43=Inputs!F$4,Inputs!I$4,IF(D43=Inputs!F$2,Inputs!I$2,IF(D43=Inputs!F$3,Inputs!I$3,IF(D43=Inputs!F$5,Inputs!I$5,"NA")))) -> NA
A44: 38 | B44: =Inputs!C$2 -> 46 | I44: =IF(K44>0,K44-J44,"NA") -> NA | J44: =IF(H44="NEW",203, IF(H44="OLD",192,0)) -> 0 | L44: =IF(K44>0,I44/E44,"NA") -> NA | P44: =IF(D44=Inputs!F$4,Inputs!I$4,IF(D44=Inputs!F$2,Inputs!I$2,IF(D44=Inputs!F$3,Inputs!I$3,IF(D44=Inputs!F$5,Inputs!I$5,"NA")))) -> NA
A45: 39 | B45: =Inputs!C$2 -> 46 | I45: =IF(K45>0,K45-J45,"NA") -> NA | J45: =IF(H45="NEW",203, IF(H45="OLD",192,0)) -> 0 | L45: =IF(K45>0,I45/E45,"NA") -> NA | P45: =IF(D45=Inputs!F$4,Inputs!I$4,IF(D45=Inputs!F$2,Inputs!I$2,IF(D45=Inputs!F$3,Inputs!I$3,IF(D45=Inputs!F$5,Inputs!I$5,"NA")))) -> NA
A46: 40 | B46: =Inputs!C$2 -> 46 | I46: =IF(K46>0,K46-J46,"NA") -> NA | J46: =IF(H46="NEW",203, IF(H46="OLD",192,0)) -> 0 | L46: =IF(K46>0,I46/E46,"NA") -> NA | P46: =IF(D46=Inputs!F$4,Inputs!I$4,IF(D46=Inputs!F$2,Inputs!I$2,IF(D46=Inputs!F$3,Inputs!I$3,IF(D46=Inputs!F$5,Inputs!I$5,"NA")))) -> NA
A47: 41 | B47: =Inputs!C$2 -> 46 | I47: =IF(K47>0,K47-J47,"NA") -> NA | J47: =IF(H47="NEW",203, IF(H47="OLD",192,0)) -> 0 | L47: =IF(K47>0,I47/E47,"NA") -> NA | P47: =IF(D47=Inputs!F$4,Inputs!I$4,IF(D47=Inputs!F$2,Inputs!I$2,IF(D47=Inputs!F$3,Inputs!I$3,IF(D47=Inputs!F$5,Inputs!I$5,"NA")))) -> NA
A48: 42 | B48: =Inputs!C$2 -> 46 | I48: =IF(K48>0,K48-J48,"NA") -> NA | J48: =IF(H48="NEW",203, IF(H48="OLD",192,0)) -> 0 | L48: =IF(K48>0,I48/E48,"NA") -> NA | P48: =IF(D48=Inputs!F$4,Inputs!I$4,IF(D48=Inputs!F$2,Inputs!I$2,IF(D48=Inputs!F$3,Inputs!I$3,IF(D48=Inputs!F$5,Inputs!I$5,"NA")))) -> NA
...

Sheet Inputs
B1: Year | C1: 2025 | G1: Hatch Date | I1: Age | J1: Wks lay | K1: Pallets
B2: Week | C2: 46 | F2: 7169-E6 | G2: 45750 | I2: =(C$3-G2)/7 -> 32.464286 | J2: =I2-19 -> 13.464286 | K2: NEW | L2: 203
B3: Week Ending | C3: =C2*7+(C1-1900)*365.25-1 -> 45977.25 | F3: 7168-E7 | G3: 45572 | I3: =(C$3-G3)/7 -> 57.892857 | J3: =I3-19 -> 38.892857 | K3: OLD | L3: 192
F4: 7169-E10 | G4: 45663 | I4: =(C$3-G4)/7 -> 44.892857 | J4: =I4-19 -> 25.892857
A5: Prepared by | B5: Pamela Penney | F5: 7168-E11 | G5: 45812 | I5: =(C$3-G5)/7 -> 23.607143 | J5: =I5-19 -> 4.6071429
A7: PRODUCTION (# of stacks)
A8: SUNDAY | E8: MONDAY
A9: Barn | B9: White | C9: Brown | E9: Barn | F9: White | G9: Brown
A10: 6 | B10: 270 | E10: 6 | F10: 265
A11: 7 | B11: 185 | C11: 18 | E11: 7 | F11: 196 | G11: 22
A12: 10 | B12: 149 | C12: 10 | E12: 10 | F12: 154 | G12: 12
A13: 11 | B13: 72 | E13: 11 | F13: 100
A14: TUESDAY | E14: WEDNESDAY
A15: Barn | B15: White | C15: Brown | E15: Barn | F15: White | G15: Brown
A16: 6 | B16: 265 | E16: 6 | F16: 270
A17: 7 | B17: 200 | C17: 23 | E17: 7 | F17: 219 | G17: 25
A18: 10 | B18: 167 | C18: 10 | E18: 10 | F18: 179 | G18: 14
A19: 11 | B19: 105 | E19: 11 | F19: 100
A21: THURSDAY | E21: FRIDAY
A22: Barn | B22: White | C22: Brown | E22: Barn | F22: White | G22: Brown
A23: 6 | B23: 265 | E23: 6 | F23: 265
A24: 7 | B24: 194 | C24: 21 | E24: 7 | F24: 198 | G24: 21
A25: 10 | B25: 150 | C25: 12 | E25: 10 | F25: 142 | G25: 10
A26: 11 | B26: 100 | E26: 11 | F26: 100
A27: SATURDAY | E27: TOTAL (stacks) | I27: TOTAL (dozens)
A28: Barn | B28: White | C28: Brown | E28: Barn | F28: White | G28: Brown | I28: Barn | J28: White | K28: Brown
A29: 6 | B29: 142 | E29: 6 | F29: =B10+F10+B16+F16+B23+F23+B29 -> 1742 | G29: =C10+G10+C16+G16+C23+G23+C29 -> 0 | I29: 6 | J29: =F29*15 -> 26130 | K29: =G29*15 -> 0
A30: 7 | B30: 270 | C30: 22 | E30: 7 | F30: =B11+F11+B17+F17+B24+F24+B30 -> 1462 | G30: =C11+G11+C17+G17+C24+G24+C30 -> 152 | I30: 7 | J30: =F30*15 -> 21930 | K30: =G30*15 -> 2280
A31: 10 | B31: 194 | C31: 10 | E31: 10 | F31: =B12+F12+B18+F18+B25+F25+B31 -> 1135 | G31: =C12+G12+C18+G18+C25+G25+C31 -> 78 | I31: 10 | J31: =F31*15 -> 17025 | K31: =G31*15 -> 1170
A32: 11 | B32: 100 | E32: 11 | F32: =B13+F13+B19+F19+B26+F26+B32 -> 677 | G32: =C13+G13+C19+G19+C26+G26+C32 -> 0 | I32: 11 | J32: =F32*15 -> 10155 | K32: =G32*180/12 -> 0
A34: GRADE OUT | G34: NEST RUN TOTALS (Boxes/Stacks)
B35: Barn 6 | C35: Barn 7 | D35: Barn 10 | E35: Barn 11 | G35: Barn 6 White | I35: 360
A36: J/XL | B36: =B37+B38 -> 0.253 | C36: =C37+C38 -> 0.253 | D36: =D37+D38 -> 0.418 | E36: =E37+E38 -> 0 | G36: Barn 7 White | I36: 180
A37: Jumbo | B37: 0.019 | C37: 0.019 | D37: 0.061 | E37: 0 | G37: Barn 7 Brown | I37: 60
A38: Xlarge | B38: 0.234 | C38: 0.234 | D38: 0.357 | E38: 0 | G38: Barn 10 White | I38: 230
A39: Large | B39: 0.665 | C39: 0.665 | D39: 0.531 | E39: 0 | G39: Barn 10 Brown | I39: 10
A40: Medium | B40: 0.068 | C40: 0.068 | D40: 0.041 | E40: 0 | G40: Barn 11 White | I40: 360
A41: Small | B41: 0.001 | C41: 0.001 | D41: 0.001 | E41: 0 | G41: Medium | I41: 0
A42: Peewee | B42: 0 | C42: 0 | D42: 0 | E42: 0
A43: Undergrade | B43: =SUM(B47:B50) -> 0.013 | C43: =SUM(C47:C50) -> 0.013 | D43: =SUM(D47:D50) -> 0.009 | E43: =SUM(E47:E50) -> 0
...

Sheet Procedures
A1: Procedure Information for Tabs
A3: Please save the completed workbook by each week number,year_grading station, I.e. Week 39, 2019_Hilly Acres Farm Ltd.
A5: Producer Number
A6: This tab is for information only.
A7: The information is used in the dropdowns on the pallet information tab.
A9: Hilly Acres Farm Ltd. (Weekly Summary Report)
A10: The reporting under this tab replaces the previous combined weekly marketing reports.
A11: You will note the reporting must be entered separately for each laying facility (barn).
A12: Enter the week # and week ending date in the yellow highlighted area.
A13: Enter the total weekly egg production in dozens from each laying facility (barn) in the green highlighted area
A14: Enter the weekly bird inventory number(s) for each laying facility in the orange highlighted area,
A15: Enter the individual grade out (by dozens and size) for each laying facility in the blue highlighted area.
... A39: 3. Complete the remaining yellow highlighted sections.

Sheet Producer Number
A1: Producer Number | B1: Producer Name
A2: 7169-E6 | B2: Theodore & Aaron Eyking Barn 6 - Enriched
A3: 7168-E7 | B3: Chris & Nico Eyking Barn 7 - Enriched
A4: 7169-E10 | B4: Theodore & Aaron Eyking Barn 10 - Enriched
A5: 7168-E11 | B5: Chris & Nico Eyking Barn 11 - Enriched
A6: Graded IP | B6: Graded IP
A8: Grades
A9: X L
A10: LARGE
A11: MED
A12: SMALL
A15: Packaging
A16: NEW | B16: Packaging weight - 203 (new pallet)
A17: OLD | B17: Packaging weight- 192 (old pallet)
