Workbook

Sheet Mon
C1: Ship Date: | F1: =DATE(2024,12,30)+(D2-1)*7 -> 46076 | K1: BBD | L1: =F1+42-1 -> 46117 | O1: NORTHSIDE
C2: Week | D2: 61
A4: OD | C4: 4. Sobeys - North Sydney | E4: OD | G4: 7.Superstore - North Sydney | I4: OD | K4: 6. WalMart - North Sydney
B5: =ROUNDDOWN(C5/24,0) -> 0 | C5: 0 | D5: OC Xlg | F5: =ROUNDDOWN(G5/24,0) -> 0 | G5: 2 | H5: Lob Xlg | K5: 0 | L5: Wal GV Xlrg
B6: =ROUNDDOWN(C6/24,0) -> 0 | C6: 8 | D6: OC Lg | F6: =ROUNDDOWN(G6/24,0) -> 0 | G6: 5 | H6: Lob Lg | K6: 0 | L6: Wal GV Lg
C7: 0 | D7: OC Med | G7: 2 | H7: Lob br | K7: 0 | L7: Wal Nova Xlg Brn
C8: 1 | D8: OC Br | F8: =ROUNDDOWN(G8/13,0) -> 1 | G8: 16 | H8: Lob 30 Lg | K8: 0 | L8: Wal Nova Brn
B9: =ROUNDDOWN(C9/20,0) -> 0 | C9: 10 | D9: OC 30 Lrg | G9: 8 | H9: ED Jumbo | K9: 0 | L9: Nova Jumbo
C10: 5 | D10: ED Jum | F10: =ROUNDDOWN(G10/24,0) -> 0 | G10: 13 | H10: ED 18 XL | K10: 0 | L10: Wal Nova 18's Lg
A11: 4 | B11: =ROUNDDOWN(C11/24,0) -> 0 | C11: 4 | D11: ED 18 XL | G11: =SUM(G5:G10) -> 46 | H11: Box Total | K11: 0 | L11: All Grain Nova
B12: =ROUNDDOWN(C12/24,0) -> 0 | C12: 6 | D12: ED 18 LG | K12: 0 | L12: Nova 6 Pack
C13: 1 | D13: Eyk Lg | G13: PO# | H13: 4881750450 | K13: 0 | L13: XLrg 30 pack Nova
C14: 2 | D14: OC Lg Cozy Coop | K14: 0 | L14: Lrg 30 pack Nova
C15: 1 | D15: OC Org F.Rng (B) | E15: OD | G15: 8. Shoppers - North Sydney | K15: =SUM(K5:K14) -> 0 | L15: Box Total
C16: 0 | D16: OC Lg Free Run (W) | G16: 12 | H16: Lob Lrg
C17: 0 | D17: OC Om3 Free Run (W) | G17: 0 | H17: Lob br | K17: PO#
C18: 0 | D18: MP Om3 6pk (W) | G18: 1 | H18: MP Om 12pk (W)
C19: 0 | D19: MP Om3 12pk (W) | G19: =SUM(G16:G18) -> 13 | H19: Box Total
C20: 0 | D20: MP Free Run (B)
C21: 0 | D21: MP Coldspring F.Rng (B) | E21: OD | G21: 2. Harbour View (2021) (565-3109) | I21: OD | K21: 5. Northside Guest Home (8740)
C22: =SUM(C5:C21) -> 38 | D22: Box Total | G22: 0 | H22: Lg Loose | K22: 0 | L22: Lg Loose
E24: OD | G24: 3. Miners Manor | I24: OD | K24: 18. Sexton's Pharmasave
A25: OD | C25: 17.Foodland - Sydney Mines | G25: 2 | H25: Lg Loose | K25: 3 | L25: Eyk Lg
C26: 0 | D26: OC xlg
C27: 0 | D27: OC lrg | E27: OD | G27: 1. Northside General
C28: 0 | D28: OC Med | G28: 2 | H28: Med Loose
C29: 0 | D29: OC Br | I29: OD | K29: **Total of Small Stops**
C30: 0 | D30: ED Jum | I30: 2 | K30: =G22+G25+K22 -> 2 | L30: Lg Loose
C31: 0 | D31: ED 18 XL | I31: 2 | K31: =G28 -> 2 | L31: Med Loose
C32: 0 | D32: ED 18 LG | K32: =K25 -> 3 | L32: Eyk Lg
C33: =SUM(C26:C32) -> 0 | D33: Box Total
C34: Ship Date: | F34: =F1 -> 46076 | K34: BBD | L34: =L1 -> 46117 | O34: SYDNEY
A36: OD | C36: 10. Sobeys - Syd. River | E36: OD | G36: 9. WalMart - Syd. River | I36: OD | K36: 12. WalMart - Spar Rd.
B37: =ROUNDDOWN(C37/24,0) -> 0 | C37: 2 | D37: OC Xlg | G37: 1 | H37: Wal GV Xlrg | K37: 3 | L37: Wal GV Xlrg
B38: =ROUNDDOWN(C38/24,0) -> 0 | C38: 4 | D38: OC Lg | G38: 17 | H38: Wal GV Lg | K38: 17 | L38: Wal GV Lg
C39: 1 | D39: OC Med | G39: 0 | H39: Wal Nova Xlg Brn | K39: 0 | L39: Wal Nova Xlg Brn
C40: 1 | D40: OC Br | G40: 1 | H40: Wal Nova Brn | K40: 1 | L40: Wal Nova Brn
B41: =ROUNDDOWN(C41/20,0) -> 1 | C41: 20 | D41: OC 30 Lrg | G41: 1 | H41: Nova Jumbo | K41: 1 | L41: Nova Jumbo
C42: 4 | D42: ED Jum | G42: 11 | H42: Wal Nova 18's Lg | K42: 13 | L42: Wal Nova 18's Lg
B43: =ROUNDDOWN(C43/24,0) -> 0 | C43: 0 | D43: ED 18 XL | G43: 0 | H43: All Grain Nova | K43: 0 | L43: All Grain Nova
...

Sheet Tues
C1: Ship Date: | F1: =DATE(2024,12,30)+(Mon!D2-1)*7+1 -> 46077 | K1: BBD | L1: =Mon!F1+42-1 -> 46117
A3: OD | C3: 3. Sobeys - Prince Street | E3: OD | G3: 7. Sobeys - New Waterford | I3: OD | K3: 12. Sobeys - Glace Bay | M3: OD | N3: 10. Foodland - Glace Bay
A4: 2 | B4: =ROUNDDOWN(C4/24,0) -> 0 | C4: 2 | D4: OC Xlg | E4: 2 | F4: =ROUNDDOWN(G4/24,0) -> 0 | G4: 2 | H4: OC Xlg | I4: 1 | J4: =ROUNDDOWN(K4/24,0) -> 0 | K4: 1 | L4: OC Xlg | N4: 0 | O4: OC Xlg
B5: =ROUNDDOWN(C5/24,0) -> 1 | C5: 24 | D5: OC Lg | E5: 8 | F5: =ROUNDDOWN(G5/24,0) -> 0 | G5: 8 | H5: OC Lg | I5: 6 | J5: =ROUNDDOWN(K5/24,0) -> 0 | K5: 6 | L5: OC Lg | N5: 0 | O5: OC Lg
A6: 2 | C6: 2 | D6: OC Med | G6: 0 | H6: OC Med | K6: 0 | L6: OC Med | N6: 0 | O6: OC Med
A7: 2 | C7: 2 | D7: OC Br | E7: 1 | G7: 1 | H7: OC Br | K7: 0 | L7: OC Br | N7: 0 | O7: OC Br
B8: =ROUNDDOWN(C8/20,0) -> 3 | C8: 60 | D8: OC 30 Lrg | E8: 28 | F8: =ROUNDDOWN(G8/20,0) -> 1 | G8: 28 | H8: OC 30 Lrg | I8: 4 | J8: =ROUNDDOWN(K8/20,0) -> 1 | K8: 24 | L8: OC 30 Lrg | N8: 0 | O8: OC 30 Lrg
A9: 8 | C9: 8 | D9: ED Jum | E9: 4 | G9: 4 | H9: ED Jum | I9: 5 | K9: 5 | L9: ED Jum | N9: 0 | O9: ED Jum
A10: 6 | B10: =ROUNDDOWN(C10/24,0) -> 0 | C10: 8 | D10: ED 18 XL | E10: 3 | F10: =ROUNDDOWN(G10/24,0) -> 0 | G10: 3 | H10: ED 18 XL | I10: 6 | J10: =ROUNDDOWN(K10/24,0) -> 0 | K10: 6 | L10: ED 18 XL | N10: 0 | O10: ED 18 XL
A11: 8 | B11: =ROUNDDOWN(C11/24,0) -> 0 | C11: 8 | D11: ED 18 LG | E11: 2 | F11: =ROUNDDOWN(G11/24,0) -> 0 | G11: 2 | H11: ED 18 LG | I11: 2 | J11: =ROUNDDOWN(K11/24,0) -> 0 | K11: 2 | L11: ED 18 LG | N11: 0 | O11: ED 18 LG
A12: 3 | C12: 3 | D12: Eyk Lg | G12: 0 | H12: Eyk Lg | I12: 2 | K12: 2 | L12: Eyk Lg | N12: 0 | O12: Eyk Lg
C13: 4 | D13: OC Lg Cozy Coop | G13: 0 | H13: OC Lg Cozy Coop | K13: 2 | L13: OC Lg Cozy Coop | N13: =SUM(N4:N12) -> 0 | O13: Box Total
C14: 2 | D14: OC Org F.Rng (B) | G14: 0 | H14: OC Org F.Rng (B) | K14: 0 | L14: OC Org F.Rng (B)
C15: 1 | D15: OC Lg Free Run (W) | G15: 0 | H15: OC Lg Free Run (W) | K15: 0 | L15: OC Lg Free Run (W)
C16: 1 | D16: OC Om3 Free Run (W) | G16: 0 | H16: OC Om3 Free Run (W) | K16: 0 | L16: OC Om3 Free Run (W) | M16: OD | N16: 6. Pier Pharmasave
C17: 1 | D17: MP Om3 6pk (W) | G17: 0 | H17: MP Om3 6pk (W) | K17: 0 | L17: MP Om3 6pk (W) | M17: 5 | N17: 6 | O17: Eyk Lg
C18: 1 | D18: MP Om3 12pk (W) | G18: 0 | H18: MP Om3 12pk (W) | K18: 1 | L18: MP Om3 12pk (W)
C19: 1 | D19: MP Free Run (B) | G19: 0 | H19: MP Free Run (B) | K19: 0 | L19: MP Free Run (B) | M19: OD | N19: 8. Dominion Pharmasave
C20: 1 | D20: MP Coldspring F.Rng (B) | G20: 0 | H20: MP Coldspring F.Rng (B) | K20: 0 | L20: MP Coldspring F.Rng (B) | M20: 5 | N20: 5 | O20: Eyk Lg
C21: =SUM(C4:C20) -> 129 | D21: Box Total | G21: =SUM(G4:G20) -> 48 | H21: Box Total | K21: =SUM(K4:K20) -> 49 | L21: Box Total
A23: OD | C23: 1.Superstore - Syd. River | E23: OD | G23: 13.Superstore - Glace Bay | I23: OD | K23: 11. Shoppers - Glace Bay | M23: OD | N23: 14. Meadows Pharmasave
B24: =ROUNDDOWN(C24/24,0) -> 0 | C24: 0 | D24: Lob Xlg | E24: 2 | F24: =ROUNDDOWN(G24/24,0) -> 0 | G24: 0 | H24: Lob Xlg | I24: 3 | K24: 3 | L24: Lob Lrg | M24: 25 | N24: 25 | O24: Eyk Lg
A25: 5 | B25: =ROUNDDOWN(C25/24,0) -> 0 | C25: 5 | D25: Lob Lg | E25: 10 | F25: =ROUNDDOWN(G25/24,0) -> 0 | G25: 10 | H25: Lob Lg | K25: 0 | L25: Lob br
A26: 1 | C26: 1 | D26: Lob br | G26: 1 | H26: Lob br | K26: 0 | L26: MP Om 12pk (W) | M26: OD | N26: 9. Medical Hall Pharmasave
B27: =ROUNDDOWN(C27/13,0) -> 0 | C27: 10 | D27: Lob 30 Lg | E27: 11 | F27: =ROUNDDOWN(G27/13,0) -> 0 | G27: 12 | H27: Lob 30 Lg | K27: =SUM(K24:K26) -> 3 | L27: Box Total | M27: 25 | N27: 25 | O27: Eyk Lg
A28: 4 | C28: 4 | D28: ED Jumbo | E28: 5 | G28: 6 | H28: ED Jumbo | N28: 0 | O28: Eyk Br
A29: 10 | B29: =ROUNDDOWN(C29/24,0) -> 0 | C29: 10 | D29: ED XL 18 | E29: 8 | F29: =ROUNDDOWN(G29/24,0) -> 0 | G29: 8 | H29: ED XL 18 | I29: OD | K29: 2. McIllvary Guest Home
C30: =SUM(C24:C29) -> 30 | D30: Box Total | G30: =SUM(G24:G29) -> 37 | H30: Box Total | I30: 3 | K30: 3 | L30: Lg Loose | M30: OD | N30: **Pharmasave Total**
M31: 61 | N31: =N17+N20+N24+N27 -> 61 | O31: Eyk Lg
C32: PO# | D32: 4881772595 | G32: PO# | H32: 4881826615 | N32: =N28 -> 0 | O32: Eyk Br
A34: OD | C34: 4. Giant Tiger | E34: OD | G34: 5. TRA
A35: 8 | C35: 8 | D35: Eyk Lrg | E35: 20 | G35: 20 | H35: Eyk Lg
C36: 0 | D36: Eyk Br | E36: 20 | G36: 20 | H36: OC 30 Lg
A37: 14 | C37: 14 | D37: ED 18 XL | G37: =SUM(G35:G36) -> 40 | H37: Box Total
C38: 0 | D38: Lrg 30 pack Nova
C39: =SUM(C35:C38) -> 22 | D39: Box Total
C40: DAILY TOTALS
C42: Our Compliments | F42: pcs | G42: Walmart | K42: Loblaws | N42: Eyking
C43: =C4+K4+N4+G4 -> 5 | D43: OC Xlg | F43: =G43*15 -> 0 | H43: Wal GV Xlrg | K43: =C24+G24 -> 0 | L43: Lob Xlg | N43: =C9+C28+K9+N9+G9+G28 -> 27 | O43: ED Jum
C44: =C5+K5+N5+G5 -> 38 | D44: OC Lg | F44: =G44*15 -> 0 | H44: Wal GV Lg | K44: =C25+G25+K24 -> 18 | L44: Lob Lg | N44: =C10+C29+K10+N10+G10+G29+C37 -> 49 | O44: ED 18 XL
...

Sheet Wed
B1: Ship Date: | D1: =DATE(2024,12,30)+(Mon!D2-1)*7+2 -> 46078 | H1: BBD | I1: =Mon!F1+49-1 -> 46124 | J1: OD | K1: 17. Cheticamp Co-op
J2: 3 | K2: 3 | L2: OC Xlg
A3: OD | B3: 1. Cedar House | D3: OD | E3: 2. Victoria Farmers - Co-op | G3: OD | H3: 11. Port Hood Co-op | J3: 5 | K3: 5 | L3: OC Lg
B4: 0 | C4: Lg Loose | D4: 2 | E4: 2 | F4: OC Xlg | G4: 2 | H4: 2 | I4: OC Xlg | J4: 5 | K4: 5 | L4: Eyk Br
D5: 11 | E5: 11 | F5: OC Lg | G5: 6 | H5: 6 | I5: OC Lg | K5: 10 | L5: OC 30 Lrg
A6: OD | B6: 6. Alderwood Rest Home | D6: 3 | E6: 3 | F6: OC Br | G6: 1 | H6: 1 | I6: OC Br | K6: 4 | L6: ED Jumbo
A7: 4 | B7: 4 | C7: Lg Loose | D7: 9 | E7: 9 | F7: ED Jum | H7: 5 | I7: OC 30 Lrg | J7: 5 | K7: 5 | L7: Eyk Xlg
D8: 20 | E8: 20 | F8: ED 18 XL | H8: =SUM(H4:H7) -> 14 | I8: Box Total | K8: 0 | L8: Eyk Lg
A9: OD | B9: 3. Julia's Bakery | E9: =SUM(E4:E8) -> 45 | F9: Box Total | J9: 6 | K9: 6 | L9: ED XL 18
A10: 2 | B10: 2 | C10: Lg Loose | K10: 0 | L10: MP Om3 6pk (W)
D11: OD | E11: 8. Whycocomagh Co-op | G11: OD | H11: 12. Shean Co-op | K11: 0 | L11: MP Om3 12pk (W)
A12: OD | B12: 5. Telegraph House | E12: 0 | F12: OC Xlg | G12: 5 | H12: 5 | I12: OC Xlg | K12: =SUM(K2:K11) -> 38 | L12: Box Total
B13: 0 | C13: Lg Loose | D13: 8 | E13: 8 | F13: OC Lg | G13: 12 | H13: 12 | I13: OC Lg
D14: 1 | E14: 1 | F14: OC Br | G14: 2 | H14: 2 | I14: OC Br | J14: OD | K14: 20. Margaree Co-op
A15: OD | B15: 4. Bean There Café | E15: 13 | F15: OC 30 Lrg | H15: 15 | I15: OC 30 Lrg | K15: 0 | L15: OC Xlg
A16: 1 | B16: 1 | C16: Med Loose | D16: 6 | E16: 6 | F16: ED Jum | H16: 0 | I16: MP Om3 6pk (W) | J16: 6 | K16: 6 | L16: OC Lg
D17: 10 | E17: 10 | F17: ED 18 XL | H17: 0 | I17: MP Om3 12pk (W) | K17: 4 | L17: OC Br
A18: OD | B18: X. Gisele's Inn | E18: =SUM(E12:E17) -> 38 | F18: Box Total | H18: =SUM(H12:H17) -> 34 | I18: Box Total | K18: 4 | L18: OC 30 Lrg
B19: 0 | C19: Lg Loose | K19: 8 | L19: ED Jumbo
J20: 10 | K20: 10 | L20: ED XL 18
A21: OD | B21: X. From Billy Bistro & Pub | D21: OD | E21: 9. Mabou Freshmart | G21: OD | H21: X. Coal Miners Café | K21: =SUM(K15:K20) -> 32 | L21: Box Total
B22: 0 | C22: Med Loose | E22: 3 | F22: Eyk Xlg | H22: 0 | I22: Lg Loose
E23: 7 | F23: Eyk Lg | J23: OD | K23: 19. Lemoines Co-op
A24: OD | B24: X. Farmers Daughter | E24: 3 | F24: Eyk Br | G24: OD | H24: 13. Inverness Pantry | J24: 3 | K24: 3 | L24: Eyk Xlg
B25: 0 | C25: Eyk Lg | E25: 0 | F25: Lg Loose | H25: 0 | I25: Eyk Lg | J25: 2 | K25: 2 | L25: Eyk Lg
B26: 0 | C26: Lg Loose | E26: 0 | F26: OC 30 Lrg | H26: 0 | I26: Lg Loose | J26: 1 | K26: 1 | L26: Eyk Br
B27: =SUM(B25:B26) -> 0 | C27: Box Total | E27: 0 | F27: MP Om3 6pk (W) | H27: =SUM(H25:H26) -> 0 | I27: Box Total | K27: =SUM(K24:K26) -> 6 | L27: Box Total
E28: 0 | F28: MP Om3 12pk (W)
A29: OD | B29: 7. McKeigans Pharmacy | E29: =SUM(E22:E28) -> 13 | F29: Box Total | G29: OD | H29: 14. Lawrence's Store | J29: OD | K29: 18. LeBlancs General Store
A30: 1 | B30: 1 | C30: Eyk Xlg | H30: 0 | I30: Eyk Lg | J30: 3 | K30: 3 | L30: Eyk Xlg
A31: 1 | B31: 1 | C31: Eyk Lg | D31: OD | E31: 10. Cabot Trail Food | J31: 1 | K31: 1 | L31: Eyk Lg
B32: =SUM(B30:B31) -> 2 | C32: Box Total | E32: 0 | F32: Eyk Xlg | G32: OD | H32: 15. Duck Cove Inn | K32: 0 | L32: Eyk Br
E33: 0 | F33: Eyk Lg | H33: 0 | I33: Lg Loose | K33: =SUM(K30:K32) -> 4 | L33: Box Total
A34: OD | B34: 21. Ingram's Rite Stop | E34: 0 | F34: Eyk Br
A35: 2 | B35: 2 | C35: Eyk Lg | E35: =SUM(E32:E34) -> 0 | F35: Box Total | G35: OD | H35: 16. Doucette's Inn | J35: OD | K35: 22. Stone's Drug Store
H36: 0 | I36: Med Loose | J36: 3 | K36: 3 | L36: Eyk Lg
K37: 0 | L37: Eyk Br
K38: =SUM(K36:K37) -> 3 | L38: Box Total
B39: DAILY TOTALS
B41: Our Compliments | D41: pcs | E41: Walmart | H41: Loblaws | K41: Eyking
...

Sheet Thurs
C1: Ship Date: | F1: =DATE(2024,12,30)+(Mon!D2-1)*7+3 -> 46079 | K1: BBD | L1: =Mon!F1+49-1 -> 46124 | O1: NORTHSIDE
A3: OD | C3: 1. Sobeys - North Sydney | E3: OD | G3: 3. Foodland - Sydney Mines | I3: OD | K3: 4. Superstore - North Sydney | M3: OD | N3: 6. WalMart - North Sydney
A4: 1 | B4: =ROUNDDOWN(C4/24,0) -> 0 | C4: 1 | D4: OC Xlg | G4: 0 | H4: OC xlg | J4: =ROUNDDOWN(K4/24,0) -> 0 | K4: 0 | L4: Lob Xlg | M4: 2 | N4: 2 | O4: Wal GV Xlrg
B5: =ROUNDDOWN(C5/24,0) -> 0 | C5: 6 | D5: OC Lg | E5: 6 | G5: 6 | H5: OC lrg | I5: 7 | J5: =ROUNDDOWN(K5/24,0) -> 0 | K5: 7 | L5: Lob Lg | M5: 11 | N5: 11 | O5: Wal GV Lg
C6: 0 | D6: OC Med | G6: 0 | H6: OC Med | K6: 2 | L6: Lob br | N6: 0 | O6: Wal Nova Xlg Brn
C7: 0 | D7: OC Br | G7: 0 | H7: OC Br | J7: =ROUNDDOWN(K7/13,0) -> 1 | K7: 17 | L7: Lob 30 Lg | N7: 0 | O7: Wal Nova Brn
B8: =ROUNDDOWN(C8/20,0) -> 1 | C8: 30 | D8: OC 30 Lrg | G8: 6 | H8: ED Jum | K8: 9 | L8: ED Jumbo | N8: 0 | O8: Nova Jumbo
C9: 7 | D9: ED Jum | E9: 8 | G9: 8 | H9: ED 18 XL | I9: 14 | J9: =ROUNDDOWN(K9/24,0) -> 0 | K9: 14 | L9: ED 18 XL | M9: 4 | N9: 4 | O9: Wal Nova 18's Lg
A10: 5 | B10: =ROUNDDOWN(C10/24,0) -> 0 | C10: 5 | D10: ED 18 XL | G10: 0 | H10: ED 18 LG | K10: =SUM(K4:K9) -> 49 | L10: Box Total | N10: 0 | O10: All Grain Nova
B11: =ROUNDDOWN(C11/24,0) -> 3 | C11: 72 | D11: ED 18 LG | G11: =SUM(G4:G10) -> 20 | H11: Box Total | N11: 0 | O11: Nova 6 Pack
C12: 0 | D12: Eyk Lg | K12: PO# | L12: 4881850405 | N12: 0 | O12: XLrg 30 pack Nova
C13: 1 | D13: OC Lg Cozy Coop | N13: 12 | O13: Lrg 30 pack Nova
C14: 1 | D14: OC Org F.Rng (B) | I14: OD | K14: 5. Shoppers - North Sydney | N14: =SUM(N4:N13) -> 29 | O14: Box Total
C15: 1 | D15: OC Lg Free Run (W) | I15: 24 | K15: 24 | L15: Lob Lrg
C16: 0 | D16: OC Om3 Free Run (W) | K16: 0 | L16: Lob br | N16: PO# | O16: 2272
C17: 0 | D17: MP Om3 6pk (W) | K17: 2 | L17: MP Om3 12pk (W)
C18: 0 | D18: MP Om3 12pk (W) | K18: =SUM(K15:K17) -> 26 | L18: Box Total
C19: 0 | D19: MP Free Run (B)
C20: 1 | D20: MP Coldspring F.Rng (B)
C21: =SUM(C4:C20) -> 125 | D21: Box Total
A24: OD | C24: 2. Nala's | E24: OD | G24: 8. Janes
A25: 2 | C25: 2 | D25: Lg Loose | G25: 0 | H25: Lg Loose
A27: OD | C27: 7. Bonnar's Meats | E27: OD | G27: 9. Bras D'or View
A28: 6 | C28: 6 | D28: Eyk Xlg | E28: 2 | G28: 2 | H28: Lg Loose
C35: Ship Date: | F35: =F1 -> 46079 | K35: BBD | L35: =L1 -> 46124 | O35: SYDNEY
A37: OD | C37: 11. Sobeys - Syd. River | E37: OD | G37: 14.Colbourne - No Frills | J37: OD | K37: 10. WalMart - Syd. River | M37: OD | N37: 13. WalMart - Spar Rd.
B38: =ROUNDDOWN(C38/24,0) -> 0 | C38: 0 | D38: OC Xlg | F38: =ROUNDDOWN(G38/24,0) -> 0 | G38: 0 | H38: Lob xlg | K38: 5 | L38: Wal GV Xlrg | N38: 14 | O38: Wal GV Xlrg
A39: 5 | B39: =ROUNDDOWN(C39/24,0) -> 0 | C39: 5 | D39: OC Lg | F39: =ROUNDDOWN(G39/24,0) -> 2 | G39: 48 | H39: Lob lg | K39: 25 | L39: Wal GV Lg | N39: 30 | O39: Wal GV Lg
C40: 0 | D40: OC Med | G40: 0 | H40: Lob Br | K40: 0 | L40: Wal Nova Xlg Brn | N40: 0 | O40: Wal Nova Xlg Brn
C41: 0 | D41: OC Br | F41: =ROUNDDOWN(G41/13,0) -> 4 | G41: 52 | H41: Lob 30 Lg | K41: 2 | L41: Wal Nova Brn | N41: 5 | O41: Wal Nova Brn
B42: =ROUNDDOWN(C42/20,0) -> 1 | C42: 20 | D42: OC 30 Lrg | G42: 5 | H42: ED Jumbo | K42: 1 | L42: Nova Jumbo | N42: 2 | O42: Nova Jumbo
C43: 5 | D43: ED Jum | E43: 24 | F43: =ROUNDDOWN(G43/24,0) -> 1 | G43: 24 | H43: ED 18 XL | K43: 20 | L43: Wal Nova 18's Lg | N43: 37 | O43: Wal Nova 18's Lg
A44: 96 | B44: =ROUNDDOWN(C44/24,0) -> 4 | C44: 96 | D44: ED 18 XL | G44: =SUM(G38:G43) -> 129 | H44: Box Total | K44: 0 | L44: All Grain Nova | N44: 0 | O44: All Grain Nova
B45: =ROUNDDOWN(C45/24,0) -> 0 | C45: 0 | D45: ED 18 LG | K45: 0 | L45: Nova 6 Pack | N45: 0 | O45: Nova 6 Pack
A46: 3 | C46: 3 | D46: Eyk Lg | G46: PO# | H46: 4881855877 | K46: 0 | L46: XLrg 30 pack Nova | N46: 0 | O46: XLrg 30 pack Nova
C47: 2 | D47: OC Lg Cozy Coop | K47: 47 | L47: Lrg 30 pack Nova | N47: 122 | O47: Lrg 30 pack Nova
C48: 1 | D48: OC Org F.Rng (B) | K48: =SUM(K38:K47) -> 100 | L48: Box Total | N48: =SUM(N38:N47) -> 210 | O48: Box Total
C49: 1 | D49: OC Lg Free Run (W) | E49: OD | G49: 15. Shoppers - Prince St.
C50: 0 | D50: OC Om Free Run (W) | E50: 40 | G50: 40 | H50: Lob Lrg | K50: PO# | L50: 2024 | N50: PO# | O50: 2292
C51: 0 | D51: MP Om 6pk (W) | G51: 0 | H51: Lob br
...

Sheet Fri
C1: Ship Date: | F1: =DATE(2024,12,30)+(Mon!D2-1)*7+4 -> 46080 | K1: BBD | L1: =Mon!F1+49-1 -> 46124
A3: OD | C3: 2. Sobeys - Prince Street | E3: OD | G3: 8. Sobeys - New Waterford | I3: OD | K3: 15. Sobeys - Glace Bay | M3: OD | N3: 12. Foodland - Glace Bay | Q3: 18. Eskasoni
B4: =ROUNDDOWN(C4/24,0) -> 0 | C4: 1 | D4: OC Xlg | F4: =ROUNDDOWN(G4/24,0) -> 0 | G4: 2 | H4: OC Xlg | J4: =ROUNDDOWN(K4/24,0) -> 0 | K4: 1 | L4: OC Xlg | N4: 0 | O4: OC Xlg | Q4: 2 | R4: OC Xlg
A5: 12 | B5: =ROUNDDOWN(C5/24,0) -> 0 | C5: 12 | D5: OC Lg | E5: 12 | F5: =ROUNDDOWN(G5/24,0) -> 0 | G5: 12 | H5: OC Lg | J5: =ROUNDDOWN(K5/24,0) -> 0 | K5: 10 | L5: OC Lg | N5: 0 | O5: OC Lg | Q5: 8 | R5: OC Lg
C6: 1 | D6: OC Med | G6: 0 | H6: OC Med | K6: 0 | L6: OC Med | N6: 0 | O6: OC Med | Q6: 2 | R6: OC Med
C7: 1 | D7: OC Br | G7: 0 | H7: OC Br | K7: 0 | L7: OC Br | N7: 0 | O7: OC Br | Q7: 4 | R7: OC Br
B8: =ROUNDDOWN(C8/20,0) -> 3 | C8: 60 | D8: OC 30 Lrg | F8: =ROUNDDOWN(G8/20,0) -> 1 | G8: 30 | H8: OC 30 Lrg | J8: =ROUNDDOWN(K8/20,0) -> 2 | K8: 40 | L8: OC 30 Lrg | N8: 0 | O8: OC 30 Lrg | Q8: 40 | R8: OC 30 Lrg
C9: 6 | D9: ED Jum | G9: 5 | H9: ED Jum | K9: 7 | L9: ED Jum | N9: 0 | O9: ED Jum | Q9: 10 | R9: ED Jum
A10: 6 | B10: =ROUNDDOWN(C10/24,0) -> 0 | C10: 6 | D10: ED 18 XL | E10: 5 | F10: =ROUNDDOWN(G10/24,0) -> 0 | G10: 5 | H10: ED 18 XL | I10: 9 | J10: =ROUNDDOWN(K10/24,0) -> 0 | K10: 9 | L10: ED 18 XL | N10: 0 | O10: ED 18 XL | P10: 15 | Q10: 15 | R10: ED 18 XL
B11: =ROUNDDOWN(C11/24,0) -> 2 | C11: 48 | D11: ED 18 LG | F11: =ROUNDDOWN(G11/24,0) -> 1 | G11: 24 | H11: ED 18 LG | J11: =ROUNDDOWN(K11/24,0) -> 3 | K11: 82 | L11: ED 18 LG | N11: 0 | O11: ED 18 LG | P11: 12 | Q11: 15 | R11: ED 18 LG
C12: 4 | D12: Eyk Lg | G12: 0 | H12: Eyk Lg | K12: 1 | L12: Eyk Lg | N12: 0 | O12: F.John Lg | Q12: 0 | R12: MP Om 12
C13: 2 | D13: OC Lg Cozy Coop | G13: 0 | H13: OC Lg Cozy Coop | K13: 0 | L13: OC Lg Cozy Coop | N13: =SUM(N4:N12) -> 0 | O13: Box Total | Q13: =SUM(Q4:Q12) -> 96 | R13: Box Total
C14: 0 | D14: OC Org F.Rng (B) | G14: 0 | H14: OC Org F.Rng (B) | K14: 0 | L14: OC Org F.Rng (B)
C15: 2 | D15: OC Lg Free Run (W) | G15: 0 | H15: OC Lg Free Run (W) | K15: 1 | L15: OC Lg Free Run (W) | M15: OD | N15: 6. Pier Pharmasave
C16: 0 | D16: OC Om3 Free Run (W) | G16: 0 | H16: OC Om3 Free Run (W) | K16: 0 | L16: OC Om3 Free Run (W) | N16: 0 | O16: Eyk Lg
C17: 0 | D17: MP Om3 6pk (W) | G17: 0 | H17: MP Om3 6pk (W) | K17: 0 | L17: MP Om3 6pk (W)
C18: 0 | D18: MP Om3 12pk (W) | G18: 0 | H18: MP Om3 12pk (W) | K18: 0 | L18: MP Om3 12pk (W) | M18: OD | N18: 9. Midtown Pharmasave
C19: 0 | D19: MP Free Run (B) | G19: 0 | H19: MP Free Run (B) | K19: 0 | L19: MP Free Run (B) | N19: 0 | O19: Eyk Lg
C20: 0 | D20: MP Coldspring | G20: 0 | H20: MP Coldspring | K20: 0 | L20: MP Coldspring
C21: =SUM(C4:C20) -> 143 | D21: Box Total | G21: =SUM(G4:G20) -> 78 | H21: Box Total | K21: =SUM(K4:K20) -> 151 | L21: Box Total | M21: OD | N21: 10. Dominion Pharmasave
N22: 5 | O22: Eyk Lg
A23: OD | C23: 1.Superstore - Syd. River | E23: OD | G23: 16. Superstore - Glace Bay | J23: OD | K23: 14. Shoppers - Glace Bay
B24: =ROUNDDOWN(C24/24,0) -> 0 | C24: 1 | D24: Lob Xlg | F24: =ROUNDDOWN(G24/24,0) -> 0 | G24: 2 | H24: Lob Xlg | K24: 2 | L24: Lob Lrg | M24: OD | N24: 11. Medical Hall Pharm.
A25: 11 | B25: =ROUNDDOWN(C25/24,0) -> 0 | C25: 11 | D25: Lob Lg | E25: 6 | F25: =ROUNDDOWN(G25/24,0) -> 0 | G25: 6 | H25: Lob Lg | K25: 0 | L25: Lob br | N25: 25 | O25: Eyk Lg
C26: 3 | D26: Lob br | G26: 1 | H26: Lob br | K26: 0 | L26: MP Om3 12pk (W)
B27: =ROUNDDOWN(C27/13,0) -> 1 | C27: 21 | D27: Lob 30 Lg | F27: =ROUNDDOWN(G27/13,0) -> 1 | G27: 14 | H27: Lob 30 Lg | K27: =SUM(K24:K26) -> 2 | L27: Box Total | M27: OD | N27: 17. Meadows Pharmasave
C28: 6 | D28: ED Jumbo | G28: 6 | H28: ED Jumbo | N28: 12 | O28: Eyk Lg
A29: 9 | B29: =ROUNDDOWN(C29/24,0) -> 0 | C29: 9 | D29: ED 18 XL | E29: 10 | F29: =ROUNDDOWN(G29/24,0) -> 0 | G29: 10 | H29: ED 18 XL
C30: =SUM(C24:C29) -> 51 | D30: Box Total | G30: =SUM(G24:G29) -> 39 | H30: Box Total | M30: OD | N30: **Pharmasave Total**
N31: =N16+N19+N22+N25+N28 -> 42 | O31: Eyk Lg
C32: PO# | D32: 4881876249 | G32: PO# | H32: 4881878299
B34: OD | C34: 4. Giant Tiger | J34: OD | K34: 7. Omni Foods | M34: OD | N34: 13. Seaview Manor
C35: 8 | D35: Eyk Lrg | K35: 0 | L35: Eyk Lg | N35: 5 | O35: Med Loose
C36: 0 | D36: Eyk Br | K36: 0 | L36: Lg Loose
B37: 8 | C37: 8 | D37: ED 18 XL | E37: OD | G37: 5. TRA | K37: =SUM(K35:K36) -> 0 | L37: Box Total
C38: =SUM(C35:C37) -> 16 | D38: Box Total | G38: 20 | H38: Eyk Lg
G39: 20 | H39: OC 30 Lg
G40: =SUM(G38:G39) -> 40 | H40: Box Total
C41: DAILY TOTALS
C43: Our Compliments | F43: pcs | G43: Walmart | K43: Loblaws | N43: Eyking
...

Sheet NFLD
A1: Ship Week: | C1: =Mon!D2+1 -> 62 | F1: BBD | G1: =Mon!F1+49-1 -> 46124
A4: Pallets | B4: Atlantic Grocery | E4: Pallets | F4: Fowlows | I4: Pallets | J4: Focenco
A5: =B5/48 -> 0 | C5: Eyk Xlg | E5: =F5/48 -> 0 | G5: Eyk Xlg | I5: =J5/48 -> 1.5 | J5: 72 | K5: Eyk Xlg
A6: =B6/48 -> 6 | B6: 288 | C6: Eyk Lg | E6: =F6/48 -> 0.5 | F6: 24 | G6: Eyk Lg | I6: =J6/48 -> 4 | J6: 192 | K6: Eyk Lg
A7: =B7/48 -> 0 | C7: Eyk Br | E7: =F7/48 -> 0 | G7: Eyk Br | I7: =J7/48 -> 1 | J7: 48 | K7: Eyk Br
A8: =B8/48 -> 0 | C8: ED Jum | E8: =F8/48 -> 0 | G8: ED Jum | I8: =J8/48 -> 0 | K8: ED Jum
A9: =B9/48 -> 0 | C9: ED XL 18 | E9: =F9/48 -> 0 | G9: ED XL 18 | I9: =J9/48 -> 3.5 | J9: 168 | K9: ED XL 18
A10: =B10/48 -> 2 | B10: 96 | C10: Lg Loose | E10: =F10/48 -> 0.5 | F10: 24 | G10: Lg Loose | I10: =J10/48 -> 0 | K10: Lg Loose
A11: =B11/48 -> 2 | B11: 96 | C11: Med Loose | E11: =F11/48 -> 0 | G11: Med Loose | I11: =J11/48 -> 0 | K11: Med Loose
A12: =B12/48 -> 10 | B12: =SUM(B5:B11) -> 480 | C12: Box Total | E12: =F12/48 -> 1 | F12: =SUM(F5:F11) -> 48 | G12: Box Total | I12: =J12/48 -> 10 | J12: =SUM(J5:J11) -> 480 | K12: Box Total
A40: DAILY TOTALS
A42: Our Compliments | C42: pcs | D42: Walmart | G42: Loblaws | J42: Eyking
B43: OC Xlg | C43: =D43*15 -> 0 | E43: Wal GV Xlrg | H43: Lob Xlg | J43: =B8+F8+J8 -> 0 | K43: ED Jum
B44: OC Lg | C44: =D44*15 -> 0 | E44: Wal GV Lg | H44: Lob Lg | J44: =B9+F9+J9 -> 168 | K44: ED 18 XL
B45: OC Med | C45: =D45*15 -> 0 | E45: Wal Nova Xlg Brn | H45: Lob br | K45: ED 18 LG
B46: OC Br | C46: =D46*15 -> 0 | E46: Wal Nova Brn | H46: Lob 30 | J46: =B5+F5+J5 -> 72 | K46: Eyk Xlg
B47: OC 30 Lrg | C47: =D47*12 -> 0 | E47: Nova Jumbo | J47: =B6+F6+J6 -> 504 | K47: Eyk Lg
B48: OC Lg Cozy Coop | C48: =D48*10 -> 0 | E48: Wal Nova 18's Lg | J48: =B7+F7+J7 -> 48 | K48: Eyk Br
C49: =D49*15 -> 0 | E49: All Grain Nova | J49: =B10+F10+J10 -> 120 | K49: Lg Loose
C50: =D50*15 -> 0 | E50: Nova 6 Pack | J50: =B11+F11+J11 -> 96 | K50: Med Loose
C51: =D51*8 -> 0 | E51: XLrg 30 pack Nova
C52: =D52*8 -> 0 | E52: Lrg 30 pack Nova
A57: Specialty | F57: pcs | G57: Small Tally
B58: OC Org F.Rng (B) | F58: =G58*15 -> 0 | G58: =A45 -> 0 | H58: OC Med
B59: OC Lg Free Run (W) | F59: =G59*15 -> 0 | G59: =A48 -> 0 | H59: OC Lg Cozy Coop
B60: OC Om Free Run (W) | F60: =G60*10 -> 0 | G60: =J45 -> 0 | H60: ED 18 LG
B61: MP Om 6pk (W) | F61: =G61*15 -> 0 | G61: =A46 -> 0 | H61: OC Br
B62: MP Om 12pk (W) | F62: =G62*15 -> 0 | G62: =G45 -> 0 | H62: Lob br
B63: MP Free Run (B) | F63: =G63*5 -> 0 | G63: =A47 -> 0 | H63: OC 30 Lg
B64: MP Coldspring F.Rng (B) | F64: =G64*8 -> 0 | G64: =G46 -> 0 | H64: Lob 30 Lg

Sheet Total
A1: Week Prepared: | C1: =Mon!D2 -> 61 | N1: WEEKLY PACKAGING USE | R1: WEEKLY TOTAL EGG SALES
N2: Carton Type | O2: Pcs | P2: Bundles | S2: Jum | T2: Xlg | U2: Lg | V2: Med | W2: Xlg Br | X2: Lg Br
A3: Our Compliments | D3: Walmart | G3: Loblaws | J3: Eyking | N3: ED Jum | O3: =J4*12 -> 1848 | P3: =O3/125 -> 14.784 | R3: Dozens | S3: =12*(D8+J4) -> 1908 | T3: =15*(A4+D4+G4+J7+J5)+20*D12 -> 9810 | U3: =15*(A5+A9+D5+D9+D10+D11+G5+J6+J8+J10)+20*(A8+D13+G7) -> 44180 | V3: =15*(A6+J11) -> 1650 | W3: =15*D6 -> 0 | X3: =15*(A7+D7+G6+J9) -> 1680
A4: =Mon!C70+Tues!C43+Wed!B42+Thurs!C72+Fri!C44+NFLD!A43 -> 26 | B4: OC Xlg | D4: =Mon!G70+Tues!G43+Wed!E42+Thurs!G72+Fri!G44+NFLD!D43 -> 25 | E4: Wal GV Xlrg | G4: =Mon!K70+Tues!K43+Wed!H42+Thurs!K72+Fri!K44+NFLD!G43 -> 6 | H4: Lob Xlg | J4: =Mon!N70+Tues!N43+Wed!K42+Thurs!N72+Fri!N44+NFLD!J43 -> 154 | K4: ED Jum | N4: ED 18 XL | O4: =J5*10 -> 4940 | P4: =O4/130 -> 38 | R4: Stacks | S4: =S3/15 -> 127.2 | T4: =T3/15 -> 654 | U4: =U3/15 -> 2945.3333 | V4: =V3/15 -> 110 | W4: =W3/15 -> 0 | X4: =X3/15 -> 112
A5: =Mon!C71+Tues!C44+Wed!B43+Thurs!C73+Fri!C45+NFLD!A44 -> 163 | B5: OC Lg | D5: =Mon!G71+Tues!G44+Wed!E43+Thurs!G73+Fri!G45+NFLD!D44 -> 100 | E5: Wal GV Lg | G5: =Mon!K71+Tues!K44+Wed!H43+Thurs!K73+Fri!K45+NFLD!G44 -> 227 | H5: Lob Lg | J5: =Mon!N71+Tues!N44+Wed!K43+Thurs!N73+Fri!N45+NFLD!J44 -> 494 | K5: ED 18 XL | N5: ED 18 LG | O5: =J6*10 -> 2590 | P5: =O5/130 -> 19.923077
A6: =Mon!C72+Tues!C45+Wed!B44+Thurs!C74+Fri!C46+NFLD!A45 -> 6 | B6: OC Med | D6: =Mon!G72+Tues!G45+Wed!E44+Thurs!G74+Fri!G46+NFLD!D45 -> 0 | E6: Wal Nova Xlg Brn | G6: =Mon!K72+Tues!K45+Wed!H44+Thurs!K74+Fri!K46+NFLD!G45 -> 13 | H6: Lob br | J6: =Mon!N72+Tues!N45+Wed!K44+Thurs!N74+Fri!N46+NFLD!J45 -> 259 | K6: ED 18 LG | N6: Eyk Xlg | O6: =J7*15 -> 1545 | P6: =O6/150 -> 10.3
A7: =Mon!C73+Tues!C46+Wed!B45+Thurs!C75+Fri!C47+NFLD!A46 -> 25 | B7: OC Br | D7: =Mon!G73+Tues!G46+Wed!E45+Thurs!G75+Fri!G47+NFLD!D46 -> 9 | E7: Wal Nova Brn | G7: =Mon!K73+Tues!K46+Wed!H45+Thurs!K75+Fri!K47+NFLD!G46 -> 184 | H7: Lob 30 | J7: =Mon!N73+Tues!N46+Wed!K45+Thurs!N75+Fri!N47+NFLD!J46 -> 103 | K7: Eyk Xlg | N7: Eyk Lg | O7: =J8*15 -> 10320 | P7: =O7/150 -> 68.8 | R7: Week | S7: =Mon!D2 -> 61
A8: =Mon!C74+Tues!C47+Wed!B46+Thurs!C76+Fri!C48+NFLD!A47 -> 453 | B8: OC 30 Lrg | D8: =Mon!G74+Tues!G47+Wed!E46+Thurs!G76+Fri!G48+NFLD!D47 -> 5 | E8: Nova Jumbo | J8: =Mon!N74+Tues!N47+Wed!K46+Thurs!N76+Fri!N48+NFLD!J47 -> 688 | K8: Eyk Lg | N8: Eyk Br | O8: =J9*15 -> 975 | P8: =O8/150 -> 6.5
A9: =Mon!C75+Tues!C48+Wed!B47+Thurs!C77+Fri!C49+NFLD!A48 -> 13 | B9: OC Lg Cozy Coop | D9: =Mon!G75+Tues!G48+Wed!E47+Thurs!G77+Fri!G49+NFLD!D48 -> 85 | E9: Wal Nova 18's Lg | J9: =Mon!N75+Tues!N48+Wed!K47+Thurs!N77+Fri!N49+NFLD!J48 -> 65 | K9: Eyk Br | N9: Filler Flats | O9: =7*(J10+J11)+8*(D12+D13+G7)+5*A9 -> 5768 | P9: =O9/140 -> 41.2
D10: =Mon!G76+Tues!G49+Wed!E48+Thurs!G78+Fri!G50+NFLD!D49 -> 0 | E10: All Grain Nova | J10: =Mon!N76+Tues!N49+Wed!K48+Thurs!N78+Fri!N50+NFLD!J49 -> 137 | K10: Lg Loose | N10: OC Xlg | O10: =A4*15 -> 390 | P10: =O10/250 -> 1.56
D11: =Mon!G77+Tues!G50+Wed!E49+Thurs!G79+Fri!G51+NFLD!D50 -> 0 | E11: Nova 6 Pack | J11: =Mon!N77+Tues!N50+Wed!K49+Thurs!N79+Fri!N51+NFLD!J50 -> 104 | K11: Med Loose | N11: OC Lg | O11: =A5*15 -> 2445 | P11: =O11/250 -> 9.78
D12: =Mon!G78+Tues!G51+Wed!E50+Thurs!G80+Fri!G52+NFLD!D51 -> 0 | E12: XLrg 30 pack Nova | N12: OC Med | O12: =A6*15 -> 90 | P12: =O12/250 -> 0.36
D13: =Mon!G79+Tues!G52+Wed!E51+Thurs!G81+Fri!G53+NFLD!D52 -> 318 | E13: Lrg 30 pack Nova | N13: OC Br | O13: =A7*15 -> 375 | P13: =O13/250 -> 1.5
N14: OC 30 Lrg Sleeve | O14: =5*A9 -> 65 | P14: =O14/50 -> 1.3
N15: OC Lg Cozy Coop | O15: =15*A9 -> 195 | P15: =O15/250 -> 0.78
A16: Specialty | D16: Small Tally | G16: QTY | H16: Carts | N16: Lob Xlg | O16: =15*G4 -> 90 | P16: =O16/250 -> 0.36
A17: =Mon!C85+Tues!C58+Wed!B57+Thurs!C87+Fri!C59+NFLD!A58 -> 6 | B17: OC Org F.Rng (B) | D17: =A6 -> 6 | E17: OC Med | G17: =Mon!N85+Tues!N58+Thurs!N87+Fri!N59 -> 0 | H17: OC Xlg | N17: Lob Lg | O17: =15*G5 -> 3405 | P17: =O17/250 -> 13.62
A18: =Mon!C86+Tues!C59+Wed!B58+Thurs!C88+Fri!C60+NFLD!A59 -> 6 | B18: OC Lg Free Run (W) | D18: =A9 -> 13 | E18: OC Lg Cozy Coop | G18: =Mon!N86+Tues!N59+Thurs!N88+Fri!N60 -> 1 | H18: OC Lg | N18: Lob br | O18: =15*G6 -> 195 | P18: =O18/250 -> 0.78
A19: =Mon!C87+Tues!C60+Wed!B59+Thurs!C89+Fri!C61+NFLD!A60 -> 1 | B19: OC Om Free Run (W) | D19: =J6 -> 259 | E19: ED 18 LG | G19: =Mon!N87+Tues!N60+Thurs!N89+Fri!N61 -> 14 | H19: OC 30 Lrg | N19: Lob 30 Sleeve | O19: =8*G7 -> 1472 | P19: =O19/50 -> 29.44
A20: =Mon!C88+Tues!C61+Wed!B60+Thurs!C90+Fri!C62+NFLD!A61 -> 1 | B20: MP Om 6pk (W) | D20: =A7 -> 25 | E20: OC Br | G20: =Mon!N88+Tues!N61+Thurs!N90+Fri!N62 -> 0 | H20: Lob Xlg | N20: Wal GV Xlrg | O20: =15*D4 -> 375 | P20: =O20/150 -> 2.5
A21: =Mon!C89+Tues!C62+Wed!B61+Thurs!C91+Fri!C63+NFLD!A62 -> 8 | B21: MP Om 12pk (W) | D21: =G6 -> 13 | E21: Lob br | G21: =Mon!N89+Tues!N62+Thurs!N91+Fri!N63 -> 2 | H21: Lob Lg | N21: Wal GV Lg | O21: =15*D5 -> 1500 | P21: =O21/150 -> 10
A22: =Mon!C90+Tues!C63+Wed!B62+Thurs!C92+Fri!C64+NFLD!A63 -> 1 | B22: MP Free Run (B) | D22: =A8 -> 453 | E22: OC 30 Lg | G22: =Mon!N90+Tues!N63+Thurs!N92+Fri!N64 -> 11 | H22: Lob 30 Lg | N22: Wal Nova Xlg Brn | O22: =15*D6 -> 0 | P22: =O22/150 -> 0
A23: =Mon!C91+Tues!C64+Wed!B63+Thurs!C93+Fri!C65+NFLD!A64 -> 2 | B23: MP Coldspring F.Rng (B) | D23: =G7 -> 184 | E23: Lob 30 Lg | G23: =Mon!N91+Tues!N64+Thurs!N93+Fri!N65 -> 5 | H23: ED 18 XL | N23: Wal Nova Brn | O23: =15*D7 -> 135 | P23: =O23/150 -> 0.9
G24: =Mon!N92+Tues!N65+Thurs!N94+Fri!N66 -> 9 | H24: ED 18 LG | N24: Nova Jumbo | O24: =12*D8 -> 60 | P24: =O24/125 -> 0.48
N25: Wal Nova 18's Lg | O25: =10*D9 -> 850 | P25: =O25/130 -> 6.5384615
N26: All Grain Nova | O26: =15*D10 -> 0 | P26: =O26/125 -> 0
N27: Nova 6 Pack | O27: =15*D11 -> 0 | P27: =O27/125 -> 0
N28: XLrg 30 pack Nova Sleeve | O28: =8*D12 -> 0 | P28: =O28/50 -> 0
N29: Lrg 30 pack Nova Sleeve | O29: =8*D13 -> 2544 | P29: =O29/50 -> 50.88
N31: Boxe Type | O31: Pcs | P31: Bundles
N32: Blue | O32: =A4+D4+G4+J5+J7-24*(G17+G20+G23) -> 534 | P32: =O32/25-24*(G17+G20+G23) -> -98.64 | R32: *box usage generally accounts for carts, but does not account if stores order a cart + boxes in the same order or if we run out of carts and have to pack carts into boxes
N33: Red | O33: =A5+A8+A9+D5+D10+D11+G5+J6+J8+J10-24*(G18+G21+G24)-20*G19 -> 1472 | P33: =O33/25-24*(G18+G21+G24)-20*G19 -> -509.12
N34: Black | O34: =D8+D9+J4 -> 244 | P34: =O34/25 -> 9.76
N35: Green | O35: =A6+J11 -> 110 | P35: =O35/25 -> 4.4
N36: Brown | O36: =A7+G6+D7+D6+J9 -> 112 | P36: =O36/25 -> 4.48
N37: Nova Wide | O37: =D12+D13 -> 318 | P37: =O37/20 -> 15.9
N38: Lob Wide | O38: =G7-13*G22 -> 41 | P38: =O38/20-13*G22 -> -140.95
