Workbook

Sheet Mon
B1: Ship Date: | D1: =DATE(2025,1,1)+(C2-1)*7-2 -> 45712 | H1: BBD | I1: =D1+42-1 -> 45753 | L1: NORTHSIDE
B2: Week | C2: 9
B4: 4. Sobeys - North Sydney | E4: 7.Superstore - North Sydney | H4: 6. WalMart - North Sydney
A5: =ROUNDDOWN(B5/24,0) -> 0 | C5: OC Xlg | D5: =ROUNDDOWN(E5/24,0) -> 0 | F5: Lob Xlg | I5: Wal GV Xlrg
A6: =ROUNDDOWN(B6/24,0) -> 0 | C6: OC Lg | D6: =ROUNDDOWN(E6/24,0) -> 0 | F6: Lob Lg | I6: Wal GV Lg
C7: OC Med | F7: Lob br | I7: Wal Nova Xlg Brn
C8: OC Br | D8: =ROUNDDOWN(E8/13,0) -> 0 | F8: Lob 30 Lg | I8: Wal Nova Brn
A9: =ROUNDDOWN(B9/20,0) -> 0 | C9: OC 30 Lrg | F9: ED Jumbo | I9: Nova Jumbo
C10: ED Jum | D10: =ROUNDDOWN(E10/24,0) -> 0 | F10: ED 18 XL | I10: Wal Nova 18's Lg
A11: =ROUNDDOWN(B11/24,0) -> 0 | C11: ED 18 XL | E11: =SUM(E5:E10) -> 0 | F11: Box Total | I11: All Grain Nova
A12: =ROUNDDOWN(B12/24,0) -> 0 | C12: ED 18 LG | I12: Nova 6 Pack
C13: Eyk Lg | E13: PO# | I13: XLrg 30 pack Nova
C14: OC Lg Cozy Coop | I14: Lrg 30 pack Nova
C15: OC Org F.Rng (B) | E15: 9. Shoppers - North Sydney | H15: =SUM(H5:H14) -> 0 | I15: Box Total
C16: OC Lg Free Run (W) | F16: Lob Lrg
C17: OC Om3 Free Run (W) | F17: Lob br | H17: PO#
C18: MP Om3 6pk (W) | F18: MP Om 12pk (W)
C19: MP Om3 12pk (W) | E19: =SUM(E16:E18) -> 0 | F19: Box Total
C20: MP Free Run (B)
C21: MP Coldspring F.Rng (B) | E21: 1. Harbour View (2021) (565-3109) | H21: 8. Northside Guest Home (8740)
B22: =SUM(B5:B21) -> 0 | C22: Box Total | F22: Lg Loose | H22: 11 | I22: Lg Loose
E24: 2. Miners Manor | H24: 18. Sexton's Pharmasave
B25: 5.Foodland - Sydney Mines | E25: 3 | F25: Lg Loose | I25: Eyk Lg
C26: OC xlg
C27: OC lrg | E27: 3. Northside General
C28: OC Med | F28: Med Loose
C29: OC Br | H29: **Total of Small Stops**
C30: ED Jum | H30: =E22+E25+H22 -> 14 | I30: Lg Loose
C31: ED 18 XL | H31: =E28 -> 0 | I31: Med Loose
C32: ED 18 LG | H32: =H25 -> 0 | I32: Eyk Lg
B33: =SUM(B26:B32) -> 0 | C33: Box Total
B34: Ship Date: | D34: =D1 -> 45712 | H34: BBD | I34: =I1 -> 45753 | L34: SYDNEY
B36: 10. Sobeys - Syd. River | E36: 11. WalMart - Syd. River | H36: 13. WalMart - Spar Rd.
A37: =ROUNDDOWN(B37/24,0) -> 0 | C37: OC Xlg | F37: Wal GV Xlrg | I37: Wal GV Xlrg
A38: =ROUNDDOWN(B38/24,0) -> 0 | C38: OC Lg | F38: Wal GV Lg | I38: Wal GV Lg
C39: OC Med | F39: Wal Nova Xlg Brn | I39: Wal Nova Xlg Brn
C40: OC Br | F40: Wal Nova Brn | I40: Wal Nova Brn
A41: =ROUNDDOWN(B41/20,0) -> 0 | C41: OC 30 Lrg | F41: Nova Jumbo | I41: Nova Jumbo
C42: ED Jum | F42: Wal Nova 18's Lg | I42: Wal Nova 18's Lg
A43: =ROUNDDOWN(B43/24,0) -> 0 | C43: ED 18 XL | F43: All Grain Nova | I43: All Grain Nova
...

Sheet Tues
B1: Ship Date: | D1: =DATE(2025,1,1)+(Mon!C2-1)*7-1 -> 45713 | H1: BBD | I1: =Mon!D1+42-1 -> 45753
B3: 2. Sobeys - Prince Street | E3: 6. Sobeys - New Waterford | H3: 11. Sobeys - Glace Bay | K3: 8. Foodland - Glace Bay
A4: =ROUNDDOWN(B4/24,0) -> 0 | B4: 2 | C4: OC Xlg | D4: =ROUNDDOWN(E4/24,0) -> 0 | E4: 0 | F4: OC Xlg | G4: =ROUNDDOWN(H4/24,0) -> 0 | H4: 0 | I4: OC Xlg | K4: 0 | L4: OC Xlg
A5: =ROUNDDOWN(B5/24,0) -> 0 | B5: 4 | C5: OC Lg | D5: =ROUNDDOWN(E5/24,0) -> 0 | E5: 4 | F5: OC Lg | G5: =ROUNDDOWN(H5/24,0) -> 0 | H5: 4 | I5: OC Lg | K5: 0 | L5: OC Lg
B6: 1 | C6: OC Med | E6: 0 | F6: OC Med | H6: 0 | I6: OC Med | K6: 0 | L6: OC Med
B7: 1 | C7: OC Br | E7: 0 | F7: OC Br | H7: 0 | I7: OC Br | K7: 0 | L7: OC Br
A8: =ROUNDDOWN(B8/20,0) -> 2 | B8: 40 | C8: OC 30 Lrg | D8: =ROUNDDOWN(E8/20,0) -> 1 | E8: 20 | F8: OC 30 Lrg | G8: =ROUNDDOWN(H8/20,0) -> 1 | H8: 24 | I8: OC 30 Lrg | K8: 8 | L8: OC 30 Lrg
B9: 7 | C9: ED Jum | E9: 5 | F9: ED Jum | H9: 6 | I9: ED Jum | K9: 0 | L9: ED Jum
A10: =ROUNDDOWN(B10/24,0) -> 0 | B10: 7 | C10: ED 18 XL | D10: =ROUNDDOWN(E10/24,0) -> 0 | E10: 2 | F10: ED 18 XL | G10: =ROUNDDOWN(H10/24,0) -> 0 | H10: 2 | I10: ED 18 XL | K10: 0 | L10: ED 18 XL
A11: =ROUNDDOWN(B11/24,0) -> 2 | B11: 48 | C11: ED 18 LG | D11: =ROUNDDOWN(E11/24,0) -> 0 | E11: 3 | F11: ED 18 LG | G11: =ROUNDDOWN(H11/24,0) -> 0 | H11: 5 | I11: ED 18 LG | K11: 0 | L11: ED 18 LG
B12: 3 | C12: Eyk Lg | E12: 0 | F12: Eyk Lg | H12: 2 | I12: Eyk Lg | K12: 0 | L12: Eyk Lg
B13: 9 | C13: OC Lg Cozy Coop | E13: 3 | F13: OC Lg Cozy Coop | H13: 2 | I13: OC Lg Cozy Coop | K13: =SUM(K4:K12) -> 8 | L13: Box Total
B14: 0 | C14: OC Org F.Rng (B) | E14: 0 | F14: OC Org F.Rng (B) | H14: 0 | I14: OC Org F.Rng (B)
B15: 0 | C15: OC Lg Free Run (W) | E15: 0 | F15: OC Lg Free Run (W) | H15: 0 | I15: OC Lg Free Run (W)
B16: 0 | C16: OC Om3 Free Run (W) | E16: 0 | F16: OC Om3 Free Run (W) | H16: 0 | I16: OC Om3 Free Run (W) | K16: 5. Pier Pharmasave
B17: 0 | C17: MP Om3 6pk (W) | E17: 0 | F17: MP Om3 6pk (W) | H17: 0 | I17: MP Om3 6pk (W) | K17: 6 | L17: Eyk Lg
B18: 0 | C18: MP Om3 12pk (W) | E18: 0 | F18: MP Om3 12pk (W) | H18: 0 | I18: MP Om3 12pk (W)
B19: 1 | C19: MP Free Run (B) | E19: 0 | F19: MP Free Run (B) | H19: 0 | I19: MP Free Run (B) | K19: 7. Dominion Pharmasave
B20: 0 | C20: MP Coldspring F.Rng (B) | E20: 0 | F20: MP Coldspring F.Rng (B) | H20: 0 | I20: MP Coldspring F.Rng (B) | K20: 4 | L20: Eyk Lg
B21: =SUM(B4:B20) -> 123 | C21: Box Total | E21: =SUM(E4:E20) -> 37 | F21: Box Total | H21: =SUM(H4:H20) -> 45 | I21: Box Total
B23: 4.Superstore - Syd. River | E23: 12.Superstore - Glace Bay | H23: 9. Shoppers - Glace Bay | K23: 14. Meadows Pharmasave
A24: =ROUNDDOWN(B24/24,0) -> 0 | B24: 1 | C24: Lob Xlg | D24: =ROUNDDOWN(E24/24,0) -> 0 | E24: 1 | F24: Lob Xlg | H24: 10 | I24: Lob Lrg | K24: 15 | L24: Eyk Lg
A25: =ROUNDDOWN(B25/24,0) -> 1 | B25: 24 | C25: Lob Lg | D25: =ROUNDDOWN(E25/24,0) -> 0 | E25: 9 | F25: Lob Lg | H25: 0 | I25: Lob br
B26: 1 | C26: Lob br | E26: 1 | F26: Lob br | H26: 0 | I26: MP Om 12pk (W) | K26: 10. Medical Hall Pharmasave
A27: =ROUNDDOWN(B27/13,0) -> 1 | B27: 13 | C27: Lob 30 Lg | D27: =ROUNDDOWN(E27/13,0) -> 0 | E27: 12 | F27: Lob 30 Lg | H27: =SUM(H24:H26) -> 10 | I27: Box Total | K27: 28 | L27: Eyk Lg
B28: 6 | C28: ED Jumbo | E28: 5 | F28: ED Jumbo | K28: 1 | L28: Eyk Br
A29: =ROUNDDOWN(B29/24,0) -> 0 | B29: 0 | C29: ED XL 18 | D29: =ROUNDDOWN(E29/24,0) -> 0 | E29: 6 | F29: ED XL 18 | H29: 3. McIllvary Guest Home
B30: =SUM(B24:B29) -> 45 | C30: Box Total | E30: =SUM(E24:E29) -> 34 | F30: Box Total | H30: 3 | I30: Lg Loose | K30: **Pharmasave Total**
K31: =K17+K20+K24+K27 -> 53 | L31: Eyk Lg
B32: PO# | C32: 4874058047 | E32: PO# | F32: 4874054015 | K32: =K28 -> 1 | L32: Eyk Br
B34: 1. Giant Tiger | E34: 13. TRA
B35: 10 | C35: Eyk Lrg | E35: 8 | F35: Eyk Lg
B36: 1 | C36: Eyk Br | E36: 12 | F36: OC 30 Lg
B37: 7 | C37: ED 18 XL | E37: =SUM(E35:E36) -> 20 | F37: Box Total
B38: 0 | C38: Lrg 30 pack Nova
B39: =SUM(B35:B38) -> 18 | C39: Box Total
B40: DAILY TOTALS
B42: Our Compliments | D42: pcs | E42: Walmart | H42: Loblaws | K42: Eyking
B43: =B4+H4+K4+E4 -> 2 | C43: OC Xlg | D43: =E43*15 -> 0 | F43: Wal GV Xlrg | H43: =B24+E24 -> 2 | I43: Lob Xlg | K43: =B9+B28+H9+K9+E9+E28 -> 29 | L43: ED Jum
B44: =B5+H5+K5+E5 -> 12 | C44: OC Lg | D44: =E44*15 -> 0 | F44: Wal GV Lg | H44: =B25+E25+H24 -> 43 | I44: Lob Lg | K44: =B10+B29+H10+K10+E10+E29+B37 -> 24 | L44: ED 18 XL
...

Sheet Wed
B1: Ship Date: | D1: =DATE(2024,1,1)+(Mon!C2-1)*7+2 -> 45350 | H1: BBD | I1: =Mon!D1+49-1 -> 45760 | K1: 21. Cheticamp Co-op
K2: 0 | L2: OC Xlg
B3: 1. Cedar House | E3: 3. Victoria Farmers - Co-op | H3: 14. Port Hood Co-op | K3: 5 | L3: OC Lg
B4: 0 | C4: Lg Loose | E4: 2 | F4: OC Xlg | H4: 2 | I4: OC Xlg | K4: 8 | L4: Eyk Br
E5: 8 | F5: OC Lg | H5: 8 | I5: OC Lg | K5: 14 | L5: OC 30 Lrg
B6: 2. Alderwood Rest Home | E6: 3 | F6: OC Br | H6: 2 | I6: OC Br | K6: 2 | L6: ED Jumbo
B7: 3 | C7: Lg Loose | E7: 12 | F7: ED Jum | H7: 6 | I7: OC 30 Lrg | K7: 8 | L7: Eyk Xlg
E8: 24 | F8: ED 18 XL | H8: =SUM(H4:H7) -> 18 | I8: Box Total | K8: 4 | L8: Eyk Lg
B9: 4. Julia's Bakery | E9: =SUM(E4:E8) -> 49 | F9: Box Total | K9: 3 | L9: ED XL 18
B10: 2 | C10: Lg Loose | K10: 0 | L10: MP Om3 6pk (W)
E11: 11. Whycocomagh Co-op | H11: 16. Shean Co-op | K11: 0 | L11: MP Om3 12pk (W)
B12: 5. Telegraph House | E12: 0 | F12: OC Xlg | H12: 10 | I12: OC Xlg | K12: =SUM(K2:K11) -> 44 | L12: Box Total
B13: 0 | C13: Lg Loose | E13: 8 | F13: OC Lg | H13: 11 | I13: OC Lg
E14: 2 | F14: OC Br | H14: 4 | I14: OC Br | K14: 24. Margaree Co-op
B15: 6. Bean There Café | E15: 12 | F15: OC 30 Lrg | H15: 13 | I15: OC 30 Lrg | K15: 0 | L15: OC Xlg
B16: 1 | C16: Med Loose | E16: 6 | F16: ED Jum | H16: 0 | I16: MP Om3 6pk (W) | K16: 3 | L16: OC Lg
E17: 8 | F17: ED 18 XL | H17: 0 | I17: MP Om3 12pk (W) | K17: 4 | L17: OC Br
B18: 7. Gisele's Inn | E18: =SUM(E12:E17) -> 36 | F18: Box Total | H18: =SUM(H12:H17) -> 38 | I18: Box Total | K18: 0 | L18: OC 30 Lrg
B19: 0 | C19: Lg Loose | K19: 4 | L19: ED Jumbo
K20: 10 | L20: ED XL 18
B21: 8. From Billy Bistro & Pub | E21: 12. Mabou Freshmart | H21: 15. Coal Miners Café | K21: =SUM(K15:K20) -> 21 | L21: Box Total
B22: 0 | C22: Med Loose | E22: 3 | F22: Eyk Xlg | H22: 1 | I22: Lg Loose
E23: 6 | F23: Eyk Lg | K23: 23. Lemoines Co-op
B24: 9. Farmers Daughter | E24: 2 | F24: Eyk Br | H24: 17. Inverness Pantry | K24: 2 | L24: Eyk Xlg
B25: 0 | C25: Eyk Lg | E25: 0 | F25: Lg Loose | H25: 0 | I25: Eyk Lg | K25: 3 | L25: Eyk Lg
B26: 0 | C26: Lg Loose | E26: 0 | F26: OC 30 Lrg | H26: 0 | I26: Lg Loose | K26: 1 | L26: Eyk Br
B27: =SUM(B25:B26) -> 0 | C27: Box Total | E27: 0 | F27: MP Om3 6pk (W) | H27: =SUM(H25:H26) -> 0 | I27: Box Total | K27: =SUM(K24:K26) -> 6 | L27: Box Total
E28: 0 | F28: MP Om3 12pk (W)
B29: 10. McKeigans Pharmacy | E29: =SUM(E22:E28) -> 11 | F29: Box Total | H29: 18. Lawrence's Store | K29: 22. LeBlancs General Store
B30: 3 | C30: Eyk Xlg | H30: 1 | I30: Eyk Lg | K30: 2 | L30: Eyk Xlg
B31: 3 | C31: Eyk Lg | E31: 13. Cabot Trail Food | K31: 1 | L31: Eyk Lg
B32: =SUM(B30:B31) -> 6 | C32: Box Total | E32: 0 | F32: Eyk Xlg | H32: 19. Duck Cove Inn | K32: 0 | L32: Eyk Br
E33: 0 | F33: Eyk Lg | H33: 0 | I33: Lg Loose | K33: =SUM(K30:K32) -> 3 | L33: Box Total
B34: Ingrahams Rite Stop | E34: 0 | F34: Eyk Br
B35: 0 | C35: Eyk Lg | E35: =SUM(E32:E34) -> 0 | F35: Box Total | H35: 20. Doucette's Inn | K35: 25. Stone's Drug Store
H36: 0 | I36: Med Loose | K36: 4 | L36: Eyk Lg
K37: 1 | L37: Eyk Br
K38: =SUM(K36:K37) -> 5 | L38: Box Total
B39: DAILY TOTALS
B41: Our Compliments | D41: pcs | E41: Walmart | H41: Loblaws | K41: Eyking
...

Sheet Thurs
B1: Ship Date: | D1: =DATE(2024,1,1)+(Mon!C2-1)*7+3 -> 45351 | H1: BBD | I1: =Mon!D1+49-1 -> 45760 | L1: NORTHSIDE
B3: 1. Sobeys - North Sydney | E3: 3. Foodland - Sydney Mines | H3: 5. Superstore - North Sydney | K3: 4. WalMart - North Sydney
A4: =ROUNDDOWN(B4/24,0) -> 0 | B4: 1 | C4: OC Xlg | E4: 0 | F4: OC xlg | G4: =ROUNDDOWN(H4/24,0) -> 0 | H4: 2 | I4: Lob Xlg | K4: 0 | L4: Wal GV Xlrg
A5: =ROUNDDOWN(B5/24,0) -> 0 | B5: 0 | C5: OC Lg | E5: 4 | F5: OC lrg | G5: =ROUNDDOWN(H5/24,0) -> 0 | H5: 8 | I5: Lob Lg | K5: 0 | L5: Wal GV Lg
B6: 1 | C6: OC Med | E6: 0 | F6: OC Med | H6: 2 | I6: Lob br | K6: 0 | L6: Wal Nova Xlg Brn
B7: 1 | C7: OC Br | E7: 1 | F7: OC Br | G7: =ROUNDDOWN(H7/13,0) -> 0 | H7: 10 | I7: Lob 30 Lg | K7: 0 | L7: Wal Nova Brn
A8: =ROUNDDOWN(B8/20,0) -> 1 | B8: 26 | C8: OC 30 Lrg | E8: 3 | F8: ED Jum | H8: 6 | I8: ED Jumbo | K8: 0 | L8: Nova Jumbo
B9: 6 | C9: ED Jum | E9: 3 | F9: ED 18 XL | G9: =ROUNDDOWN(H9/24,0) -> 0 | H9: 15 | I9: ED 18 XL | K9: 0 | L9: Wal Nova 18's Lg
A10: =ROUNDDOWN(B10/24,0) -> 0 | B10: 4 | C10: ED 18 XL | E10: 0 | F10: ED 18 LG | H10: =SUM(H4:H9) -> 43 | I10: Box Total | K10: 0 | L10: All Grain Nova
A11: =ROUNDDOWN(B11/24,0) -> 2 | B11: 48 | C11: ED 18 LG | E11: =SUM(E4:E10) -> 11 | F11: Box Total | K11: 0 | L11: Nova 6 Pack
B12: 0 | C12: Eyk Lg | H12: PO# | I12: 4874092794 | K12: 0 | L12: XLrg 30 pack Nova
B13: 2 | C13: OC Lg Cozy Coop | K13: 0 | L13: Lrg 30 pack Nova
B14: 0 | C14: OC Org F.Rng (B) | H14: 7. Shoppers - North Sydney | K14: =SUM(K4:K13) -> 0 | L14: Box Total
B15: 0 | C15: OC Lg Free Run (W) | H15: 16 | I15: Lob Lrg
B16: 0 | C16: OC Om3 Free Run (W) | H16: 0 | I16: Lob br | K16: PO#
B17: 1 | C17: MP Om3 6pk (W) | H17: 0 | I17: MP Om3 12pk (W)
B18: 0 | C18: MP Om3 12pk (W) | H18: =SUM(H15:H17) -> 16 | I18: Box Total
B19: 0 | C19: MP Free Run (B)
B20: 0 | C20: MP Coldspring F.Rng (B)
B21: =SUM(B4:B20) -> 90 | C21: Box Total
B24: 2. Nala's | E24: 16. Janes
B25: 3 | C25: Lg Loose | E25: 1 | F25: Lg Loose
B27: 6. Bonnar's Meats | E27: 17. Bras D'or View
B28: 8 | C28: Eyk Xlg | E28: 0 | F28: Lg Loose
B35: Ship Date: | D35: =D1 -> 45351 | H35: BBD | I35: =I1 -> 45760 | L35: SYDNEY
B37: 8. Sobeys - Syd. River | E37: 12.Colbourne - No Frills | H37: 9. WalMart - Syd. River | K37: 11. WalMart - Spar Rd.
A38: =ROUNDDOWN(B38/24,0) -> 0 | B38: 2 | C38: OC Xlg | D38: =ROUNDDOWN(E38/24,0) -> 0 | E38: 15 | F38: Lob xlg | H38: 8 | I38: Wal GV Xlrg | K38: 15 | L38: Wal GV Xlrg
A39: =ROUNDDOWN(B39/24,0) -> 0 | B39: 8 | C39: OC Lg | D39: =ROUNDDOWN(E39/24,0) -> 4 | E39: 96 | F39: Lob lg | H39: 12 | I39: Wal GV Lg | K39: 15 | L39: Wal GV Lg
B40: 1 | C40: OC Med | E40: 8 | F40: Lob Br | H40: 0 | I40: Wal Nova Xlg Brn | K40: 0 | L40: Wal Nova Xlg Brn
B41: 0 | C41: OC Br | D41: =ROUNDDOWN(E41/13,0) -> 4 | E41: 52 | F41: Lob 30 Lg | H41: 3 | I41: Wal Nova Brn | K41: 2 | L41: Wal Nova Brn
A42: =ROUNDDOWN(B42/20,0) -> 1 | B42: 20 | C42: OC 30 Lrg | E42: 15 | F42: ED Jumbo | H42: 0 | I42: Nova Jumbo | K42: 0 | L42: Nova Jumbo
B43: 6 | C43: ED Jum | D43: =ROUNDDOWN(E43/24,0) -> 0 | E43: 15 | F43: ED 18 XL | H43: 23 | I43: Wal Nova 18's Lg | K43: 37 | L43: Wal Nova 18's Lg
A44: =ROUNDDOWN(B44/24,0) -> 5 | B44: 120 | C44: ED 18 XL | E44: =SUM(E38:E43) -> 201 | F44: Box Total | H44: 0 | I44: All Grain Nova | K44: 0 | L44: All Grain Nova
A45: =ROUNDDOWN(B45/24,0) -> 0 | B45: 0 | C45: ED 18 LG | H45: 0 | I45: Nova 6 Pack | K45: 0 | L45: Nova 6 Pack
B46: 6 | C46: Eyk Lg | E46: PO# | F46: 4874092179 | H46: 0 | I46: XLrg 30 pack Nova | K46: 0 | L46: XLrg 30 pack Nova
B47: 0 | C47: OC Lg Cozy Coop | H47: 36 | I47: Lrg 30 pack Nova | K47: 56 | L47: Lrg 30 pack Nova
B48: 0 | C48: OC Org F.Rng (B) | H48: =SUM(H38:H47) -> 82 | I48: Box Total | K48: =SUM(K38:K47) -> 125 | L48: Box Total
B49: 0 | C49: OC Lg Free Run (W) | E49: 13. Shoppers - Prince St.
B50: 0 | C50: OC Om Free Run (W) | E50: 60 | F50: Lob Lrg | H50: PO# | I50: 9638 | K50: PO# | L50: 9542
B51: 0 | C51: MP Om 6pk (W) | E51: 0 | F51: Lob br
...

Sheet Fri
B1: Ship Date: | D1: =DATE(2024,1,1)+(Mon!C2-1)*7+4 -> 45352 | H1: BBD | I1: =Mon!D1+49-1 -> 45760
B3: 2. Sobeys - Prince Street | E3: 7. Sobeys - New Waterford | H3: 13. Sobeys - Glace Bay | K3: 10. Foodland - Glace Bay | N3: 16. Eskasoni
A4: =ROUNDDOWN(B4/24,0) -> 0 | B4: 1 | C4: OC Xlg | D4: =ROUNDDOWN(E4/24,0) -> 0 | E4: 0 | F4: OC Xlg | G4: =ROUNDDOWN(H4/24,0) -> 0 | H4: 0 | I4: OC Xlg | K4: 1 | L4: OC Xlg | N4: 0 | O4: OC Xlg
A5: =ROUNDDOWN(B5/24,0) -> 0 | B5: 1 | C5: OC Lg | D5: =ROUNDDOWN(E5/24,0) -> 0 | E5: 6 | F5: OC Lg | G5: =ROUNDDOWN(H5/24,0) -> 0 | H5: 6 | I5: OC Lg | K5: 0 | L5: OC Lg | N5: 0 | O5: OC Lg
B6: 1 | C6: OC Med | E6: 1 | F6: OC Med | H6: 0 | I6: OC Med | K6: 1 | L6: OC Med | N6: 0 | O6: OC Med
B7: 1 | C7: OC Br | E7: 1 | F7: OC Br | H7: 1 | I7: OC Br | K7: 0 | L7: OC Br | N7: 0 | O7: OC Br
A8: =ROUNDDOWN(B8/20,0) -> 1 | B8: 20 | C8: OC 30 Lrg | D8: =ROUNDDOWN(E8/20,0) -> 1 | E8: 20 | F8: OC 30 Lrg | G8: =ROUNDDOWN(H8/20,0) -> 1 | H8: 30 | I8: OC 30 Lrg | K8: 0 | L8: OC 30 Lrg | N8: 0 | O8: OC 30 Lrg
B9: 3 | C9: ED Jum | E9: 6 | F9: ED Jum | H9: 5 | I9: ED Jum | K9: 4 | L9: ED Jum | N9: 0 | O9: ED Jum
A10: =ROUNDDOWN(B10/24,0) -> 0 | B10: 3 | C10: ED 18 XL | D10: =ROUNDDOWN(E10/24,0) -> 0 | E10: 2 | F10: ED 18 XL | G10: =ROUNDDOWN(H10/24,0) -> 0 | H10: 8 | I10: ED 18 XL | K10: 4 | L10: ED 18 XL | N10: 0 | O10: ED 18 XL
A11: =ROUNDDOWN(B11/24,0) -> 4 | B11: 96 | C11: ED 18 LG | D11: =ROUNDDOWN(E11/24,0) -> 0 | E11: 10 | F11: ED 18 LG | G11: =ROUNDDOWN(H11/24,0) -> 4 | H11: 96 | I11: ED 18 LG | K11: 0 | L11: ED 18 LG | N11: 0 | O11: ED 18 LG
B12: 2 | C12: Eyk Lg | E12: 0 | F12: Eyk Lg | H12: 2 | I12: Eyk Lg | K12: 0 | L12: F.John Lg | N12: 0 | O12: MP Om 12
B13: 0 | C13: OC Lg Cozy Coop | E13: 0 | F13: OC Lg Cozy Coop | H13: 1 | I13: OC Lg Cozy Coop | K13: =SUM(K4:K12) -> 10 | L13: Box Total | N13: =SUM(N4:N12) -> 0 | O13: Box Total
B14: 0 | C14: OC Org F.Rng (B) | E14: 0 | F14: OC Org F.Rng (B) | H14: 0 | I14: OC Org F.Rng (B)
B15: 4 | C15: OC Lg Free Run (W) | E15: 0 | F15: OC Lg Free Run (W) | H15: 1 | I15: OC Lg Free Run (W) | K15: 5. Pier Pharmasave
B16: 0 | C16: OC Om3 Free Run (W) | E16: 0 | F16: OC Om3 Free Run (W) | H16: 1 | I16: OC Om3 Free Run (W) | K16: 0 | L16: Eyk Lg
B17: 0 | C17: MP Om3 6pk (W) | E17: 0 | F17: MP Om3 6pk (W) | H17: 0 | I17: MP Om3 6pk (W)
B18: 0 | C18: MP Om3 12pk (W) | E18: 1 | F18: MP Om3 12pk (W) | H18: 1 | I18: MP Om3 12pk (W) | K18: 8. Midtown Pharmasave
B19: 1 | C19: MP Free Run (B) | E19: 0 | F19: MP Free Run (B) | H19: 0 | I19: MP Free Run (B) | K19: 20 | L19: Eyk Lg
B20: 1 | C20: MP Coldspring | E20: 0 | F20: MP Coldspring | H20: 0 | I20: MP Coldspring
B21: =SUM(B4:B20) -> 134 | C21: Box Total | E21: =SUM(E4:E20) -> 47 | F21: Box Total | H21: =SUM(H4:H20) -> 152 | I21: Box Total | K21: 9. Dominion Pharmasave
K22: 4 | L22: Eyk Lg
B23: 4.Superstore - Syd. River | E23: 14. Superstore - Glace Bay | H23: 11. Shoppers - Glace Bay
A24: =ROUNDDOWN(B24/24,0) -> 0 | B24: 0 | C24: Lob Xlg | D24: =ROUNDDOWN(E24/24,0) -> 0 | E24: 2 | F24: Lob Xlg | H24: 5 | I24: Lob Lrg | K24: 12. Medical Hall Pharm.
A25: =ROUNDDOWN(B25/24,0) -> 1 | B25: 24 | C25: Lob Lg | D25: =ROUNDDOWN(E25/24,0) -> 0 | E25: 10 | F25: Lob Lg | H25: 0 | I25: Lob br | K25: 25 | L25: Eyk Lg
B26: 0 | C26: Lob br | E26: 1 | F26: Lob br | H26: 0 | I26: MP Om3 12pk (W) | K26: 1 | L26: Eyk Brn
A27: =ROUNDDOWN(B27/13,0) -> 1 | B27: 14 | C27: Lob 30 Lg | D27: =ROUNDDOWN(E27/13,0) -> 0 | E27: 12 | F27: Lob 30 Lg | H27: =SUM(H24:H26) -> 5 | I27: Box Total | K27: 17. Meadows Pharmasave
B28: 6 | C28: ED Jumbo | E28: 6 | F28: ED Jumbo | K28: 15 | L28: Eyk Lg
A29: =ROUNDDOWN(B29/24,0) -> 0 | B29: 0 | C29: ED 18 XL | D29: =ROUNDDOWN(E29/24,0) -> 0 | E29: 8 | F29: ED 18 XL
B30: =SUM(B24:B29) -> 44 | C30: Box Total | E30: =SUM(E24:E29) -> 39 | F30: Box Total | K30: **Pharmasave Total**
K31: =K16+K19+K22+K25+K28 -> 64 | L31: Eyk Lg
B32: PO# | C32: 4874114444 | E32: PO# | F32: 4874113383
B34: 1. Giant Tiger | E34: 3. Mira Ferry Market | H34: 6. Omni Foods | K34: 11. Seaview Manor
B35: 10 | C35: Eyk Lrg | E35: 0 | F35: Lg Loose | H35: 0 | I35: Eyk Lg | K35: 5 | L35: Med Loose
B36: 2 | C36: Eyk Br | H36: 0 | I36: Lg Loose
B37: 10 | C37: ED 18 XL | E37: 15. TRA | H37: =SUM(H35:H36) -> 0 | I37: Box Total
B38: =SUM(B35:B37) -> 22 | C38: Box Total | E38: 10 | F38: Eyk Lg
E39: 15 | F39: OC 30 Lg
E40: =SUM(E38:E39) -> 25 | F40: Box Total
B41: DAILY TOTALS
B43: Our Compliments | D43: pcs | E43: Walmart | H43: Loblaws | K43: Eyking
...

Sheet NFLD
A1: Ship Week: | C1: =Mon!C2+1 -> 10 | F1: BBD | G1: =Mon!D1+49-1 -> 45760
A4: Pallets | B4: Atlantic Grocery | E4: Pallets | F4: Fowlows | I4: Pallets | J4: Focenco
A5: =B5/48 -> 1 | B5: 48 | C5: Eyk Xlg | E5: =F5/48 -> 0 | G5: Eyk Xlg | I5: =J5/48 -> 1 | J5: 48 | K5: Eyk Xlg
A6: =B6/48 -> 5 | B6: 240 | C6: Eyk Lg | E6: =F6/48 -> 0 | G6: Eyk Lg | I6: =J6/48 -> 4 | J6: 192 | K6: Eyk Lg
A7: =B7/48 -> 0 | C7: Eyk Br | E7: =F7/48 -> 0 | G7: Eyk Br | I7: =J7/48 -> 0.5 | J7: 24 | K7: Eyk Br
A8: =B8/48 -> 0 | C8: ED Jum | E8: =F8/48 -> 0 | G8: ED Jum | I8: =J8/48 -> 0 | K8: ED Jum
A9: =B9/48 -> 0 | C9: ED XL 18 | E9: =F9/48 -> 0 | G9: ED XL 18 | I9: =J9/48 -> 3.5 | J9: 168 | K9: ED XL 18
A10: =B10/48 -> 2 | B10: 96 | C10: Lg Loose | E10: =F10/48 -> 0 | G10: Lg Loose | I10: =J10/48 -> 0 | K10: Lg Loose
A11: =B11/48 -> 3 | B11: 144 | C11: Med Loose | E11: =F11/48 -> 0 | G11: Med Loose | I11: =J11/48 -> 0 | K11: Med Loose
A12: =B12/48 -> 11 | B12: =SUM(B5:B11) -> 528 | C12: Box Total | E12: =F12/48 -> 0 | F12: =SUM(F5:F11) -> 0 | G12: Box Total | I12: =J12/48 -> 9 | J12: =SUM(J5:J11) -> 432 | K12: Box Total
A40: DAILY TOTALS
A42: Our Compliments | C42: pcs | D42: Walmart | G42: Loblaws | J42: Eyking
B43: OC Xlg | C43: =D43*15 -> 0 | E43: Wal GV Xlrg | H43: Lob Xlg | J43: =B8+F8+J8 -> 0 | K43: ED Jum
B44: OC Lg | C44: =D44*15 -> 0 | E44: Wal GV Lg | H44: Lob Lg | J44: =B9+F9+J9 -> 168 | K44: ED 18 XL
B45: OC Med | C45: =D45*15 -> 0 | E45: Wal Nova Xlg Brn | H45: Lob br | K45: ED 18 LG
B46: OC Br | C46: =D46*15 -> 0 | E46: Wal Nova Brn | H46: Lob 30 | J46: =B5+F5+J5 -> 96 | K46: Eyk Xlg
B47: OC 30 Lrg | C47: =D47*12 -> 0 | E47: Nova Jumbo | J47: =B6+F6+J6 -> 432 | K47: Eyk Lg
B48: OC Lg Cozy Coop | C48: =D48*10 -> 0 | E48: Wal Nova 18's Lg | J48: =B7+F7+J7 -> 24 | K48: Eyk Br
C49: =D49*15 -> 0 | E49: All Grain Nova | J49: =B10+F10+J10 -> 96 | K49: Lg Loose
C50: =D50*15 -> 0 | E50: Nova 6 Pack | J50: =B11+F11+J11 -> 144 | K50: Med Loose
C51: =D51*8 -> 0 | E51: XLrg 30 pack Nova
C52: =D52*8 -> 0 | E52: Lrg 30 pack Nova
A57: Specialty | F57: pcs | G57: Small Tally
B58: OC Org F.Rng (B) | F58: =G58*15 -> 0 | G58: =A45 -> 0 | H58: OC Med
B59: OC Lg Free Run (W) | F59: =G59*15 -> 0 | G59: =A48 -> 0 | H59: OC Lg Cozy Coop
B60: OC Om Free Run (W) | F60: =G60*10 -> 0 | G60: =J45 -> 0 | H60: ED 18 LG
B61: MP Om 6pk (W) | F61: =G61*15 -> 0 | G61: =A46 -> 0 | H61: OC Br
B62: MP Om 12pk (W) | F62: =G62*15 -> 0 | G62: =G45 -> 0 | H62: Lob br
B63: MP Free Run (B) | F63: =G63*5 -> 0 | G63: =A47 -> 0 | H63: OC 30 Lg
B64: MP Coldspring F.Rng (B) | F64: =G64*8 -> 0 | G64: =G46 -> 0 | H64: Lob 30 Lg

Sheet Total
A1: Week Prepared: | C1: =Mon!C2 -> 9 | N1: WEEKLY PACKAGING USE | R1: WEEKLY TOTAL EGG SALES
N2: Carton Type | O2: Pcs | P2: Bundles | S2: Jum | T2: Xlg | U2: Lg | V2: Med | W2: Xlg Br | X2: Lg Br
A3: Our Compliments | D3: Walmart | G3: Loblaws | J3: Eyking | N3: ED Jum | O3: =J4*12 -> 1380 | P3: =O3/125 -> 11.04 | R3: Dozens | S3: =12*(D8+J4) -> 1380 | T3: =15*(A4+D4+G4+J7+J5)+20*D12 -> 9375 | U3: =15*(A5+A9+D5+D9+D10+D11+G5+J6+J8+J10)+20*(A8+D13+G7) -> 32410 | V3: =15*(A6+J11) -> 2340 | W3: =15*D6 -> 0 | X3: =15*(A7+D7+G6+J9) -> 1260
A4: =Mon!B70+Tues!B43+Wed!B42+Thurs!B72+Fri!B44+NFLD!A43 -> 21 | B4: OC Xlg | D4: =Mon!E70+Tues!E43+Wed!E42+Thurs!E72+Fri!E44+NFLD!D43 -> 23 | E4: Wal GV Xlrg | G4: =Mon!H70+Tues!H43+Wed!H42+Thurs!H72+Fri!H44+NFLD!G43 -> 21 | H4: Lob Xlg | J4: =Mon!K70+Tues!K43+Wed!K42+Thurs!K72+Fri!K44+NFLD!J43 -> 115 | K4: ED Jum | N4: ED 18 XL | O4: =J5*10 -> 4330 | P4: =O4/130 -> 33.307692 | R4: Stacks | S4: =S3/15 -> 92 | T4: =T3/15 -> 625 | U4: =U3/15 -> 2160.6667 | V4: =V3/15 -> 156 | W4: =W3/15 -> 0 | X4: =X3/15 -> 84
A5: =Mon!B71+Tues!B44+Wed!B43+Thurs!B73+Fri!B45+NFLD!A44 -> 83 | B5: OC Lg | D5: =Mon!E71+Tues!E44+Wed!E43+Thurs!E73+Fri!E45+NFLD!D44 -> 27 | E5: Wal GV Lg | G5: =Mon!H71+Tues!H44+Wed!H43+Thurs!H73+Fri!H45+NFLD!G44 -> 292 | H5: Lob Lg | J5: =Mon!K71+Tues!K44+Wed!K43+Thurs!K73+Fri!K45+NFLD!J44 -> 433 | K5: ED 18 XL | N5: ED 18 LG | O5: =J6*10 -> 3060 | P5: =O5/130 -> 23.538462
A6: =Mon!B72+Tues!B45+Wed!B44+Thurs!B74+Fri!B46+NFLD!A45 -> 6 | B6: OC Med | D6: =Mon!E72+Tues!E45+Wed!E44+Thurs!E74+Fri!E46+NFLD!D45 -> 0 | E6: Wal Nova Xlg Brn | G6: =Mon!H72+Tues!H45+Wed!H44+Thurs!H74+Fri!H46+NFLD!G45 -> 13 | H6: Lob br | J6: =Mon!K72+Tues!K45+Wed!K44+Thurs!K74+Fri!K46+NFLD!J45 -> 306 | K6: ED 18 LG | N6: Eyk Xlg | O6: =J7*15 -> 1905 | P6: =O6/150 -> 12.7
A7: =Mon!B73+Tues!B46+Wed!B45+Thurs!B75+Fri!B47+NFLD!A46 -> 25 | B7: OC Br | D7: =Mon!E73+Tues!E46+Wed!E45+Thurs!E75+Fri!E47+NFLD!D46 -> 5 | E7: Wal Nova Brn | G7: =Mon!H73+Tues!H46+Wed!H45+Thurs!H75+Fri!H47+NFLD!G46 -> 113 | H7: Lob 30 | J7: =Mon!K73+Tues!K46+Wed!K45+Thurs!K75+Fri!K47+NFLD!J46 -> 127 | K7: Eyk Xlg | N7: Eyk Lg | O7: =J8*15 -> 9060 | P7: =O7/150 -> 60.4 | R7: Week | S7: =Mon!C2 -> 9
A8: =Mon!B74+Tues!B47+Wed!B46+Thurs!B76+Fri!B48+NFLD!A47 -> 280 | B8: OC 30 Lrg | D8: =Mon!E74+Tues!E47+Wed!E46+Thurs!E76+Fri!E48+NFLD!D47 -> 0 | E8: Nova Jumbo | J8: =Mon!K74+Tues!K47+Wed!K46+Thurs!K76+Fri!K48+NFLD!J47 -> 604 | K8: Eyk Lg | N8: Eyk Br | O8: =J9*15 -> 615 | P8: =O8/150 -> 4.1
A9: =Mon!B75+Tues!B48+Wed!B47+Thurs!B77+Fri!B49+NFLD!A48 -> 17 | B9: OC Lg Cozy Coop | D9: =Mon!E75+Tues!E48+Wed!E47+Thurs!E77+Fri!E49+NFLD!D48 -> 60 | E9: Wal Nova 18's Lg | J9: =Mon!K75+Tues!K48+Wed!K47+Thurs!K77+Fri!K49+NFLD!J48 -> 41 | K9: Eyk Br | N9: Filler Flats | O9: =7*(J10+J11)+8*(D12+D13+G7)+5*A9 -> 3650 | P9: =O9/140 -> 26.071429
D10: =Mon!E76+Tues!E49+Wed!E48+Thurs!E78+Fri!E50+NFLD!D49 -> 0 | E10: All Grain Nova | J10: =Mon!K76+Tues!K49+Wed!K48+Thurs!K78+Fri!K50+NFLD!J49 -> 125 | K10: Lg Loose | N10: OC Xlg | O10: =A4*15 -> 315 | P10: =O10/250 -> 1.26
D11: =Mon!E77+Tues!E50+Wed!E49+Thurs!E79+Fri!E51+NFLD!D50 -> 0 | E11: Nova 6 Pack | J11: =Mon!K77+Tues!K50+Wed!K49+Thurs!K79+Fri!K51+NFLD!J50 -> 150 | K11: Med Loose | N11: OC Lg | O11: =A5*15 -> 1245 | P11: =O11/250 -> 4.98
D12: =Mon!E78+Tues!E51+Wed!E50+Thurs!E80+Fri!E52+NFLD!D51 -> 0 | E12: XLrg 30 pack Nova | N12: OC Med | O12: =A6*15 -> 90 | P12: =O12/250 -> 0.36
D13: =Mon!E79+Tues!E52+Wed!E51+Thurs!E81+Fri!E53+NFLD!D52 -> 92 | E13: Lrg 30 pack Nova | N13: OC Br | O13: =A7*15 -> 375 | P13: =O13/250 -> 1.5
N14: OC 30 Lrg Sleeve | O14: =5*A9 -> 85 | P14: =O14/50 -> 1.7
N15: OC Lg Cozy Coop | O15: =15*A9 -> 255 | P15: =O15/250 -> 1.02
A16: Specialty | D16: Small Tally | G16: QTY | H16: Carts | N16: Lob Xlg | O16: =15*G4 -> 315 | P16: =O16/250 -> 1.26
A17: =Mon!B85+Tues!B58+Wed!B57+Thurs!B87+Fri!B59+NFLD!A58 -> 0 | B17: OC Org F.Rng (B) | D17: =A6 -> 6 | E17: OC Med | G17: =Mon!K85+Tues!K58+Thurs!K87+Fri!K59 -> 0 | H17: OC Xlg | N17: Lob Lg | O17: =15*G5 -> 4380 | P17: =O17/250 -> 17.52
A18: =Mon!B86+Tues!B59+Wed!B58+Thurs!B88+Fri!B60+NFLD!A59 -> 5 | B18: OC Lg Free Run (W) | D18: =A9 -> 17 | E18: OC Lg Cozy Coop | G18: =Mon!K86+Tues!K59+Thurs!K88+Fri!K60 -> 0 | H18: OC Lg | N18: Lob br | O18: =15*G6 -> 195 | P18: =O18/250 -> 0.78
A19: =Mon!B87+Tues!B60+Wed!B59+Thurs!B89+Fri!B61+NFLD!A60 -> 1 | B19: OC Om Free Run (W) | D19: =J6 -> 306 | E19: ED 18 LG | G19: =Mon!K87+Tues!K60+Thurs!K89+Fri!K61 -> 9 | H19: OC 30 Lrg | N19: Lob 30 Sleeve | O19: =8*G7 -> 904 | P19: =O19/50 -> 18.08
A20: =Mon!B88+Tues!B61+Wed!B60+Thurs!B90+Fri!B62+NFLD!A61 -> 1 | B20: MP Om 6pk (W) | D20: =A7 -> 25 | E20: OC Br | G20: =Mon!K88+Tues!K61+Thurs!K90+Fri!K62 -> 0 | H20: Lob Xlg | N20: Wal GV Xlrg | O20: =15*D4 -> 345 | P20: =O20/150 -> 2.3
A21: =Mon!B89+Tues!B62+Wed!B61+Thurs!B91+Fri!B63+NFLD!A62 -> 2 | B21: MP Om 12pk (W) | D21: =G6 -> 13 | E21: Lob br | G21: =Mon!K89+Tues!K62+Thurs!K91+Fri!K63 -> 6 | H21: Lob Lg | N21: Wal GV Lg | O21: =15*D5 -> 405 | P21: =O21/150 -> 2.7
A22: =Mon!B90+Tues!B63+Wed!B62+Thurs!B92+Fri!B64+NFLD!A63 -> 2 | B22: MP Free Run (B) | D22: =A8 -> 280 | E22: OC 30 Lg | G22: =Mon!K90+Tues!K63+Thurs!K92+Fri!K64 -> 6 | H22: Lob 30 Lg | N22: Wal Nova Xlg Brn | O22: =15*D6 -> 0 | P22: =O22/150 -> 0
A23: =Mon!B91+Tues!B64+Wed!B63+Thurs!B93+Fri!B65+NFLD!A64 -> 1 | B23: MP Coldspring F.Rng (B) | D23: =G7 -> 113 | E23: Lob 30 Lg | G23: =Mon!K91+Tues!K64+Thurs!K93+Fri!K65 -> 5 | H23: ED 18 XL | N23: Wal Nova Brn | O23: =15*D7 -> 75 | P23: =O23/150 -> 0.5
G24: =Mon!K92+Tues!K65+Thurs!K94+Fri!K66 -> 12 | H24: ED 18 LG | N24: Nova Jumbo | O24: =12*D8 -> 0 | P24: =O24/125 -> 0
N25: Wal Nova 18's Lg | O25: =10*D9 -> 600 | P25: =O25/130 -> 4.6153846
N26: All Grain Nova | O26: =15*D10 -> 0 | P26: =O26/125 -> 0
N27: Nova 6 Pack | O27: =15*D11 -> 0 | P27: =O27/125 -> 0
N28: XLrg 30 pack Nova Sleeve | O28: =8*D12 -> 0 | P28: =O28/50 -> 0
N29: Lrg 30 pack Nova Sleeve | O29: =8*D13 -> 736 | P29: =O29/50 -> 14.72
N31: Boxe Type | O31: Pcs | P31: Bundles
N32: Blue | O32: =A4+D4+G4+J5+J7-24*(G17+G20+G23) -> 505 | P32: =O32/25-24*(G17+G20+G23) -> -99.8 | R32: *box usage generally accounts for carts, but does not account if stores order a cart + boxes in the same order or if we run out of carts and have to pack carts into boxes
N33: Red | O33: =A5+A8+A9+D5+D10+D11+G5+J6+J8+J10-24*(G18+G21+G24)-20*G19 -> 1122 | P33: =O33/25-24*(G18+G21+G24)-20*G19 -> -567.12
N34: Black | O34: =D8+D9+J4 -> 175 | P34: =O34/25 -> 7
N35: Green | O35: =A6+J11 -> 156 | P35: =O35/25 -> 6.24
N36: Brown | O36: =A7+G6+D7+D6+J9 -> 84 | P36: =O36/25 -> 3.36
N37: Nova Wide | O37: =D12+D13 -> 92 | P37: =O37/20 -> 4.6
N38: Lob Wide | O38: =G7-13*G22 -> 35 | P38: =O38/20-13*G22 -> -76.25
